Workbook

Sheet HDSD
A1: LƯƠNG THỜI VỤ (RSS, TRỰC LÒ, A LƯỚI, THỜI VỤ HAQT, KHOÁN TẤN MỦ, BỐC XẾP) & CÔNG NHÂN LÀO
A2: Thay cho file "ĐNTT CÔNG NHÂN THỜI VỤ", "BẢNG LƯƠNG CÔNG NHÂN THỜI VỤ HAQT" và sheet "Công nhân Lào". Một bảng công, quy tắc theo NHÓM, khoán tấn chia tổ tự động.
A4: QUY ƯỚC MÀU
A5: Chữ xanh, nền vàng nhạt | B5: Ô nhập liệu
A6: Nền vàng đậm | B6: Định mức theo nhóm – HCNS đổi khi có quyết định
A7: Chữ đen | B7: Công thức, đã khoá
A8: Nền xanh lá | B8: Kết quả cuối – đưa sang ĐNTT
A10: CÁCH CHẤM CÔNG
A11: Số giờ | B11: Ví dụ 8, 12, 8.5 (bội số 0,5). Trực lò: 12 giờ = 1 ca.
A12: Số giờ + N | B12: Ví dụ 12N = 12 giờ ca ĐÊM. Thay cho việc chọn tay ô ca đêm trong công thức cũ (SUM(J,R,S)/8).
A13: Một người làm 2 nhóm | B13: Chấm 2 dòng: cùng Mã NV, khác Nhóm (vd Lê Văn Nghị: dòng RSS + dòng Trực lò). Đơn giá riêng ghi ở cột "Đơn giá riêng" nếu khác mặc định của nhóm.
A15: QUY TRÌNH KỲ LƯƠNG (cả tháng hoặc nửa tháng)
A16: 1. THAM_SO | B16: Tháng, năm, kỳ (Cả tháng / 1–15 / 16–31), tỷ giá kíp.
A17: 2. NHOM | B17: Đơn giá ngày mặc định, giờ/công, hỗ trợ ngày/đêm, tiền ăn, ngày chia lương tháng, làm tròn – theo từng nhóm.
A18: 3. NHAN_VIEN | B18: Người mới: mã, nhóm chính, hình thức (Lương ngày / Lương ca / Lương tháng / Khoán tháng), lương tháng (Lào), tổ & vai trò (HAQT).
A19: 4. BCC | B19: Chấm giờ. Cột Nhóm bắt buộc. Người chấm / Người duyệt.
A20: 5. KHOAN_TAN + KT_NGUOI | B20: Sản lượng mủ khoán theo ngày & tổ; đánh dấu x người tham gia ngày đó ở KT_NGUOI (ngày khoán tấn không chấm giờ). Tiền chia đều làm tròn xuống nghìn, trưởng tổ nhận phần dư. Bốc xếp mủ tạp đích danh (tối đa 3 người, chia đều).
A21: 6. DIEU_CHINH | B21: Tạm ứng, hỗ trợ thêm, thưởng, khoản trừ – có lý do & người duyệt. Tiền kíp Lào ghi LAK, tự quy đổi.
A22: 7. LUONG, KIEM_TRA | B22: Tự tính. Tất cả OK mới chốt.
A24: PHÁT HIỆN KHI ĐỐI CHIẾU FILE CŨ (tháng 8)
A25: Công nhân Lào | B25: Nghen: gõ cứng 4.500.000 dù 31 công; Ken: chia 31 (3tr/31×19); Ngon, Lun: chia 30. File này thống nhất: lương tháng / 30 × MIN(công, 30). Ken theo quy tắc mới = 1.900.000 (cũ 1.838.710) – HCNS quyết.
A26: Khoán tấn HAQT | B26: Số tiền từng người gõ tay; suy ra quy tắc: chia đều làm tròn xuống nghìn, trưởng tổ nhận phần dư. Ngày 23/08 tổ 1 không khớp hoàn toàn → HCNS xác nhận quy tắc.
A27: Trần Thắng / Trần Thăng | B27: RSS ghi "Trần Thắng", trực lò ghi "Trần Thăng" – một người hai tên. Cần mã NV thống nhất.
A28: Dương (Lào) ngày 31 | B28: Ô chấm công ghi 31 (giờ) – lỗi nhập; file này chặn bằng validation.
A29: A Lưới ca đêm | B29: Công thức cũ chọn ô bằng tay (SUM(8,J12)/8, SUM(H,T,U,V)/8) – không tái lập được; file này dùng hậu tố N.

Sheet THAM_SO
A1: THAM SỐ KỲ LƯƠNG THỜI VỤ
B3: Tháng | C3: 8
B4: Năm | C4: 2026
B5: Kỳ (Cả tháng / 1–15 / 16–31) | C5: Cả tháng | D5: Kỳ nửa tháng: chỉ các cột ngày thuộc kỳ được mở để chấm (cột ngoài kỳ tô xám).
B7: Tỷ giá 1 LAK (kíp) = ? VND | C7: 1.15 | D7: VÍ DỤ – lấy tỷ giá kế toán
B8: Cảnh báo nếu giờ/ngày lớn hơn | C8: 12
B9: Đơn giá bốc xếp mủ tạp (đ/tấn) | C9: 50000

Sheet NHOM
A1: ĐỊNH MỨC THEO NHÓM LAO ĐỘNG
A2: Mỗi nhóm một dòng. Thêm nhóm mới = thêm dòng.
A4: Nhóm | B4: Mô tả | C4: Đơn giá ngày mặc định (đ/công) | D4: Giờ / 1 công | E4: Hỗ trợ / công ngày | F4: Hỗ trợ / công đêm | G4: Tiền ăn / công | H4: Ngày chia lương tháng | I4: Làm tròn xuống (đ) | J4: Nguồn trong file cũ
A5: RSS HAPĐ | B5: Công nhân thời vụ RSS Phong Điền | C5: 350000 | D5: 8 | E5: 0 | F5: 0 | G5: 0 | H5: 30 | I5: 1 | J5: Sheet "Công nhân thời vụ RSS": 350k, riêng Nghị 370k
A6: Trực lò | B6: Trực lò 12 giờ/ca | C6: 250000 | D6: 12 | E6: 0 | F6: 0 | G6: 0 | H6: 30 | I6: 1 | J6: Sheet "Công trực lò": 250k/12h
A7: A Lưới SX | B7: Thời vụ A Lưới – sản xuất | C7: 270000 | D7: 8 | E7: 80000 | F7: 100000 | G7: 0 | H7: 30 | I7: 1 | J7: 80k/công ngày, 100k/ca đêm
A8: A Lưới RSS | B8: Thời vụ A Lưới – RSS | C8: 350000 | D8: 8 | E8: 0 | F8: 20000 | G8: 0 | H8: 30 | I8: 1 | J8: 20k/ca đêm
A9: Thời vụ HAQT | B9: Công nhân thời vụ Huy Anh Quảng Trị | C9: 370000 | D9: 8 | E9: 0 | F9: 0 | G9: 0 | H9: 30 | I9: 1 | J9: 370k/công + khoán tấn theo tổ + bốc xếp
A10: Lào | B10: Công nhân Lào | C10: 0 | D10: 8 | E10: 0 | F10: 0 | G10: 0 | H10: 30 | I10: 1000 | J10: Lương tháng/30 × công; tiền ăn 90k/công ghi riêng từng người (file cũ chỉ Nghen có); làm tròn nghìn

Sheet NHAN_VIEN
A1: DANH MỤC LAO ĐỘNG THỜI VỤ & CÔNG NHÂN LÀO
A2: Mã NV là khoá. Hình thức: Lương ngày (công × đơn giá) / Lương ca (ca 12h × đơn giá) / Lương tháng (lương tháng/ngày chia × công) / Khoán tháng (nhận nguyên lương tháng).
A4: STT | B4: Mã NV | C4: Họ và tên | D4: Nhóm chính | E4: Hình thức | F4: Đơn giá riêng (đ/công) | G4: Lương tháng (Lương tháng/Khoán tháng) | H4: Tiền ăn riêng (đ/công) | I4: Tổ (khoán tấn) | J4: Vai trò tổ | K4: Ngày vào | L4: Tình trạng | M4: Ghi chú
A5: 1 | B5: RSS-01 | C5: Hồ Thị Lẽ | D5: RSS HAPĐ | E5: Lương ngày | L5: Thời vụ
A6: 2 | B6: RSS-02 | C6: Thèn Thị Giang | D6: RSS HAPĐ | E6: Lương ngày | L6: Thời vụ
A7: 3 | B7: RSS-03 | C7: Lê Văn Nghị | D7: RSS HAPĐ | E7: Lương ngày | F7: 370000 | L7: Thời vụ | M7: Đơn giá riêng 370.000 (file cũ)
A8: 4 | B8: RSS-04 | C8: Trần Thắng | D8: RSS HAPĐ | E8: Lương ngày | L8: Thời vụ
A9: 5 | B9: RSS-05 | C9: Trần Phước Hùng | D9: RSS HAPĐ | E9: Lương ngày | L9: Thời vụ
A10: 6 | B10: RSS-06 | C10: Lê Thị Hảo | D10: RSS HAPĐ | E10: Lương ngày | L10: Thời vụ
A11: 7 | B11: RSS-07 | C11: Dương Thị Huệ | D11: RSS HAPĐ | E11: Lương ngày | L11: Thời vụ
A12: 8 | B12: RSS-08 | C12: Lê Thị Như Ý | D12: RSS HAPĐ | E12: Lương ngày | L12: Thời vụ
A13: 9 | B13: RSS-09 | C13: Nguyễn Thị Thùy Trang | D13: RSS HAPĐ | E13: Lương ngày | L13: Thời vụ
A14: 10 | B14: RSS-10 | C14: Võ Thị Ngọc Ánh | D14: RSS HAPĐ | E14: Lương ngày | L14: Thời vụ
A15: 11 | B15: RSS-11 | C15: Lê Thị Hiên | D15: RSS HAPĐ | E15: Lương ngày | L15: Thời vụ
A16: 12 | B16: RSS-12 | C16: Phan Thị Như Nghĩa | D16: RSS HAPĐ | E16: Lương ngày | L16: Thời vụ
A17: 13 | B17: RSS-13 | C17: Nguyễn Quyền | D17: RSS HAPĐ | E17: Lương ngày | L17: Thời vụ
A18: 14 | B18: RSS-14 | C18: Lê Quốc Vượng | D18: RSS HAPĐ | E18: Lương ngày | L18: Thời vụ
A19: 15 | B19: RSS-15 | C19: Ngô Quý Anh Tuấn | D19: RSS HAPĐ | E19: Lương ngày | L19: Thời vụ
... A26: 22 | B26: AL-07 | C26: Hồ Văn Lài | D26: A Lưới SX | E26: Lương ngày | L26: Thời vụ
A27: 23 | B27: QT-01 | C27: Lê Văn Đạt | D27: Thời vụ HAQT | E27: Lương ngày | I27: Tổ 1 | J27: Trưởng tổ | L27: Thời vụ
A28: 24 | B28: QT-02 | C28: Nguyễn Văn Ánh | D28: Thời vụ HAQT | E28: Lương ngày | I28: Tổ 1 | J28: Thành viên | L28: Thời vụ
A29: 25 | B29: QT-03 | C29: Lê Đăng Đức | D29: Thời vụ HAQT | E29: Lương ngày | I29: Tổ 1 | J29: Thành viên | L29: Thời vụ
A30: 26 | B30: QT-04 | C30: Phạm Khai | D30: Thời vụ HAQT | E30: Lương ngày | L30: Thời vụ
A31: 27 | B31: QT-05 | C31: Nguyễn Thị Nhung | D31: Thời vụ HAQT | E31: Lương ngày | I31: Tổ 1 | J31: Thành viên | L31: Thời vụ
A32: 28 | B32: QT-06 | C32: Tạ Thị Na | D32: Thời vụ HAQT | E32: Lương ngày | I32: Tổ 1 | J32: Thành viên | L32: Thời vụ
A33: 29 | B33: QT-07 | C33: Lê Thị Thanh | D33: Thời vụ HAQT | E33: Lương ngày | I33: Tổ 1 | J33: Thành viên | L33: Thời vụ
A34: 30 | B34: QT-08 | C34: Nguyễn Thị Thanh | D34: Thời vụ HAQT | E34: Lương ngày | I34: Tổ 1 | J34: Thành viên | L34: Thời vụ
A35: 31 | B35: QT-09 | C35: Lưu Thị Lan | D35: Thời vụ HAQT | E35: Lương ngày | I35: Tổ 1 | J35: Thành viên | L35: Thời vụ
A36: 32 | B36: QT-10 | C36: Lê Thị Minh Thu | D36: Thời vụ HAQT | E36: Lương ngày | I36: Tổ 1 | J36: Thành viên | L36: Thời vụ
A37: 33 | B37: QT-11 | C37: Trần Viết Hải | D37: Thời vụ HAQT | E37: Lương ngày | I37: Tổ 2 | J37: Trưởng tổ | L37: Thời vụ
A38: 34 | B38: QT-12 | C38: Phạm Gia Hiếu | D38: Thời vụ HAQT | E38: Lương ngày | I38: Tổ 3 | J38: Thành viên | L38: Thời vụ
A39: 35 | B39: QT-13 | C39: Nguyễn Thọ Lộc | D39: Thời vụ HAQT | E39: Lương ngày | I39: Tổ 2 | J39: Thành viên | L39: Thời vụ
A40: 36 | B40: QT-14 | C40: Nguyễn Phước Thành | D40: Thời vụ HAQT | E40: Lương ngày | I40: Tổ 2 | J40: Thành viên | L40: Thời vụ
A41: 37 | B41: QT-15 | C41: Nguyễn Thị X Thành | D41: Thời vụ HAQT | E41: Lương ngày | L41: Thời vụ
A42: 38 | B42: QT-16 | C42: Nguyễn Thị Mai | D42: Thời vụ HAQT | E42: Lương ngày | I42: Tổ 2 | J42: Thành viên | L42: Thời vụ
A43: 39 | B43: QT-17 | C43: Nguyễn Thị Điệp | D43: Thời vụ HAQT | E43: Lương ngày | I43: Tổ 2 | J43: Thành viên | L43: Thời vụ
A44: 40 | B44: QT-18 | C44: Trần Thị Thắm | D44: Thời vụ HAQT | E44: Lương ngày | I44: Tổ 2 | J44: Thành viên | L44: Thời vụ
A45: 41 | B45: QT-19 | C45: Lê Thị Thủy | D45: Thời vụ HAQT | E45: Lương ngày | I45: Tổ 2 | J45: Thành viên | L45: Thời vụ
A46: 42 | B46: QT-20 | C46: Nguyễn Thị Kim Thoa | D46: Thời vụ HAQT | E46: Lương ngày | I46: Tổ 2 | J46: Thành viên | L46: Thời vụ
A47: 43 | B47: QT-21 | C47: Hồ Xuân Đông | D47: Thời vụ HAQT | E47: Lương ngày | I47: Tổ 3 | J47: Trưởng tổ | L47: Thời vụ
...

Sheet BCC
A1: BẢNG CHẤM CÔNG THỜI VỤ & LÀO – giờ/ngày, hậu tố N = ca đêm
A2: Mỗi dòng = 1 người × 1 nhóm. Cột Nhóm bắt buộc (chọn từ danh sách). Đơn giá riêng chỉ ghi khi khác mặc định.
G3: =IF(0<DAY(EOMONTH(DATE(NAM,THANG,1),0)),DATE(NAM,THANG,1)+0,"") -> 46235 | H3: =IF(1<DAY(EOMONTH(DATE(NAM,THANG,1),0)),DATE(NAM,THANG,1)+1,"") -> 46236 | I3: =IF(2<DAY(EOMONTH(DATE(NAM,THANG,1),0)),DATE(NAM,THANG,1)+2,"") -> 46237 | J3: =IF(3<DAY(EOMONTH(DATE(NAM,THANG,1),0)),DATE(NAM,THANG,1)+3,"") -> 46238 | K3: =IF(4<DAY(EOMONTH(DATE(NAM,THANG,1),0)),DATE(NAM,THANG,1)+4,"") -> 46239 | L3: =IF(5<DAY(EOMONTH(DATE(NAM,THANG,1),0)),DATE(NAM,THANG,1)+5,"") -> 46240 | M3: =IF(6<DAY(EOMONTH(DATE(NAM,THANG,1),0)),DATE(NAM,THANG,1)+6,"") -> 46241 | N3: =IF(7<DAY(EOMONTH(DATE(NAM,THANG,1),0)),DATE(NAM,THANG,1)+7,"") -> 46242 | O3: =IF(8<DAY(EOMONTH(DATE(NAM,THANG,1),0)),DATE(NAM,THANG,1)+8,"") -> 46243 | P3: =IF(9<DAY(EOMONTH(DATE(NAM,THANG,1),0)),DATE(NAM,THANG,1)+9,"") -> 46244 | Q3: =IF(10<DAY(EOMONTH(DATE(NAM,THANG,1),0)),DATE(NAM,THANG,1)+10,"") -> 46245 | R3: =IF(11<DAY(EOMONTH(DATE(NAM,THANG,1),0)),DATE(NAM,THANG,1)+11,"") -> 46246 | S3: =IF(12<DAY(EOMONTH(DATE(NAM,THANG,1),0)),DATE(NAM,THANG,1)+12,"") -> 46247 | T3: =IF(13<DAY(EOMONTH(DATE(NAM,THANG,1),0)),DATE(NAM,THANG,1)+13,"") -> 46248 | U3: =IF(14<DAY(EOMONTH(DATE(NAM,THANG,1),0)),DATE(NAM,THANG,1)+14,"") -> 46249 | V3: =IF(15<DAY(EOMONTH(DATE(NAM,THANG,1),0)),DATE(NAM,THANG,1)+15,"") -> 46250 | W3: =IF(16<DAY(EOMONTH(DATE(NAM,THANG,1),0)),DATE(NAM,THANG,1)+16,"") -> 46251 | X3: =IF(17<DAY(EOMONTH(DATE(NAM,THANG,1),0)),DATE(NAM,THANG,1)+17,"") -> 46252 | Y3: =IF(18<DAY(EOMONTH(DATE(NAM,THANG,1),0)),DATE(NAM,THANG,1)+18,"") -> 46253 | Z3: =IF(19<DAY(EOMONTH(DATE(NAM,THANG,1),0)),DATE(NAM,THANG,1)+19,"") -> 46254 | AA3: =IF(20<DAY(EOMONTH(DATE(NAM,THANG,1),0)),DATE(NAM,THANG,1)+20,"") -> 46255 | AB3: =IF(21<DAY(EOMONTH(DATE(NAM,THANG,1),0)),DATE(NAM,THANG,1)+21,"") -> 46256 | AC3: =IF(22<DAY(EOMONTH(DATE(NAM,THANG,1),0)),DATE(NAM,THANG,1)+22,"") -> 46257 | AD3: =IF(23<DAY(EOMONTH(DATE(NAM,THANG,1),0)),DATE(NAM,THANG,1)+23,"") -> 46258 | AE3: =IF(24<DAY(EOMONTH(DATE(NAM,THANG,1),0)),DATE(NAM,THANG,1)+24,"") -> 46259 | AF3: =IF(25<DAY(EOMONTH(DATE(NAM,THANG,1),0)),DATE(NAM,THANG,1)+25,"") -> 46260 | AG3: =IF(26<DAY(EOMONTH(DATE(NAM,THANG,1),0)),DATE(NAM,THANG,1)+26,"") -> 46261 | AH3: =IF(27<DAY(EOMONTH(DATE(NAM,THANG,1),0)),DATE(NAM,THANG,1)+27,"") -> 46262 | AI3: =IF(28<DAY(EOMONTH(DATE(NAM,THANG,1),0)),DATE(NAM,THANG,1)+28,"") -> 46263 | AJ3: =IF(29<DAY(EOMONTH(DATE(NAM,THANG,1),0)),DATE(NAM,THANG,1)+29,"") -> 46264 | AK3: =IF(30<DAY(EOMONTH(DATE(NAM,THANG,1),0)),DATE(NAM,THANG,1)+30,"") -> 46265
G4: =IF(G3="","",CHOOSE(WEEKDAY(G3),"CN","T2","T3","T4","T5","T6","T7")) -> T7 | H4: =IF(H3="","",CHOOSE(WEEKDAY(H3),"CN","T2","T3","T4","T5","T6","T7")) -> CN | I4: =IF(I3="","",CHOOSE(WEEKDAY(I3),"CN","T2","T3","T4","T5","T6","T7")) -> T2 | J4: =IF(J3="","",CHOOSE(WEEKDAY(J3),"CN","T2","T3","T4","T5","T6","T7")) -> T3 | K4: =IF(K3="","",CHOOSE(WEEKDAY(K3),"CN","T2","T3","T4","T5","T6","T7")) -> T4 | L4: =IF(L3="","",CHOOSE(WEEKDAY(L3),"CN","T2","T3","T4","T5","T6","T7")) -> T5 | M4: =IF(M3="","",CHOOSE(WEEKDAY(M3),"CN","T2","T3","T4","T5","T6","T7")) -> T6 | N4: =IF(N3="","",CHOOSE(WEEKDAY(N3),"CN","T2","T3","T4","T5","T6","T7")) -> T7 | ... AK4: =IF(AK3="","",CHOOSE(WEEKDAY(AK3),"CN","T2","T3","T4","T5","T6","T7")) -> T2
A5: STT | B5: Mã NV | C5: Họ và tên | D5: Nhóm | E5: Đơn giá riêng | F5: Giờ/công | G5: 1 | H5: 2 | I5: 3 | J5: 4 | K5: 5 | L5: 6 | M5: 7 | N5: 8 | O5: 9 | P5: 10 | Q5: 11 | R5: 12 | S5: 13 | T5: 14 | U5: 15 | V5: 16 | W5: 17 | X5: 18 | Y5: 19 | Z5: 20 | AA5: 21 | AB5: 22 | AC5: 23 | AD5: 24 | AE5: 25 | AF5: 26 | AG5: 27 | AH5: 28 | AI5: 29 | AJ5: 30 | AK5: 31 | AL5: Tổng giờ | AM5: Công | AN5: Công đêm | AO5: Người chấm | AP5: Người duyệt | AQ5: Ghi chú | AR5: Max giờ/ngày (mọi dòng cùng mã)
A6: 1 | B6: RSS-01 | C6: =IF(B6="","",IFERROR(INDEX(NV_TEN,MATCH(B6,NV_MA,0)),"MÃ KHÔNG CÓ")) -> Hồ Thị Lẽ | D6: RSS HAPĐ | F6: =IF(D6="","",IFERROR(INDEX(NH_GIO,MATCH(D6,NH_TEN,0)),"NHÓM?")) -> 8 | G6: 8 | H6: 8 | I6: 8 | K6: 8 | L6: 8 | M6: 8 | N6: 10 | O6: 8 | P6: 8 | Q6: 4 | R6: 8 | S6: 8 | T6: 8.5 | U6: 8 | V6: 8 | W6: 8 | X6: 8 | Y6: 8 | Z6: 8 | AA6: 8 | AB6: 8 | AC6: 10 | AD6: 12.5 | AE6: 8 | AF6: 10 | AG6: 8 | AH6: 10 | AI6: 8 | AJ6: 8 | AK6: 8 | AL6: =IF(B6="","",SUMPRODUCT(IFERROR(VALUE(SUBSTITUTE(G6:AK6,"N","")),0))) -> 249 | AM6: =IF(B6="","",AL6/F6) -> 31.125 | AN6: =IF(B6="","",SUMPRODUCT(ISNUMBER(SEARCH("N",G6:AK6))*IFERROR(VALUE(SUBSTITUTE(G6:AK6,"N","")),0))/F6) -> 0 | AR6: =IF(B6="",0,MAX(SUMPRODUCT((BCC_MA=$B6)*IFERROR(VALUE(SUBSTITUTE($G$6:$G$100,"N","")),0)),SUMPRODUCT((BCC_MA=$B6)*IFERROR(VALUE(SUBSTITUTE($H$6:$H$100,"N","")),0)),SUMPRODUCT((BCC_MA=$B6)*IFERROR(VALUE(SUBSTITUTE($I$6:$I$100,"N","")),0)),SUMPRODUCT((BCC_MA=$B6)*IFERROR(VALUE(SUBSTITUTE($J$6:$J$100,"N","")),0)),SUMPRODUCT((BCC_MA=$B6)*IFERROR(VALUE(SUBSTITUTE($K$6:$K$100,"N","")),0)),SUMPRODUCT((BCC_MA=$B6)*IFERROR(VALUE(SUBSTITUTE($L$6:$L$100,"N","")),0)),SUMPRODUCT((BCC_MA=$B6)*IFERROR(VALUE(SUBSTITUTE($M$6:$M$100,"N","")),0)),SUMPRODUCT((BCC_MA=$B6)*IFERROR(VALUE(SUBSTITUTE($N$6:$N$100,"N","")),0)),SUMPRODUCT((BCC_MA=$B6)*IFERROR(VALUE(SUBSTITUTE($O$6:$O$100,"N","")),0)),SUMPRODUCT((BCC_MA=$B6)*IFERROR(VALUE(SUBSTITUTE($P$6:$P$100,"N","")),0)),SUMPRODUCT((BCC_MA=$B6)*IFERROR(VALUE(SUBSTITUTE($Q$6:$Q$100,"N","")),0)),SUMPRODUCT((BCC_MA=$B6)*IFERROR(VALUE(SUBSTITUTE($R$6:$R$100,"N","")),0)),SUMPRODUCT((BCC_MA=$B6)*IFERROR(VALUE(SUBSTITUTE($S$6:$S$100,"N","")),0)),SUMPRODUCT((BCC_MA=$B6)*IFERROR(VALUE(SUBSTITUTE($T$6:$T$100,"N","")),0)),SUMPRODUCT((BCC_MA=$B6)*IFERROR(VALUE(SUBSTITUTE($U$6:$U$100,"N","")),0)),SUMPRODUCT((BCC_MA=$B6)*IFERROR(VALUE(SUBSTITUTE($V$6:$V$100,"N","")),0)),SUMPRODUCT((BCC_MA=$B6)*IFERROR(VALUE(SUBSTITUTE($W$6:$W$100,"N","")),0)),SUMPRODUCT((BCC_MA=$B6)*IFERROR(VALUE(SUBSTITUTE($X$6:$X$100,"N","")),0)),SUMPRODUCT((BCC_MA=$B6)*IFERROR(VALUE(SUBSTITUTE($Y$6:$Y$100,"N","")),0)),SUMPRODUCT((BCC_MA=$B6)*IFERROR(VALUE(SUBSTITUTE($Z$6:$Z$100,"N","")),0)),SUMPRODUCT((BCC_MA=$B6)*IFERROR(VALUE(SUBSTITUTE($AA$6:$AA$100,"N","")),0)),SUMPRODUCT((BCC_MA=$B6)*IFERROR(VALUE(SUBSTITUTE($AB$6:$AB$100,"N","")),0)),SUMPRODUCT((BCC_MA=$B6)*IFERROR(VALUE(SUBSTITUTE($AC$6:$AC$100,"N","")),0)),SUMPRODUCT((BCC_MA=$B6)*IFERROR(VALUE(SUBSTITUTE($AD$6:$AD$100,"N","")),0)),SUMPRODUCT((BCC_MA=$B6)*IFERROR(VALUE(SUBSTITUTE($AE$6:$AE$100,"N","")),0)),SUMPRODUCT((BCC_MA=$B6)*IFERROR(VALUE(SUBSTITUTE($AF$6:$AF$100,"N","")),0)),SUMPRODUCT((BCC_MA=$B6)*IFERROR(VALUE(SUBSTITUTE($AG$6:$AG$100,"N","")),0)),SUMPRODUCT((BCC_MA=$B6)*IFERROR(VALUE(SUBSTITUTE($AH$6:$AH$100,"N","")),0)),SUMPRODUCT((BCC_MA=$B6)*IFERROR(VALUE(SUBSTITUTE($AI$6:$AI$100,"N","")),0)),SUMPRODUCT((BCC_MA=$B6)*IFERROR(VALUE(SUBSTITUTE($AJ$6:$AJ$100,"N","")),0)),SUMPRODUCT((BCC_MA=$B6)*IFERROR(VALUE(SUBSTITUTE($AK$6:$AK$100,"N","")),0)))) -> 12.5
A7: 2 | B7: RSS-02 | C7: =IF(B7="","",IFERROR(INDEX(NV_TEN,MATCH(B7,NV_MA,0)),"MÃ KHÔNG CÓ")) -> Thèn Thị Giang | D7: RSS HAPĐ | F7: =IF(D7="","",IFERROR(INDEX(NH_GIO,MATCH(D7,NH_TEN,0)),"NHÓM?")) -> 8 | G7: 8 | H7: 8 | L7: 8 | M7: 8 | O7: 8 | P7: 8 | Q7: 8 | R7: 8 | S7: 8 | T7: 8.5 | U7: 8 | V7: 8 | W7: 8 | Y7: 8 | Z7: 8 | AA7: 8 | AB7: 8 | AC7: 10 | AD7: 12.5 | AE7: 8 | AF7: 10 | AG7: 8 | AH7: 10 | AJ7: 8 | AK7: 8 | AL7: =IF(B7="","",SUMPRODUCT(IFERROR(VALUE(SUBSTITUTE(G7:AK7,"N","")),0))) -> 211 | AM7: =IF(B7="","",AL7/F7) -> 26.375 | AN7: =IF(B7="","",SUMPRODUCT(ISNUMBER(SEARCH("N",G7:AK7))*IFERROR(VALUE(SUBSTITUTE(G7:AK7,"N","")),0))/F7) -> 0 | AR7: =IF(B7="",0,MAX(SUMPRODUCT((BCC_MA=$B7)*IFERROR(VALUE(SUBSTITUTE($G$6:$G$100,"N","")),0)),SUMPRODUCT((BCC_MA=$B7)*IFERROR(VALUE(SUBSTITUTE($H$6:$H$100,"N","")),0)),SUMPRODUCT((BCC_MA=$B7)*IFERROR(VALUE(SUBSTITUTE($I$6:$I$100,"N","")),0)),SUMPRODUCT((BCC_MA=$B7)*IFERROR(VALUE(SUBSTITUTE($J$6:$J$100,"N","")),0)),SUMPRODUCT((BCC_MA=$B7)*IFERROR(VALUE(SUBSTITUTE($K$6:$K$100,"N","")),0)),SUMPRODUCT((BCC_MA=$B7)*IFERROR(VALUE(SUBSTITUTE($L$6:$L$100,"N","")),0)),SUMPRODUCT((BCC_MA=$B7)*IFERROR(VALUE(SUBSTITUTE($M$6:$M$100,"N","")),0)),SUMPRODUCT((BCC_MA=$B7)*IFERROR(VALUE(SUBSTITUTE($N$6:$N$100,"N","")),0)),SUMPRODUCT((BCC_MA=$B7)*IFERROR(VALUE(SUBSTITUTE($O$6:$O$100,"N","")),0)),SUMPRODUCT((BCC_MA=$B7)*IFERROR(VALUE(SUBSTITUTE($P$6:$P$100,"N","")),0)),SUMPRODUCT((BCC_MA=$B7)*IFERROR(VALUE(SUBSTITUTE($Q$6:$Q$100,"N","")),0)),SUMPRODUCT((BCC_MA=$B7)*IFERROR(VALUE(SUBSTITUTE($R$6:$R$100,"N","")),0)),SUMPRODUCT((BCC_MA=$B7)*IFERROR(VALUE(SUBSTITUTE($S$6:$S$100,"N","")),0)),SUMPRODUCT((BCC_MA=$B7)*IFERROR(VALUE(SUBSTITUTE($T$6:$T$100,"N","")),0)),SUMPRODUCT((BCC_MA=$B7)*IFERROR(VALUE(SUBSTITUTE($U$6:$U$100,"N","")),0)),SUMPRODUCT((BCC_MA=$B7)*IFERROR(VALUE(SUBSTITUTE($V$6:$V$100,"N","")),0)),SUMPRODUCT((BCC_MA=$B7)*IFERROR(VALUE(SUBSTITUTE($W$6:$W$100,"N","")),0)),SUMPRODUCT((BCC_MA=$B7)*IFERROR(VALUE(SUBSTITUTE($X$6:$X$100,"N","")),0)),SUMPRODUCT((BCC_MA=$B7)*IFERROR(VALUE(SUBSTITUTE($Y$6:$Y$100,"N","")),0)),SUMPRODUCT((BCC_MA=$B7)*IFERROR(VALUE(SUBSTITUTE($Z$6:$Z$100,"N","")),0)),SUMPRODUCT((BCC_MA=$B7)*IFERROR(VALUE(SUBSTITUTE($AA$6:$AA$100,"N","")),0)),SUMPRODUCT((BCC_MA=$B7)*IFERROR(VALUE(SUBSTITUTE($AB$6:$AB$100,"N","")),0)),SUMPRODUCT((BCC_MA=$B7)*IFERROR(VALUE(SUBSTITUTE($AC$6:$AC$100,"N","")),0)),SUMPRODUCT((BCC_MA=$B7)*IFERROR(VALUE(SUBSTITUTE($AD$6:$AD$100,"N","")),0)),SUMPRODUCT((BCC_MA=$B7)*IFERROR(VALUE(SUBSTITUTE($AE$6:$AE$100,"N","")),0)),SUMPRODUCT((BCC_MA=$B7)*IFERROR(VALUE(SUBSTITUTE($AF$6:$AF$100,"N","")),0)),SUMPRODUCT((BCC_MA=$B7)*IFERROR(VALUE(SUBSTITUTE($AG$6:$AG$100,"N","")),0)),SUMPRODUCT((BCC_MA=$B7)*IFERROR(VALUE(SUBSTITUTE($AH$6:$AH$100,"N","")),0)),SUMPRODUCT((BCC_MA=$B7)*IFERROR(VALUE(SUBSTITUTE($AI$6:$AI$100,"N","")),0)),SUMPRODUCT((BCC_MA=$B7)*IFERROR(VALUE(SUBSTITUTE($AJ$6:$AJ$100,"N","")),0)),SUMPRODUCT((BCC_MA=$B7)*IFERROR(VALUE(SUBSTITUTE($AK$6:$AK$100,"N","")),0)))) -> 12.5
A8: 3 | B8: RSS-03 | C8: =IF(B8="","",IFERROR(INDEX(NV_TEN,MATCH(B8,NV_MA,0)),"MÃ KHÔNG CÓ")) -> Lê Văn Nghị | D8: RSS HAPĐ | E8: 370000 | F8: =IF(D8="","",IFERROR(INDEX(NH_GIO,MATCH(D8,NH_TEN,0)),"NHÓM?")) -> 8 | G8: 10 | H8: 10 | I8: 8 | J8: 8 | K8: 8 | L8: 8 | M8: 8 | N8: 17 | O8: 11 | P8: 8 | Q8: 8 | R8: 8 | S8: 8 | T8: 9 | U8: 8 | V8: 18 | W8: 8 | X8: 11 | Y8: 8 | Z8: 8 | AA8: 8 | AB8: 8 | AC8: 10 | AD8: 13 | AE8: 8 | AF8: 10 | AG8: 8 | AH8: 10 | AI8: 9 | AJ8: 8 | AK8: 8 | AL8: =IF(B8="","",SUMPRODUCT(IFERROR(VALUE(SUBSTITUTE(G8:AK8,"N","")),0))) -> 290 | AM8: =IF(B8="","",AL8/F8) -> 36.25 | AN8: =IF(B8="","",SUMPRODUCT(ISNUMBER(SEARCH("N",G8:AK8))*IFERROR(VALUE(SUBSTITUTE(G8:AK8,"N","")),0))/F8) -> 0 | AR8: =IF(B8="",0,MAX(SUMPRODUCT((BCC_MA=$B8)*IFERROR(VALUE(SUBSTITUTE($G$6:$G$100,"N","")),0)),SUMPRODUCT((BCC_MA=$B8)*IFERROR(VALUE(SUBSTITUTE($H$6:$H$100,"N","")),0)),SUMPRODUCT((BCC_MA=$B8)*IFERROR(VALUE(SUBSTITUTE($I$6:$I$100,"N","")),0)),SUMPRODUCT((BCC_MA=$B8)*IFERROR(VALUE(SUBSTITUTE($J$6:$J$100,"N","")),0)),SUMPRODUCT((BCC_MA=$B8)*IFERROR(VALUE(SUBSTITUTE($K$6:$K$100,"N","")),0)),SUMPRODUCT((BCC_MA=$B8)*IFERROR(VALUE(SUBSTITUTE($L$6:$L$100,"N","")),0)),SUMPRODUCT((BCC_MA=$B8)*IFERROR(VALUE(SUBSTITUTE($M$6:$M$100,"N","")),0)),SUMPRODUCT((BCC_MA=$B8)*IFERROR(VALUE(SUBSTITUTE($N$6:$N$100,"N","")),0)),SUMPRODUCT((BCC_MA=$B8)*IFERROR(VALUE(SUBSTITUTE($O$6:$O$100,"N","")),0)),SUMPRODUCT((BCC_MA=$B8)*IFERROR(VALUE(SUBSTITUTE($P$6:$P$100,"N","")),0)),SUMPRODUCT((BCC_MA=$B8)*IFERROR(VALUE(SUBSTITUTE($Q$6:$Q$100,"N","")),0)),SUMPRODUCT((BCC_MA=$B8)*IFERROR(VALUE(SUBSTITUTE($R$6:$R$100,"N","")),0)),SUMPRODUCT((BCC_MA=$B8)*IFERROR(VALUE(SUBSTITUTE($S$6:$S$100,"N","")),0)),SUMPRODUCT((BCC_MA=$B8)*IFERROR(VALUE(SUBSTITUTE($T$6:$T$100,"N","")),0)),SUMPRODUCT((BCC_MA=$B8)*IFERROR(VALUE(SUBSTITUTE($U$6:$U$100,"N","")),0)),SUMPRODUCT((BCC_MA=$B8)*IFERROR(VALUE(SUBSTITUTE($V$6:$V$100,"N","")),0)),SUMPRODUCT((BCC_MA=$B8)*IFERROR(VALUE(SUBSTITUTE($W$6:$W$100,"N","")),0)),SUMPRODUCT((BCC_MA=$B8)*IFERROR(VALUE(SUBSTITUTE($X$6:$X$100,"N","")),0)),SUMPRODUCT((BCC_MA=$B8)*IFERROR(VALUE(SUBSTITUTE($Y$6:$Y$100,"N","")),0)),SUMPRODUCT((BCC_MA=$B8)*IFERROR(VALUE(SUBSTITUTE($Z$6:$Z$100,"N","")),0)),SUMPRODUCT((BCC_MA=$B8)*IFERROR(VALUE(SUBSTITUTE($AA$6:$AA$100,"N","")),0)),SUMPRODUCT((BCC_MA=$B8)*IFERROR(VALUE(SUBSTITUTE($AB$6:$AB$100,"N","")),0)),SUMPRODUCT((BCC_MA=$B8)*IFERROR(VALUE(SUBSTITUTE($AC$6:$AC$100,"N","")),0)),SUMPRODUCT((BCC_MA=$B8)*IFERROR(VALUE(SUBSTITUTE($AD$6:$AD$100,"N","")),0)),SUMPRODUCT((BCC_MA=$B8)*IFERROR(VALUE(SUBSTITUTE($AE$6:$AE$100,"N","")),0)),SUMPRODUCT((BCC_MA=$B8)*IFERROR(VALUE(SUBSTITUTE($AF$6:$AF$100,"N","")),0)),SUMPRODUCT((BCC_MA=$B8)*IFERROR(VALUE(SUBSTITUTE($AG$6:$AG$100,"N","")),0)),SUMPRODUCT((BCC_MA=$B8)*IFERROR(VALUE(SUBSTITUTE($AH$6:$AH$100,"N","")),0)),SUMPRODUCT((BCC_MA=$B8)*IFERROR(VALUE(SUBSTITUTE($AI$6:$AI$100,"N","")),0)),SUMPRODUCT((BCC_MA=$B8)*IFERROR(VALUE(SUBSTITUTE($AJ$6:$AJ$100,"N","")),0)),SUMPRODUCT((BCC_MA=$B8)*IFERROR(VALUE(SUBSTITUTE($AK$6:$AK$100,"N","")),0)))) -> 29
A9: 4 | B9: RSS-04 | C9: =IF(B9="","",IFERROR(INDEX(NV_TEN,MATCH(B9,NV_MA,0)),"MÃ KHÔNG CÓ")) -> Trần Thắng | D9: RSS HAPĐ | F9: =IF(D9="","",IFERROR(INDEX(NH_GIO,MATCH(D9,NH_TEN,0)),"NHÓM?")) -> 8 | G9: 8 | H9: 8 | I9: 8 | J9: 8 | K9: 8 | L9: 8 | M9: 8 | N9: 8 | O9: 8 | P9: 8 | Q9: 8 | R9: 8 | S9: 8 | T9: 8 | U9: 8 | V9: 8 | W9: 8 | X9: 8 | Y9: 8 | Z9: 8 | AA9: 8 | AB9: 8 | AC9: 8 | AD9: 8 | AE9: 8 | AF9: 8 | AG9: 8 | AH9: 8 | AI9: 8 | AJ9: 8 | AK9: 8 | AL9: =IF(B9="","",SUMPRODUCT(IFERROR(VALUE(SUBSTITUTE(G9:AK9,"N","")),0))) -> 248 | AM9: =IF(B9="","",AL9/F9) -> 31 | AN9: =IF(B9="","",SUMPRODUCT(ISNUMBER(SEARCH("N",G9:AK9))*IFERROR(VALUE(SUBSTITUTE(G9:AK9,"N","")),0))/F9) -> 0 | AR9: =IF(B9="",0,MAX(SUMPRODUCT((BCC_MA=$B9)*IFERROR(VALUE(SUBSTITUTE($G$6:$G$100,"N","")),0)),SUMPRODUCT((BCC_MA=$B9)*IFERROR(VALUE(SUBSTITUTE($H$6:$H$100,"N","")),0)),SUMPRODUCT((BCC_MA=$B9)*IFERROR(VALUE(SUBSTITUTE($I$6:$I$100,"N","")),0)),SUMPRODUCT((BCC_MA=$B9)*IFERROR(VALUE(SUBSTITUTE($J$6:$J$100,"N","")),0)),SUMPRODUCT((BCC_MA=$B9)*IFERROR(VALUE(SUBSTITUTE($K$6:$K$100,"N","")),0)),SUMPRODUCT((BCC_MA=$B9)*IFERROR(VALUE(SUBSTITUTE($L$6:$L$100,"N","")),0)),SUMPRODUCT((BCC_MA=$B9)*IFERROR(VALUE(SUBSTITUTE($M$6:$M$100,"N","")),0)),SUMPRODUCT((BCC_MA=$B9)*IFERROR(VALUE(SUBSTITUTE($N$6:$N$100,"N","")),0)),SUMPRODUCT((BCC_MA=$B9)*IFERROR(VALUE(SUBSTITUTE($O$6:$O$100,"N","")),0)),SUMPRODUCT((BCC_MA=$B9)*IFERROR(VALUE(SUBSTITUTE($P$6:$P$100,"N","")),0)),SUMPRODUCT((BCC_MA=$B9)*IFERROR(VALUE(SUBSTITUTE($Q$6:$Q$100,"N","")),0)),SUMPRODUCT((BCC_MA=$B9)*IFERROR(VALUE(SUBSTITUTE($R$6:$R$100,"N","")),0)),SUMPRODUCT((BCC_MA=$B9)*IFERROR(VALUE(SUBSTITUTE($S$6:$S$100,"N","")),0)),SUMPRODUCT((BCC_MA=$B9)*IFERROR(VALUE(SUBSTITUTE($T$6:$T$100,"N","")),0)),SUMPRODUCT((BCC_MA=$B9)*IFERROR(VALUE(SUBSTITUTE($U$6:$U$100,"N","")),0)),SUMPRODUCT((BCC_MA=$B9)*IFERROR(VALUE(SUBSTITUTE($V$6:$V$100,"N","")),0)),SUMPRODUCT((BCC_MA=$B9)*IFERROR(VALUE(SUBSTITUTE($W$6:$W$100,"N","")),0)),SUMPRODUCT((BCC_MA=$B9)*IFERROR(VALUE(SUBSTITUTE($X$6:$X$100,"N","")),0)),SUMPRODUCT((BCC_MA=$B9)*IFERROR(VALUE(SUBSTITUTE($Y$6:$Y$100,"N","")),0)),SUMPRODUCT((BCC_MA=$B9)*IFERROR(VALUE(SUBSTITUTE($Z$6:$Z$100,"N","")),0)),SUMPRODUCT((BCC_MA=$B9)*IFERROR(VALUE(SUBSTITUTE($AA$6:$AA$100,"N","")),0)),SUMPRODUCT((BCC_MA=$B9)*IFERROR(VALUE(SUBSTITUTE($AB$6:$AB$100,"N","")),0)),SUMPRODUCT((BCC_MA=$B9)*IFERROR(VALUE(SUBSTITUTE($AC$6:$AC$100,"N","")),0)),SUMPRODUCT((BCC_MA=$B9)*IFERROR(VALUE(SUBSTITUTE($AD$6:$AD$100,"N","")),0)),SUMPRODUCT((BCC_MA=$B9)*IFERROR(VALUE(SUBSTITUTE($AE$6:$AE$100,"N","")),0)),SUMPRODUCT((BCC_MA=$B9)*IFERROR(VALUE(SUBSTITUTE($AF$6:$AF$100,"N","")),0)),SUMPRODUCT((BCC_MA=$B9)*IFERROR(VALUE(SUBSTITUTE($AG$6:$AG$100,"N","")),0)),SUMPRODUCT((BCC_MA=$B9)*IFERROR(VALUE(SUBSTITUTE($AH$6:$AH$100,"N","")),0)),SUMPRODUCT((BCC_MA=$B9)*IFERROR(VALUE(SUBSTITUTE($AI$6:$AI$100,"N","")),0)),SUMPRODUCT((BCC_MA=$B9)*IFERROR(VALUE(SUBSTITUTE($AJ$6:$AJ$100,"N","")),0)),SUMPRODUCT((BCC_MA=$B9)*IFERROR(VALUE(SUBSTITUTE($AK$6:$AK$100,"N","")),0)))) -> 20
A10: 5 | B10: RSS-05 | C10: =IF(B10="","",IFERROR(INDEX(NV_TEN,MATCH(B10,NV_MA,0)),"MÃ KHÔNG CÓ")) -> Trần Phước Hùng | D10: RSS HAPĐ | F10: =IF(D10="","",IFERROR(INDEX(NH_GIO,MATCH(D10,NH_TEN,0)),"NHÓM?")) -> 8 | H10: 8 | K10: 8 | L10: 8 | M10: 8 | N10: 10 | O10: 8 | P10: 8 | Q10: 10 | R10: 8 | S10: 8 | T10: 8.5 | U10: 8 | V10: 8 | W10: 8 | X10: 8 | Y10: 8 | Z10: 8 | AA10: 8 | AB10: 8 | AC10: 8 | AF10: 10 | AG10: 8 | AI10: 8 | AJ10: 8 | AK10: 8 | AL10: =IF(B10="","",SUMPRODUCT(IFERROR(VALUE(SUBSTITUTE(G10:AK10,"N","")),0))) -> 206.5 | AM10: =IF(B10="","",AL10/F10) -> 25.8125 | AN10: =IF(B10="","",SUMPRODUCT(ISNUMBER(SEARCH("N",G10:AK10))*IFERROR(VALUE(SUBSTITUTE(G10:AK10,"N","")),0))/F10) -> 0 | AR10: =IF(B10="",0,MAX(SUMPRODUCT((BCC_MA=$B10)*IFERROR(VALUE(SUBSTITUTE($G$6:$G$100,"N","")),0)),SUMPRODUCT((BCC_MA=$B10)*IFERROR(VALUE(SUBSTITUTE($H$6:$H$100,"N","")),0)),SUMPRODUCT((BCC_MA=$B10)*IFERROR(VALUE(SUBSTITUTE($I$6:$I$100,"N","")),0)),SUMPRODUCT((BCC_MA=$B10)*IFERROR(VALUE(SUBSTITUTE($J$6:$J$100,"N","")),0)),SUMPRODUCT((BCC_MA=$B10)*IFERROR(VALUE(SUBSTITUTE($K$6:$K$100,"N","")),0)),SUMPRODUCT((BCC_MA=$B10)*IFERROR(VALUE(SUBSTITUTE($L$6:$L$100,"N","")),0)),SUMPRODUCT((BCC_MA=$B10)*IFERROR(VALUE(SUBSTITUTE($M$6:$M$100,"N","")),0)),SUMPRODUCT((BCC_MA=$B10)*IFERROR(VALUE(SUBSTITUTE($N$6:$N$100,"N","")),0)),SUMPRODUCT((BCC_MA=$B10)*IFERROR(VALUE(SUBSTITUTE($O$6:$O$100,"N","")),0)),SUMPRODUCT((BCC_MA=$B10)*IFERROR(VALUE(SUBSTITUTE($P$6:$P$100,"N","")),0)),SUMPRODUCT((BCC_MA=$B10)*IFERROR(VALUE(SUBSTITUTE($Q$6:$Q$100,"N","")),0)),SUMPRODUCT((BCC_MA=$B10)*IFERROR(VALUE(SUBSTITUTE($R$6:$R$100,"N","")),0)),SUMPRODUCT((BCC_MA=$B10)*IFERROR(VALUE(SUBSTITUTE($S$6:$S$100,"N","")),0)),SUMPRODUCT((BCC_MA=$B10)*IFERROR(VALUE(SUBSTITUTE($T$6:$T$100,"N","")),0)),SUMPRODUCT((BCC_MA=$B10)*IFERROR(VALUE(SUBSTITUTE($U$6:$U$100,"N","")),0)),SUMPRODUCT((BCC_MA=$B10)*IFERROR(VALUE(SUBSTITUTE($V$6:$V$100,"N","")),0)),SUMPRODUCT((BCC_MA=$B10)*IFERROR(VALUE(SUBSTITUTE($W$6:$W$100,"N","")),0)),SUMPRODUCT((BCC_MA=$B10)*IFERROR(VALUE(SUBSTITUTE($X$6:$X$100,"N","")),0)),SUMPRODUCT((BCC_MA=$B10)*IFERROR(VALUE(SUBSTITUTE($Y$6:$Y$100,"N","")),0)),SUMPRODUCT((BCC_MA=$B10)*IFERROR(VALUE(SUBSTITUTE($Z$6:$Z$100,"N","")),0)),SUMPRODUCT((BCC_MA=$B10)*IFERROR(VALUE(SUBSTITUTE($AA$6:$AA$100,"N","")),0)),SUMPRODUCT((BCC_MA=$B10)*IFERROR(VALUE(SUBSTITUTE($AB$6:$AB$100,"N","")),0)),SUMPRODUCT((BCC_MA=$B10)*IFERROR(VALUE(SUBSTITUTE($AC$6:$AC$100,"N","")),0)),SUMPRODUCT((BCC_MA=$B10)*IFERROR(VALUE(SUBSTITUTE($AD$6:$AD$100,"N","")),0)),SUMPRODUCT((BCC_MA=$B10)*IFERROR(VALUE(SUBSTITUTE($AE$6:$AE$100,"N","")),0)),SUMPRODUCT((BCC_MA=$B10)*IFERROR(VALUE(SUBSTITUTE($AF$6:$AF$100,"N","")),0)),SUMPRODUCT((BCC_MA=$B10)*IFERROR(VALUE(SUBSTITUTE($AG$6:$AG$100,"N","")),0)),SUMPRODUCT((BCC_MA=$B10)*IFERROR(VALUE(SUBSTITUTE($AH$6:$AH$100,"N","")),0)),SUMPRODUCT((BCC_MA=$B10)*IFERROR(VALUE(SUBSTITUTE($AI$6:$AI$100,"N","")),0)),SUMPRODUCT((BCC_MA=$B10)*IFERROR(VALUE(SUBSTITUTE($AJ$6:$AJ$100,"N","")),0)),SUMPRODUCT((BCC_MA=$B10)*IFERROR(VALUE(SUBSTITUTE($AK$6:$AK$100,"N","")),0)))) -> 10
A11: 6 | B11: RSS-06 | C11: =IF(B11="","",IFERROR(INDEX(NV_TEN,MATCH(B11,NV_MA,0)),"MÃ KHÔNG CÓ")) -> Lê Thị Hảo | D11: RSS HAPĐ | F11: =IF(D11="","",IFERROR(INDEX(NH_GIO,MATCH(D11,NH_TEN,0)),"NHÓM?")) -> 8 | G11: 8 | AF11: 10 | AG11: 8 | AH11: 10 | AI11: 8 | AJ11: 8 | AK11: 8 | AL11: =IF(B11="","",SUMPRODUCT(IFERROR(VALUE(SUBSTITUTE(G11:AK11,"N","")),0))) -> 60 | AM11: =IF(B11="","",AL11/F11) -> 7.5 | AN11: =IF(B11="","",SUMPRODUCT(ISNUMBER(SEARCH("N",G11:AK11))*IFERROR(VALUE(SUBSTITUTE(G11:AK11,"N","")),0))/F11) -> 0 | AR11: =IF(B11="",0,MAX(SUMPRODUCT((BCC_MA=$B11)*IFERROR(VALUE(SUBSTITUTE($G$6:$G$100,"N","")),0)),SUMPRODUCT((BCC_MA=$B11)*IFERROR(VALUE(SUBSTITUTE($H$6:$H$100,"N","")),0)),SUMPRODUCT((BCC_MA=$B11)*IFERROR(VALUE(SUBSTITUTE($I$6:$I$100,"N","")),0)),SUMPRODUCT((BCC_MA=$B11)*IFERROR(VALUE(SUBSTITUTE($J$6:$J$100,"N","")),0)),SUMPRODUCT((BCC_MA=$B11)*IFERROR(VALUE(SUBSTITUTE($K$6:$K$100,"N","")),0)),SUMPRODUCT((BCC_MA=$B11)*IFERROR(VALUE(SUBSTITUTE($L$6:$L$100,"N","")),0)),SUMPRODUCT((BCC_MA=$B11)*IFERROR(VALUE(SUBSTITUTE($M$6:$M$100,"N","")),0)),SUMPRODUCT((BCC_MA=$B11)*IFERROR(VALUE(SUBSTITUTE($N$6:$N$100,"N","")),0)),SUMPRODUCT((BCC_MA=$B11)*IFERROR(VALUE(SUBSTITUTE($O$6:$O$100,"N","")),0)),SUMPRODUCT((BCC_MA=$B11)*IFERROR(VALUE(SUBSTITUTE($P$6:$P$100,"N","")),0)),SUMPRODUCT((BCC_MA=$B11)*IFERROR(VALUE(SUBSTITUTE($Q$6:$Q$100,"N","")),0)),SUMPRODUCT((BCC_MA=$B11)*IFERROR(VALUE(SUBSTITUTE($R$6:$R$100,"N","")),0)),SUMPRODUCT((BCC_MA=$B11)*IFERROR(VALUE(SUBSTITUTE($S$6:$S$100,"N","")),0)),SUMPRODUCT((BCC_MA=$B11)*IFERROR(VALUE(SUBSTITUTE($T$6:$T$100,"N","")),0)),SUMPRODUCT((BCC_MA=$B11)*IFERROR(VALUE(SUBSTITUTE($U$6:$U$100,"N","")),0)),SUMPRODUCT((BCC_MA=$B11)*IFERROR(VALUE(SUBSTITUTE($V$6:$V$100,"N","")),0)),SUMPRODUCT((BCC_MA=$B11)*IFERROR(VALUE(SUBSTITUTE($W$6:$W$100,"N","")),0)),SUMPRODUCT((BCC_MA=$B11)*IFERROR(VALUE(SUBSTITUTE($X$6:$X$100,"N","")),0)),SUMPRODUCT((BCC_MA=$B11)*IFERROR(VALUE(SUBSTITUTE($Y$6:$Y$100,"N","")),0)),SUMPRODUCT((BCC_MA=$B11)*IFERROR(VALUE(SUBSTITUTE($Z$6:$Z$100,"N","")),0)),SUMPRODUCT((BCC_MA=$B11)*IFERROR(VALUE(SUBSTITUTE($AA$6:$AA$100,"N","")),0)),SUMPRODUCT((BCC_MA=$B11)*IFERROR(VALUE(SUBSTITUTE($AB$6:$AB$100,"N","")),0)),SUMPRODUCT((BCC_MA=$B11)*IFERROR(VALUE(SUBSTITUTE($AC$6:$AC$100,"N","")),0)),SUMPRODUCT((BCC_MA=$B11)*IFERROR(VALUE(SUBSTITUTE($AD$6:$AD$100,"N","")),0)),SUMPRODUCT((BCC_MA=$B11)*IFERROR(VALUE(SUBSTITUTE($AE$6:$AE$100,"N","")),0)),SUMPRODUCT((BCC_MA=$B11)*IFERROR(VALUE(SUBSTITUTE($AF$6:$AF$100,"N","")),0)),SUMPRODUCT((BCC_MA=$B11)*IFERROR(VALUE(SUBSTITUTE($AG$6:$AG$100,"N","")),0)),SUMPRODUCT((BCC_MA=$B11)*IFERROR(VALUE(SUBSTITUTE($AH$6:$AH$100,"N","")),0)),SUMPRODUCT((BCC_MA=$B11)*IFERROR(VALUE(SUBSTITUTE($AI$6:$AI$100,"N","")),0)),SUMPRODUCT((BCC_MA=$B11)*IFERROR(VALUE(SUBSTITUTE($AJ$6:$AJ$100,"N","")),0)),SUMPRODUCT((BCC_MA=$B11)*IFERROR(VALUE(SUBSTITUTE($AK$6:$AK$100,"N","")),0)))) -> 10
A12: 7 | B12: RSS-07 | C12: =IF(B12="","",IFERROR(INDEX(NV_TEN,MATCH(B12,NV_MA,0)),"MÃ KHÔNG CÓ")) -> Dương Thị Huệ | D12: RSS HAPĐ | F12: =IF(D12="","",IFERROR(INDEX(NH_GIO,MATCH(D12,NH_TEN,0)),"NHÓM?")) -> 8 | G12: 8 | H12: 8 | I12: 8 | K12: 8 | L12: 8 | M12: 8 | N12: 10 | O12: 8 | P12: 8 | Q12: 8 | R12: 8 | S12: 8 | T12: 8.5 | U12: 8 | W12: 8 | Y12: 8 | Z12: 8 | AA12: 8 | AB12: 8 | AC12: 10 | AD12: 12.5 | AE12: 8 | AF12: 10 | AG12: 8 | AH12: 10 | AI12: 8 | AL12: =IF(B12="","",SUMPRODUCT(IFERROR(VALUE(SUBSTITUTE(G12:AK12,"N","")),0))) -> 221 | AM12: =IF(B12="","",AL12/F12) -> 27.625 | AN12: =IF(B12="","",SUMPRODUCT(ISNUMBER(SEARCH("N",G12:AK12))*IFERROR(VALUE(SUBSTITUTE(G12:AK12,"N","")),0))/F12) -> 0 | AR12: =IF(B12="",0,MAX(SUMPRODUCT((BCC_MA=$B12)*IFERROR(VALUE(SUBSTITUTE($G$6:$G$100,"N","")),0)),SUMPRODUCT((BCC_MA=$B12)*IFERROR(VALUE(SUBSTITUTE($H$6:$H$100,"N","")),0)),SUMPRODUCT((BCC_MA=$B12)*IFERROR(VALUE(SUBSTITUTE($I$6:$I$100,"N","")),0)),SUMPRODUCT((BCC_MA=$B12)*IFERROR(VALUE(SUBSTITUTE($J$6:$J$100,"N","")),0)),SUMPRODUCT((BCC_MA=$B12)*IFERROR(VALUE(SUBSTITUTE($K$6:$K$100,"N","")),0)),SUMPRODUCT((BCC_MA=$B12)*IFERROR(VALUE(SUBSTITUTE($L$6:$L$100,"N","")),0)),SUMPRODUCT((BCC_MA=$B12)*IFERROR(VALUE(SUBSTITUTE($M$6:$M$100,"N","")),0)),SUMPRODUCT((BCC_MA=$B12)*IFERROR(VALUE(SUBSTITUTE($N$6:$N$100,"N","")),0)),SUMPRODUCT((BCC_MA=$B12)*IFERROR(VALUE(SUBSTITUTE($O$6:$O$100,"N","")),0)),SUMPRODUCT((BCC_MA=$B12)*IFERROR(VALUE(SUBSTITUTE($P$6:$P$100,"N","")),0)),SUMPRODUCT((BCC_MA=$B12)*IFERROR(VALUE(SUBSTITUTE($Q$6:$Q$100,"N","")),0)),SUMPRODUCT((BCC_MA=$B12)*IFERROR(VALUE(SUBSTITUTE($R$6:$R$100,"N","")),0)),SUMPRODUCT((BCC_MA=$B12)*IFERROR(VALUE(SUBSTITUTE($S$6:$S$100,"N","")),0)),SUMPRODUCT((BCC_MA=$B12)*IFERROR(VALUE(SUBSTITUTE($T$6:$T$100,"N","")),0)),SUMPRODUCT((BCC_MA=$B12)*IFERROR(VALUE(SUBSTITUTE($U$6:$U$100,"N","")),0)),SUMPRODUCT((BCC_MA=$B12)*IFERROR(VALUE(SUBSTITUTE($V$6:$V$100,"N","")),0)),SUMPRODUCT((BCC_MA=$B12)*IFERROR(VALUE(SUBSTITUTE($W$6:$W$100,"N","")),0)),SUMPRODUCT((BCC_MA=$B12)*IFERROR(VALUE(SUBSTITUTE($X$6:$X$100,"N","")),0)),SUMPRODUCT((BCC_MA=$B12)*IFERROR(VALUE(SUBSTITUTE($Y$6:$Y$100,"N","")),0)),SUMPRODUCT((BCC_MA=$B12)*IFERROR(VALUE(SUBSTITUTE($Z$6:$Z$100,"N","")),0)),SUMPRODUCT((BCC_MA=$B12)*IFERROR(VALUE(SUBSTITUTE($AA$6:$AA$100,"N","")),0)),SUMPRODUCT((BCC_MA=$B12)*IFERROR(VALUE(SUBSTITUTE($AB$6:$AB$100,"N","")),0)),SUMPRODUCT((BCC_MA=$B12)*IFERROR(VALUE(SUBSTITUTE($AC$6:$AC$100,"N","")),0)),SUMPRODUCT((BCC_MA=$B12)*IFERROR(VALUE(SUBSTITUTE($AD$6:$AD$100,"N","")),0)),SUMPRODUCT((BCC_MA=$B12)*IFERROR(VALUE(SUBSTITUTE($AE$6:$AE$100,"N","")),0)),SUMPRODUCT((BCC_MA=$B12)*IFERROR(VALUE(SUBSTITUTE($AF$6:$AF$100,"N","")),0)),SUMPRODUCT((BCC_MA=$B12)*IFERROR(VALUE(SUBSTITUTE($AG$6:$AG$100,"N","")),0)),SUMPRODUCT((BCC_MA=$B12)*IFERROR(VALUE(SUBSTITUTE($AH$6:$AH$100,"N","")),0)),SUMPRODUCT((BCC_MA=$B12)*IFERROR(VALUE(SUBSTITUTE($AI$6:$AI$100,"N","")),0)),SUMPRODUCT((BCC_MA=$B12)*IFERROR(VALUE(SUBSTITUTE($AJ$6:$AJ$100,"N","")),0)),SUMPRODUCT((BCC_MA=$B12)*IFERROR(VALUE(SUBSTITUTE($AK$6:$AK$100,"N","")),0)))) -> 12.5
A13: 8 | B13: RSS-08 | C13: =IF(B13="","",IFERROR(INDEX(NV_TEN,MATCH(B13,NV_MA,0)),"MÃ KHÔNG CÓ")) -> Lê Thị Như Ý | D13: RSS HAPĐ | F13: =IF(D13="","",IFERROR(INDEX(NH_GIO,MATCH(D13,NH_TEN,0)),"NHÓM?")) -> 8 | G13: 8 | H13: 8 | I13: 8 | K13: 8 | L13: 8 | AL13: =IF(B13="","",SUMPRODUCT(IFERROR(VALUE(SUBSTITUTE(G13:AK13,"N","")),0))) -> 40 | AM13: =IF(B13="","",AL13/F13) -> 5 | AN13: =IF(B13="","",SUMPRODUCT(ISNUMBER(SEARCH("N",G13:AK13))*IFERROR(VALUE(SUBSTITUTE(G13:AK13,"N","")),0))/F13) -> 0 | AR13: =IF(B13="",0,MAX(SUMPRODUCT((BCC_MA=$B13)*IFERROR(VALUE(SUBSTITUTE($G$6:$G$100,"N","")),0)),SUMPRODUCT((BCC_MA=$B13)*IFERROR(VALUE(SUBSTITUTE($H$6:$H$100,"N","")),0)),SUMPRODUCT((BCC_MA=$B13)*IFERROR(VALUE(SUBSTITUTE($I$6:$I$100,"N","")),0)),SUMPRODUCT((BCC_MA=$B13)*IFERROR(VALUE(SUBSTITUTE($J$6:$J$100,"N","")),0)),SUMPRODUCT((BCC_MA=$B13)*IFERROR(VALUE(SUBSTITUTE($K$6:$K$100,"N","")),0)),SUMPRODUCT((BCC_MA=$B13)*IFERROR(VALUE(SUBSTITUTE($L$6:$L$100,"N","")),0)),SUMPRODUCT((BCC_MA=$B13)*IFERROR(VALUE(SUBSTITUTE($M$6:$M$100,"N","")),0)),SUMPRODUCT((BCC_MA=$B13)*IFERROR(VALUE(SUBSTITUTE($N$6:$N$100,"N","")),0)),SUMPRODUCT((BCC_MA=$B13)*IFERROR(VALUE(SUBSTITUTE($O$6:$O$100,"N","")),0)),SUMPRODUCT((BCC_MA=$B13)*IFERROR(VALUE(SUBSTITUTE($P$6:$P$100,"N","")),0)),SUMPRODUCT((BCC_MA=$B13)*IFERROR(VALUE(SUBSTITUTE($Q$6:$Q$100,"N","")),0)),SUMPRODUCT((BCC_MA=$B13)*IFERROR(VALUE(SUBSTITUTE($R$6:$R$100,"N","")),0)),SUMPRODUCT((BCC_MA=$B13)*IFERROR(VALUE(SUBSTITUTE($S$6:$S$100,"N","")),0)),SUMPRODUCT((BCC_MA=$B13)*IFERROR(VALUE(SUBSTITUTE($T$6:$T$100,"N","")),0)),SUMPRODUCT((BCC_MA=$B13)*IFERROR(VALUE(SUBSTITUTE($U$6:$U$100,"N","")),0)),SUMPRODUCT((BCC_MA=$B13)*IFERROR(VALUE(SUBSTITUTE($V$6:$V$100,"N","")),0)),SUMPRODUCT((BCC_MA=$B13)*IFERROR(VALUE(SUBSTITUTE($W$6:$W$100,"N","")),0)),SUMPRODUCT((BCC_MA=$B13)*IFERROR(VALUE(SUBSTITUTE($X$6:$X$100,"N","")),0)),SUMPRODUCT((BCC_MA=$B13)*IFERROR(VALUE(SUBSTITUTE($Y$6:$Y$100,"N","")),0)),SUMPRODUCT((BCC_MA=$B13)*IFERROR(VALUE(SUBSTITUTE($Z$6:$Z$100,"N","")),0)),SUMPRODUCT((BCC_MA=$B13)*IFERROR(VALUE(SUBSTITUTE($AA$6:$AA$100,"N","")),0)),SUMPRODUCT((BCC_MA=$B13)*IFERROR(VALUE(SUBSTITUTE($AB$6:$AB$100,"N","")),0)),SUMPRODUCT((BCC_MA=$B13)*IFERROR(VALUE(SUBSTITUTE($AC$6:$AC$100,"N","")),0)),SUMPRODUCT((BCC_MA=$B13)*IFERROR(VALUE(SUBSTITUTE($AD$6:$AD$100,"N","")),0)),SUMPRODUCT((BCC_MA=$B13)*IFERROR(VALUE(SUBSTITUTE($AE$6:$AE$100,"N","")),0)),SUMPRODUCT((BCC_MA=$B13)*IFERROR(VALUE(SUBSTITUTE($AF$6:$AF$100,"N","")),0)),SUMPRODUCT((BCC_MA=$B13)*IFERROR(VALUE(SUBSTITUTE($AG$6:$AG$100,"N","")),0)),SUMPRODUCT((BCC_MA=$B13)*IFERROR(VALUE(SUBSTITUTE($AH$6:$AH$100,"N","")),0)),SUMPRODUCT((BCC_MA=$B13)*IFERROR(VALUE(SUBSTITUTE($AI$6:$AI$100,"N","")),0)),SUMPRODUCT((BCC_MA=$B13)*IFERROR(VALUE(SUBSTITUTE($AJ$6:$AJ$100,"N","")),0)),SUMPRODUCT((BCC_MA=$B13)*IFERROR(VALUE(SUBSTITUTE($AK$6:$AK$100,"N","")),0)))) -> 8
A14: 9 | B14: RSS-09 | C14: =IF(B14="","",IFERROR(INDEX(NV_TEN,MATCH(B14,NV_MA,0)),"MÃ KHÔNG CÓ")) -> Nguyễn Thị Thùy Trang | D14: RSS HAPĐ | F14: =IF(D14="","",IFERROR(INDEX(NH_GIO,MATCH(D14,NH_TEN,0)),"NHÓM?")) -> 8 | G14: 8 | H14: 8 | I14: 8 | K14: 8 | L14: 8 | M14: 8 | N14: 10 | O14: 8 | P14: 8 | Q14: 8 | R14: 8 | S14: 8 | T14: 8.5 | U14: 8 | V14: 8 | W14: 8 | X14: 8 | Y14: 8 | Z14: 8 | AA14: 8 | AB14: 8 | AC14: 10 | AD14: 12.5 | AE14: 8 | AF14: 10 | AG14: 8 | AH14: 10 | AI14: 8 | AK14: 8 | AL14: =IF(B14="","",SUMPRODUCT(IFERROR(VALUE(SUBSTITUTE(G14:AK14,"N","")),0))) -> 245 | AM14: =IF(B14="","",AL14/F14) -> 30.625 | AN14: =IF(B14="","",SUMPRODUCT(ISNUMBER(SEARCH("N",G14:AK14))*IFERROR(VALUE(SUBSTITUTE(G14:AK14,"N","")),0))/F14) -> 0 | AR14: =IF(B14="",0,MAX(SUMPRODUCT((BCC_MA=$B14)*IFERROR(VALUE(SUBSTITUTE($G$6:$G$100,"N","")),0)),SUMPRODUCT((BCC_MA=$B14)*IFERROR(VALUE(SUBSTITUTE($H$6:$H$100,"N","")),0)),SUMPRODUCT((BCC_MA=$B14)*IFERROR(VALUE(SUBSTITUTE($I$6:$I$100,"N","")),0)),SUMPRODUCT((BCC_MA=$B14)*IFERROR(VALUE(SUBSTITUTE($J$6:$J$100,"N","")),0)),SUMPRODUCT((BCC_MA=$B14)*IFERROR(VALUE(SUBSTITUTE($K$6:$K$100,"N","")),0)),SUMPRODUCT((BCC_MA=$B14)*IFERROR(VALUE(SUBSTITUTE($L$6:$L$100,"N","")),0)),SUMPRODUCT((BCC_MA=$B14)*IFERROR(VALUE(SUBSTITUTE($M$6:$M$100,"N","")),0)),SUMPRODUCT((BCC_MA=$B14)*IFERROR(VALUE(SUBSTITUTE($N$6:$N$100,"N","")),0)),SUMPRODUCT((BCC_MA=$B14)*IFERROR(VALUE(SUBSTITUTE($O$6:$O$100,"N","")),0)),SUMPRODUCT((BCC_MA=$B14)*IFERROR(VALUE(SUBSTITUTE($P$6:$P$100,"N","")),0)),SUMPRODUCT((BCC_MA=$B14)*IFERROR(VALUE(SUBSTITUTE($Q$6:$Q$100,"N","")),0)),SUMPRODUCT((BCC_MA=$B14)*IFERROR(VALUE(SUBSTITUTE($R$6:$R$100,"N","")),0)),SUMPRODUCT((BCC_MA=$B14)*IFERROR(VALUE(SUBSTITUTE($S$6:$S$100,"N","")),0)),SUMPRODUCT((BCC_MA=$B14)*IFERROR(VALUE(SUBSTITUTE($T$6:$T$100,"N","")),0)),SUMPRODUCT((BCC_MA=$B14)*IFERROR(VALUE(SUBSTITUTE($U$6:$U$100,"N","")),0)),SUMPRODUCT((BCC_MA=$B14)*IFERROR(VALUE(SUBSTITUTE($V$6:$V$100,"N","")),0)),SUMPRODUCT((BCC_MA=$B14)*IFERROR(VALUE(SUBSTITUTE($W$6:$W$100,"N","")),0)),SUMPRODUCT((BCC_MA=$B14)*IFERROR(VALUE(SUBSTITUTE($X$6:$X$100,"N","")),0)),SUMPRODUCT((BCC_MA=$B14)*IFERROR(VALUE(SUBSTITUTE($Y$6:$Y$100,"N","")),0)),SUMPRODUCT((BCC_MA=$B14)*IFERROR(VALUE(SUBSTITUTE($Z$6:$Z$100,"N","")),0)),SUMPRODUCT((BCC_MA=$B14)*IFERROR(VALUE(SUBSTITUTE($AA$6:$AA$100,"N","")),0)),SUMPRODUCT((BCC_MA=$B14)*IFERROR(VALUE(SUBSTITUTE($AB$6:$AB$100,"N","")),0)),SUMPRODUCT((BCC_MA=$B14)*IFERROR(VALUE(SUBSTITUTE($AC$6:$AC$100,"N","")),0)),SUMPRODUCT((BCC_MA=$B14)*IFERROR(VALUE(SUBSTITUTE($AD$6:$AD$100,"N","")),0)),SUMPRODUCT((BCC_MA=$B14)*IFERROR(VALUE(SUBSTITUTE($AE$6:$AE$100,"N","")),0)),SUMPRODUCT((BCC_MA=$B14)*IFERROR(VALUE(SUBSTITUTE($AF$6:$AF$100,"N","")),0)),SUMPRODUCT((BCC_MA=$B14)*IFERROR(VALUE(SUBSTITUTE($AG$6:$AG$100,"N","")),0)),SUMPRODUCT((BCC_MA=$B14)*IFERROR(VALUE(SUBSTITUTE($AH$6:$AH$100,"N","")),0)),SUMPRODUCT((BCC_MA=$B14)*IFERROR(VALUE(SUBSTITUTE($AI$6:$AI$100,"N","")),0)),SUMPRODUCT((BCC_MA=$B14)*IFERROR(VALUE(SUBSTITUTE($AJ$6:$AJ$100,"N","")),0)),SUMPRODUCT((BCC_MA=$B14)*IFERROR(VALUE(SUBSTITUTE($AK$6:$AK$100,"N","")),0)))) -> 12.5
A15: 10 | B15: RSS-10 | C15: =IF(B15="","",IFERROR(INDEX(NV_TEN,MATCH(B15,NV_MA,0)),"MÃ KHÔNG CÓ")) -> Võ Thị Ngọc Ánh | D15: RSS HAPĐ | F15: =IF(D15="","",IFERROR(INDEX(NH_GIO,MATCH(D15,NH_TEN,0)),"NHÓM?")) -> 8 | H15: 8 | I15: 8 | K15: 8 | L15: 8 | M15: 8 | N15: 10 | P15: 8 | Q15: 8 | R15: 8 | S15: 8 | T15: 8.5 | U15: 8 | W15: 8 | X15: 8 | Y15: 8 | Z15: 8 | AA15: 8 | AB15: 8 | AC15: 10 | AD15: 12.5 | AE15: 8 | AF15: 10 | AG15: 4 | AH15: 10 | AI15: 8 | AJ15: 8 | AK15: 8 | AL15: =IF(B15="","",SUMPRODUCT(IFERROR(VALUE(SUBSTITUTE(G15:AK15,"N","")),0))) -> 225 | AM15: =IF(B15="","",AL15/F15) -> 28.125 | AN15: =IF(B15="","",SUMPRODUCT(ISNUMBER(SEARCH("N",G15:AK15))*IFERROR(VALUE(SUBSTITUTE(G15:AK15,"N","")),0))/F15) -> 0 | AR15: =IF(B15="",0,MAX(SUMPRODUCT((BCC_MA=$B15)*IFERROR(VALUE(SUBSTITUTE($G$6:$G$100,"N","")),0)),SUMPRODUCT((BCC_MA=$B15)*IFERROR(VALUE(SUBSTITUTE($H$6:$H$100,"N","")),0)),SUMPRODUCT((BCC_MA=$B15)*IFERROR(VALUE(SUBSTITUTE($I$6:$I$100,"N","")),0)),SUMPRODUCT((BCC_MA=$B15)*IFERROR(VALUE(SUBSTITUTE($J$6:$J$100,"N","")),0)),SUMPRODUCT((BCC_MA=$B15)*IFERROR(VALUE(SUBSTITUTE($K$6:$K$100,"N","")),0)),SUMPRODUCT((BCC_MA=$B15)*IFERROR(VALUE(SUBSTITUTE($L$6:$L$100,"N","")),0)),SUMPRODUCT((BCC_MA=$B15)*IFERROR(VALUE(SUBSTITUTE($M$6:$M$100,"N","")),0)),SUMPRODUCT((BCC_MA=$B15)*IFERROR(VALUE(SUBSTITUTE($N$6:$N$100,"N","")),0)),SUMPRODUCT((BCC_MA=$B15)*IFERROR(VALUE(SUBSTITUTE($O$6:$O$100,"N","")),0)),SUMPRODUCT((BCC_MA=$B15)*IFERROR(VALUE(SUBSTITUTE($P$6:$P$100,"N","")),0)),SUMPRODUCT((BCC_MA=$B15)*IFERROR(VALUE(SUBSTITUTE($Q$6:$Q$100,"N","")),0)),SUMPRODUCT((BCC_MA=$B15)*IFERROR(VALUE(SUBSTITUTE($R$6:$R$100,"N","")),0)),SUMPRODUCT((BCC_MA=$B15)*IFERROR(VALUE(SUBSTITUTE($S$6:$S$100,"N","")),0)),SUMPRODUCT((BCC_MA=$B15)*IFERROR(VALUE(SUBSTITUTE($T$6:$T$100,"N","")),0)),SUMPRODUCT((BCC_MA=$B15)*IFERROR(VALUE(SUBSTITUTE($U$6:$U$100,"N","")),0)),SUMPRODUCT((BCC_MA=$B15)*IFERROR(VALUE(SUBSTITUTE($V$6:$V$100,"N","")),0)),SUMPRODUCT((BCC_MA=$B15)*IFERROR(VALUE(SUBSTITUTE($W$6:$W$100,"N","")),0)),SUMPRODUCT((BCC_MA=$B15)*IFERROR(VALUE(SUBSTITUTE($X$6:$X$100,"N","")),0)),SUMPRODUCT((BCC_MA=$B15)*IFERROR(VALUE(SUBSTITUTE($Y$6:$Y$100,"N","")),0)),SUMPRODUCT((BCC_MA=$B15)*IFERROR(VALUE(SUBSTITUTE($Z$6:$Z$100,"N","")),0)),SUMPRODUCT((BCC_MA=$B15)*IFERROR(VALUE(SUBSTITUTE($AA$6:$AA$100,"N","")),0)),SUMPRODUCT((BCC_MA=$B15)*IFERROR(VALUE(SUBSTITUTE($AB$6:$AB$100,"N","")),0)),SUMPRODUCT((BCC_MA=$B15)*IFERROR(VALUE(SUBSTITUTE($AC$6:$AC$100,"N","")),0)),SUMPRODUCT((BCC_MA=$B15)*IFERROR(VALUE(SUBSTITUTE($AD$6:$AD$100,"N","")),0)),SUMPRODUCT((BCC_MA=$B15)*IFERROR(VALUE(SUBSTITUTE($AE$6:$AE$100,"N","")),0)),SUMPRODUCT((BCC_MA=$B15)*IFERROR(VALUE(SUBSTITUTE($AF$6:$AF$100,"N","")),0)),SUMPRODUCT((BCC_MA=$B15)*IFERROR(VALUE(SUBSTITUTE($AG$6:$AG$100,"N","")),0)),SUMPRODUCT((BCC_MA=$B15)*IFERROR(VALUE(SUBSTITUTE($AH$6:$AH$100,"N","")),0)),SUMPRODUCT((BCC_MA=$B15)*IFERROR(VALUE(SUBSTITUTE($AI$6:$AI$100,"N","")),0)),SUMPRODUCT((BCC_MA=$B15)*IFERROR(VALUE(SUBSTITUTE($AJ$6:$AJ$100,"N","")),0)),SUMPRODUCT((BCC_MA=$B15)*IFERROR(VALUE(SUBSTITUTE($AK$6:$AK$100,"N","")),0)))) -> 12.5
A16: 11 | B16: RSS-11 | C16: =IF(B16="","",IFERROR(INDEX(NV_TEN,MATCH(B16,NV_MA,0)),"MÃ KHÔNG CÓ")) -> Lê Thị Hiên | D16: RSS HAPĐ | F16: =IF(D16="","",IFERROR(INDEX(NH_GIO,MATCH(D16,NH_TEN,0)),"NHÓM?")) -> 8 | G16: 8 | I16: 8 | K16: 8 | AL16: =IF(B16="","",SUMPRODUCT(IFERROR(VALUE(SUBSTITUTE(G16:AK16,"N","")),0))) -> 24 | AM16: =IF(B16="","",AL16/F16) -> 3 | AN16: =IF(B16="","",SUMPRODUCT(ISNUMBER(SEARCH("N",G16:AK16))*IFERROR(VALUE(SUBSTITUTE(G16:AK16,"N","")),0))/F16) -> 0 | AR16: =IF(B16="",0,MAX(SUMPRODUCT((BCC_MA=$B16)*IFERROR(VALUE(SUBSTITUTE($G$6:$G$100,"N","")),0)),SUMPRODUCT((BCC_MA=$B16)*IFERROR(VALUE(SUBSTITUTE($H$6:$H$100,"N","")),0)),SUMPRODUCT((BCC_MA=$B16)*IFERROR(VALUE(SUBSTITUTE($I$6:$I$100,"N","")),0)),SUMPRODUCT((BCC_MA=$B16)*IFERROR(VALUE(SUBSTITUTE($J$6:$J$100,"N","")),0)),SUMPRODUCT((BCC_MA=$B16)*IFERROR(VALUE(SUBSTITUTE($K$6:$K$100,"N","")),0)),SUMPRODUCT((BCC_MA=$B16)*IFERROR(VALUE(SUBSTITUTE($L$6:$L$100,"N","")),0)),SUMPRODUCT((BCC_MA=$B16)*IFERROR(VALUE(SUBSTITUTE($M$6:$M$100,"N","")),0)),SUMPRODUCT((BCC_MA=$B16)*IFERROR(VALUE(SUBSTITUTE($N$6:$N$100,"N","")),0)),SUMPRODUCT((BCC_MA=$B16)*IFERROR(VALUE(SUBSTITUTE($O$6:$O$100,"N","")),0)),SUMPRODUCT((BCC_MA=$B16)*IFERROR(VALUE(SUBSTITUTE($P$6:$P$100,"N","")),0)),SUMPRODUCT((BCC_MA=$B16)*IFERROR(VALUE(SUBSTITUTE($Q$6:$Q$100,"N","")),0)),SUMPRODUCT((BCC_MA=$B16)*IFERROR(VALUE(SUBSTITUTE($R$6:$R$100,"N","")),0)),SUMPRODUCT((BCC_MA=$B16)*IFERROR(VALUE(SUBSTITUTE($S$6:$S$100,"N","")),0)),SUMPRODUCT((BCC_MA=$B16)*IFERROR(VALUE(SUBSTITUTE($T$6:$T$100,"N","")),0)),SUMPRODUCT((BCC_MA=$B16)*IFERROR(VALUE(SUBSTITUTE($U$6:$U$100,"N","")),0)),SUMPRODUCT((BCC_MA=$B16)*IFERROR(VALUE(SUBSTITUTE($V$6:$V$100,"N","")),0)),SUMPRODUCT((BCC_MA=$B16)*IFERROR(VALUE(SUBSTITUTE($W$6:$W$100,"N","")),0)),SUMPRODUCT((BCC_MA=$B16)*IFERROR(VALUE(SUBSTITUTE($X$6:$X$100,"N","")),0)),SUMPRODUCT((BCC_MA=$B16)*IFERROR(VALUE(SUBSTITUTE($Y$6:$Y$100,"N","")),0)),SUMPRODUCT((BCC_MA=$B16)*IFERROR(VALUE(SUBSTITUTE($Z$6:$Z$100,"N","")),0)),SUMPRODUCT((BCC_MA=$B16)*IFERROR(VALUE(SUBSTITUTE($AA$6:$AA$100,"N","")),0)),SUMPRODUCT((BCC_MA=$B16)*IFERROR(VALUE(SUBSTITUTE($AB$6:$AB$100,"N","")),0)),SUMPRODUCT((BCC_MA=$B16)*IFERROR(VALUE(SUBSTITUTE($AC$6:$AC$100,"N","")),0)),SUMPRODUCT((BCC_MA=$B16)*IFERROR(VALUE(SUBSTITUTE($AD$6:$AD$100,"N","")),0)),SUMPRODUCT((BCC_MA=$B16)*IFERROR(VALUE(SUBSTITUTE($AE$6:$AE$100,"N","")),0)),SUMPRODUCT((BCC_MA=$B16)*IFERROR(VALUE(SUBSTITUTE($AF$6:$AF$100,"N","")),0)),SUMPRODUCT((BCC_MA=$B16)*IFERROR(VALUE(SUBSTITUTE($AG$6:$AG$100,"N","")),0)),SUMPRODUCT((BCC_MA=$B16)*IFERROR(VALUE(SUBSTITUTE($AH$6:$AH$100,"N","")),0)),SUMPRODUCT((BCC_MA=$B16)*IFERROR(VALUE(SUBSTITUTE($AI$6:$AI$100,"N","")),0)),SUMPRODUCT((BCC_MA=$B16)*IFERROR(VALUE(SUBSTITUTE($AJ$6:$AJ$100,"N","")),0)),SUMPRODUCT((BCC_MA=$B16)*IFERROR(VALUE(SUBSTITUTE($AK$6:$AK$100,"N","")),0)))) -> 8
A17: 12 | B17: RSS-12 | C17: =IF(B17="","",IFERROR(INDEX(NV_TEN,MATCH(B17,NV_MA,0)),"MÃ KHÔNG CÓ")) -> Phan Thị Như Nghĩa | D17: RSS HAPĐ | F17: =IF(D17="","",IFERROR(INDEX(NH_GIO,MATCH(D17,NH_TEN,0)),"NHÓM?")) -> 8 | G17: 8 | H17: 8 | I17: 8 | K17: 4 | AL17: =IF(B17="","",SUMPRODUCT(IFERROR(VALUE(SUBSTITUTE(G17:AK17,"N","")),0))) -> 28 | AM17: =IF(B17="","",AL17/F17) -> 3.5 | AN17: =IF(B17="","",SUMPRODUCT(ISNUMBER(SEARCH("N",G17:AK17))*IFERROR(VALUE(SUBSTITUTE(G17:AK17,"N","")),0))/F17) -> 0 | AR17: =IF(B17="",0,MAX(SUMPRODUCT((BCC_MA=$B17)*IFERROR(VALUE(SUBSTITUTE($G$6:$G$100,"N","")),0)),SUMPRODUCT((BCC_MA=$B17)*IFERROR(VALUE(SUBSTITUTE($H$6:$H$100,"N","")),0)),SUMPRODUCT((BCC_MA=$B17)*IFERROR(VALUE(SUBSTITUTE($I$6:$I$100,"N","")),0)),SUMPRODUCT((BCC_MA=$B17)*IFERROR(VALUE(SUBSTITUTE($J$6:$J$100,"N","")),0)),SUMPRODUCT((BCC_MA=$B17)*IFERROR(VALUE(SUBSTITUTE($K$6:$K$100,"N","")),0)),SUMPRODUCT((BCC_MA=$B17)*IFERROR(VALUE(SUBSTITUTE($L$6:$L$100,"N","")),0)),SUMPRODUCT((BCC_MA=$B17)*IFERROR(VALUE(SUBSTITUTE($M$6:$M$100,"N","")),0)),SUMPRODUCT((BCC_MA=$B17)*IFERROR(VALUE(SUBSTITUTE($N$6:$N$100,"N","")),0)),SUMPRODUCT((BCC_MA=$B17)*IFERROR(VALUE(SUBSTITUTE($O$6:$O$100,"N","")),0)),SUMPRODUCT((BCC_MA=$B17)*IFERROR(VALUE(SUBSTITUTE($P$6:$P$100,"N","")),0)),SUMPRODUCT((BCC_MA=$B17)*IFERROR(VALUE(SUBSTITUTE($Q$6:$Q$100,"N","")),0)),SUMPRODUCT((BCC_MA=$B17)*IFERROR(VALUE(SUBSTITUTE($R$6:$R$100,"N","")),0)),SUMPRODUCT((BCC_MA=$B17)*IFERROR(VALUE(SUBSTITUTE($S$6:$S$100,"N","")),0)),SUMPRODUCT((BCC_MA=$B17)*IFERROR(VALUE(SUBSTITUTE($T$6:$T$100,"N","")),0)),SUMPRODUCT((BCC_MA=$B17)*IFERROR(VALUE(SUBSTITUTE($U$6:$U$100,"N","")),0)),SUMPRODUCT((BCC_MA=$B17)*IFERROR(VALUE(SUBSTITUTE($V$6:$V$100,"N","")),0)),SUMPRODUCT((BCC_MA=$B17)*IFERROR(VALUE(SUBSTITUTE($W$6:$W$100,"N","")),0)),SUMPRODUCT((BCC_MA=$B17)*IFERROR(VALUE(SUBSTITUTE($X$6:$X$100,"N","")),0)),SUMPRODUCT((BCC_MA=$B17)*IFERROR(VALUE(SUBSTITUTE($Y$6:$Y$100,"N","")),0)),SUMPRODUCT((BCC_MA=$B17)*IFERROR(VALUE(SUBSTITUTE($Z$6:$Z$100,"N","")),0)),SUMPRODUCT((BCC_MA=$B17)*IFERROR(VALUE(SUBSTITUTE($AA$6:$AA$100,"N","")),0)),SUMPRODUCT((BCC_MA=$B17)*IFERROR(VALUE(SUBSTITUTE($AB$6:$AB$100,"N","")),0)),SUMPRODUCT((BCC_MA=$B17)*IFERROR(VALUE(SUBSTITUTE($AC$6:$AC$100,"N","")),0)),SUMPRODUCT((BCC_MA=$B17)*IFERROR(VALUE(SUBSTITUTE($AD$6:$AD$100,"N","")),0)),SUMPRODUCT((BCC_MA=$B17)*IFERROR(VALUE(SUBSTITUTE($AE$6:$AE$100,"N","")),0)),SUMPRODUCT((BCC_MA=$B17)*IFERROR(VALUE(SUBSTITUTE($AF$6:$AF$100,"N","")),0)),SUMPRODUCT((BCC_MA=$B17)*IFERROR(VALUE(SUBSTITUTE($AG$6:$AG$100,"N","")),0)),SUMPRODUCT((BCC_MA=$B17)*IFERROR(VALUE(SUBSTITUTE($AH$6:$AH$100,"N","")),0)),SUMPRODUCT((BCC_MA=$B17)*IFERROR(VALUE(SUBSTITUTE($AI$6:$AI$100,"N","")),0)),SUMPRODUCT((BCC_MA=$B17)*IFERROR(VALUE(SUBSTITUTE($AJ$6:$AJ$100,"N","")),0)),SUMPRODUCT((BCC_MA=$B17)*IFERROR(VALUE(SUBSTITUTE($AK$6:$AK$100,"N","")),0)))) -> 8
A18: 13 | B18: RSS-13 | C18: =IF(B18="","",IFERROR(INDEX(NV_TEN,MATCH(B18,NV_MA,0)),"MÃ KHÔNG CÓ")) -> Nguyễn Quyền | D18: RSS HAPĐ | F18: =IF(D18="","",IFERROR(INDEX(NH_GIO,MATCH(D18,NH_TEN,0)),"NHÓM?")) -> 8 | G18: 8 | H18: 8 | I18: 8 | K18: 8 | L18: 8 | P18: 8 | Q18: 8 | R18: 8 | S18: 8 | T18: 8 | U18: 8 | V18: 8 | X18: 8 | Y18: 8 | AL18: =IF(B18="","",SUMPRODUCT(IFERROR(VALUE(SUBSTITUTE(G18:AK18,"N","")),0))) -> 112 | AM18: =IF(B18="","",AL18/F18) -> 14 | AN18: =IF(B18="","",SUMPRODUCT(ISNUMBER(SEARCH("N",G18:AK18))*IFERROR(VALUE(SUBSTITUTE(G18:AK18,"N","")),0))/F18) -> 0 | AR18: =IF(B18="",0,MAX(SUMPRODUCT((BCC_MA=$B18)*IFERROR(VALUE(SUBSTITUTE($G$6:$G$100,"N","")),0)),SUMPRODUCT((BCC_MA=$B18)*IFERROR(VALUE(SUBSTITUTE($H$6:$H$100,"N","")),0)),SUMPRODUCT((BCC_MA=$B18)*IFERROR(VALUE(SUBSTITUTE($I$6:$I$100,"N","")),0)),SUMPRODUCT((BCC_MA=$B18)*IFERROR(VALUE(SUBSTITUTE($J$6:$J$100,"N","")),0)),SUMPRODUCT((BCC_MA=$B18)*IFERROR(VALUE(SUBSTITUTE($K$6:$K$100,"N","")),0)),SUMPRODUCT((BCC_MA=$B18)*IFERROR(VALUE(SUBSTITUTE($L$6:$L$100,"N","")),0)),SUMPRODUCT((BCC_MA=$B18)*IFERROR(VALUE(SUBSTITUTE($M$6:$M$100,"N","")),0)),SUMPRODUCT((BCC_MA=$B18)*IFERROR(VALUE(SUBSTITUTE($N$6:$N$100,"N","")),0)),SUMPRODUCT((BCC_MA=$B18)*IFERROR(VALUE(SUBSTITUTE($O$6:$O$100,"N","")),0)),SUMPRODUCT((BCC_MA=$B18)*IFERROR(VALUE(SUBSTITUTE($P$6:$P$100,"N","")),0)),SUMPRODUCT((BCC_MA=$B18)*IFERROR(VALUE(SUBSTITUTE($Q$6:$Q$100,"N","")),0)),SUMPRODUCT((BCC_MA=$B18)*IFERROR(VALUE(SUBSTITUTE($R$6:$R$100,"N","")),0)),SUMPRODUCT((BCC_MA=$B18)*IFERROR(VALUE(SUBSTITUTE($S$6:$S$100,"N","")),0)),SUMPRODUCT((BCC_MA=$B18)*IFERROR(VALUE(SUBSTITUTE($T$6:$T$100,"N","")),0)),SUMPRODUCT((BCC_MA=$B18)*IFERROR(VALUE(SUBSTITUTE($U$6:$U$100,"N","")),0)),SUMPRODUCT((BCC_MA=$B18)*IFERROR(VALUE(SUBSTITUTE($V$6:$V$100,"N","")),0)),SUMPRODUCT((BCC_MA=$B18)*IFERROR(VALUE(SUBSTITUTE($W$6:$W$100,"N","")),0)),SUMPRODUCT((BCC_MA=$B18)*IFERROR(VALUE(SUBSTITUTE($X$6:$X$100,"N","")),0)),SUMPRODUCT((BCC_MA=$B18)*IFERROR(VALUE(SUBSTITUTE($Y$6:$Y$100,"N","")),0)),SUMPRODUCT((BCC_MA=$B18)*IFERROR(VALUE(SUBSTITUTE($Z$6:$Z$100,"N","")),0)),SUMPRODUCT((BCC_MA=$B18)*IFERROR(VALUE(SUBSTITUTE($AA$6:$AA$100,"N","")),0)),SUMPRODUCT((BCC_MA=$B18)*IFERROR(VALUE(SUBSTITUTE($AB$6:$AB$100,"N","")),0)),SUMPRODUCT((BCC_MA=$B18)*IFERROR(VALUE(SUBSTITUTE($AC$6:$AC$100,"N","")),0)),SUMPRODUCT((BCC_MA=$B18)*IFERROR(VALUE(SUBSTITUTE($AD$6:$AD$100,"N","")),0)),SUMPRODUCT((BCC_MA=$B18)*IFERROR(VALUE(SUBSTITUTE($AE$6:$AE$100,"N","")),0)),SUMPRODUCT((BCC_MA=$B18)*IFERROR(VALUE(SUBSTITUTE($AF$6:$AF$100,"N","")),0)),SUMPRODUCT((BCC_MA=$B18)*IFERROR(VALUE(SUBSTITUTE($AG$6:$AG$100,"N","")),0)),SUMPRODUCT((BCC_MA=$B18)*IFERROR(VALUE(SUBSTITUTE($AH$6:$AH$100,"N","")),0)),SUMPRODUCT((BCC_MA=$B18)*IFERROR(VALUE(SUBSTITUTE($AI$6:$AI$100,"N","")),0)),SUMPRODUCT((BCC_MA=$B18)*IFERROR(VALUE(SUBSTITUTE($AJ$6:$AJ$100,"N","")),0)),SUMPRODUCT((BCC_MA=$B18)*IFERROR(VALUE(SUBSTITUTE($AK$6:$AK$100,"N","")),0)))) -> 8
A19: 14 | B19: RSS-14 | C19: =IF(B19="","",IFERROR(INDEX(NV_TEN,MATCH(B19,NV_MA,0)),"MÃ KHÔNG CÓ")) -> Lê Quốc Vượng | D19: RSS HAPĐ | F19: =IF(D19="","",IFERROR(INDEX(NH_GIO,MATCH(D19,NH_TEN,0)),"NHÓM?")) -> 8 | H19: 8 | I19: 8 | AL19: =IF(B19="","",SUMPRODUCT(IFERROR(VALUE(SUBSTITUTE(G19:AK19,"N","")),0))) -> 16 | AM19: =IF(B19="","",AL19/F19) -> 2 | AN19: =IF(B19="","",SUMPRODUCT(ISNUMBER(SEARCH("N",G19:AK19))*IFERROR(VALUE(SUBSTITUTE(G19:AK19,"N","")),0))/F19) -> 0 | AR19: =IF(B19="",0,MAX(SUMPRODUCT((BCC_MA=$B19)*IFERROR(VALUE(SUBSTITUTE($G$6:$G$100,"N","")),0)),SUMPRODUCT((BCC_MA=$B19)*IFERROR(VALUE(SUBSTITUTE($H$6:$H$100,"N","")),0)),SUMPRODUCT((BCC_MA=$B19)*IFERROR(VALUE(SUBSTITUTE($I$6:$I$100,"N","")),0)),SUMPRODUCT((BCC_MA=$B19)*IFERROR(VALUE(SUBSTITUTE($J$6:$J$100,"N","")),0)),SUMPRODUCT((BCC_MA=$B19)*IFERROR(VALUE(SUBSTITUTE($K$6:$K$100,"N","")),0)),SUMPRODUCT((BCC_MA=$B19)*IFERROR(VALUE(SUBSTITUTE($L$6:$L$100,"N","")),0)),SUMPRODUCT((BCC_MA=$B19)*IFERROR(VALUE(SUBSTITUTE($M$6:$M$100,"N","")),0)),SUMPRODUCT((BCC_MA=$B19)*IFERROR(VALUE(SUBSTITUTE($N$6:$N$100,"N","")),0)),SUMPRODUCT((BCC_MA=$B19)*IFERROR(VALUE(SUBSTITUTE($O$6:$O$100,"N","")),0)),SUMPRODUCT((BCC_MA=$B19)*IFERROR(VALUE(SUBSTITUTE($P$6:$P$100,"N","")),0)),SUMPRODUCT((BCC_MA=$B19)*IFERROR(VALUE(SUBSTITUTE($Q$6:$Q$100,"N","")),0)),SUMPRODUCT((BCC_MA=$B19)*IFERROR(VALUE(SUBSTITUTE($R$6:$R$100,"N","")),0)),SUMPRODUCT((BCC_MA=$B19)*IFERROR(VALUE(SUBSTITUTE($S$6:$S$100,"N","")),0)),SUMPRODUCT((BCC_MA=$B19)*IFERROR(VALUE(SUBSTITUTE($T$6:$T$100,"N","")),0)),SUMPRODUCT((BCC_MA=$B19)*IFERROR(VALUE(SUBSTITUTE($U$6:$U$100,"N","")),0)),SUMPRODUCT((BCC_MA=$B19)*IFERROR(VALUE(SUBSTITUTE($V$6:$V$100,"N","")),0)),SUMPRODUCT((BCC_MA=$B19)*IFERROR(VALUE(SUBSTITUTE($W$6:$W$100,"N","")),0)),SUMPRODUCT((BCC_MA=$B19)*IFERROR(VALUE(SUBSTITUTE($X$6:$X$100,"N","")),0)),SUMPRODUCT((BCC_MA=$B19)*IFERROR(VALUE(SUBSTITUTE($Y$6:$Y$100,"N","")),0)),SUMPRODUCT((BCC_MA=$B19)*IFERROR(VALUE(SUBSTITUTE($Z$6:$Z$100,"N","")),0)),SUMPRODUCT((BCC_MA=$B19)*IFERROR(VALUE(SUBSTITUTE($AA$6:$AA$100,"N","")),0)),SUMPRODUCT((BCC_MA=$B19)*IFERROR(VALUE(SUBSTITUTE($AB$6:$AB$100,"N","")),0)),SUMPRODUCT((BCC_MA=$B19)*IFERROR(VALUE(SUBSTITUTE($AC$6:$AC$100,"N","")),0)),SUMPRODUCT((BCC_MA=$B19)*IFERROR(VALUE(SUBSTITUTE($AD$6:$AD$100,"N","")),0)),SUMPRODUCT((BCC_MA=$B19)*IFERROR(VALUE(SUBSTITUTE($AE$6:$AE$100,"N","")),0)),SUMPRODUCT((BCC_MA=$B19)*IFERROR(VALUE(SUBSTITUTE($AF$6:$AF$100,"N","")),0)),SUMPRODUCT((BCC_MA=$B19)*IFERROR(VALUE(SUBSTITUTE($AG$6:$AG$100,"N","")),0)),SUMPRODUCT((BCC_MA=$B19)*IFERROR(VALUE(SUBSTITUTE($AH$6:$AH$100,"N","")),0)),SUMPRODUCT((BCC_MA=$B19)*IFERROR(VALUE(SUBSTITUTE($AI$6:$AI$100,"N","")),0)),SUMPRODUCT((BCC_MA=$B19)*IFERROR(VALUE(SUBSTITUTE($AJ$6:$AJ$100,"N","")),0)),SUMPRODUCT((BCC_MA=$B19)*IFERROR(VALUE(SUBSTITUTE($AK$6:$AK$100,"N","")),0)))) -> 8
A20: 15 | B20: RSS-15 | C20: =IF(B20="","",IFERROR(INDEX(NV_TEN,MATCH(B20,NV_MA,0)),"MÃ KHÔNG CÓ")) -> Ngô Quý Anh Tuấn | D20: RSS HAPĐ | F20: =IF(D20="","",IFERROR(INDEX(NH_GIO,MATCH(D20,NH_TEN,0)),"NHÓM?")) -> 8 | G20: 8 | H20: 8 | I20: 8 | J20: 8 | K20: 8 | L20: 8 | AL20: =IF(B20="","",SUMPRODUCT(IFERROR(VALUE(SUBSTITUTE(G20:AK20,"N","")),0))) -> 48 | AM20: =IF(B20="","",AL20/F20) -> 6 | AN20: =IF(B20="","",SUMPRODUCT(ISNUMBER(SEARCH("N",G20:AK20))*IFERROR(VALUE(SUBSTITUTE(G20:AK20,"N","")),0))/F20) -> 0 | AR20: =IF(B20="",0,MAX(SUMPRODUCT((BCC_MA=$B20)*IFERROR(VALUE(SUBSTITUTE($G$6:$G$100,"N","")),0)),SUMPRODUCT((BCC_MA=$B20)*IFERROR(VALUE(SUBSTITUTE($H$6:$H$100,"N","")),0)),SUMPRODUCT((BCC_MA=$B20)*IFERROR(VALUE(SUBSTITUTE($I$6:$I$100,"N","")),0)),SUMPRODUCT((BCC_MA=$B20)*IFERROR(VALUE(SUBSTITUTE($J$6:$J$100,"N","")),0)),SUMPRODUCT((BCC_MA=$B20)*IFERROR(VALUE(SUBSTITUTE($K$6:$K$100,"N","")),0)),SUMPRODUCT((BCC_MA=$B20)*IFERROR(VALUE(SUBSTITUTE($L$6:$L$100,"N","")),0)),SUMPRODUCT((BCC_MA=$B20)*IFERROR(VALUE(SUBSTITUTE($M$6:$M$100,"N","")),0)),SUMPRODUCT((BCC_MA=$B20)*IFERROR(VALUE(SUBSTITUTE($N$6:$N$100,"N","")),0)),SUMPRODUCT((BCC_MA=$B20)*IFERROR(VALUE(SUBSTITUTE($O$6:$O$100,"N","")),0)),SUMPRODUCT((BCC_MA=$B20)*IFERROR(VALUE(SUBSTITUTE($P$6:$P$100,"N","")),0)),SUMPRODUCT((BCC_MA=$B20)*IFERROR(VALUE(SUBSTITUTE($Q$6:$Q$100,"N","")),0)),SUMPRODUCT((BCC_MA=$B20)*IFERROR(VALUE(SUBSTITUTE($R$6:$R$100,"N","")),0)),SUMPRODUCT((BCC_MA=$B20)*IFERROR(VALUE(SUBSTITUTE($S$6:$S$100,"N","")),0)),SUMPRODUCT((BCC_MA=$B20)*IFERROR(VALUE(SUBSTITUTE($T$6:$T$100,"N","")),0)),SUMPRODUCT((BCC_MA=$B20)*IFERROR(VALUE(SUBSTITUTE($U$6:$U$100,"N","")),0)),SUMPRODUCT((BCC_MA=$B20)*IFERROR(VALUE(SUBSTITUTE($V$6:$V$100,"N","")),0)),SUMPRODUCT((BCC_MA=$B20)*IFERROR(VALUE(SUBSTITUTE($W$6:$W$100,"N","")),0)),SUMPRODUCT((BCC_MA=$B20)*IFERROR(VALUE(SUBSTITUTE($X$6:$X$100,"N","")),0)),SUMPRODUCT((BCC_MA=$B20)*IFERROR(VALUE(SUBSTITUTE($Y$6:$Y$100,"N","")),0)),SUMPRODUCT((BCC_MA=$B20)*IFERROR(VALUE(SUBSTITUTE($Z$6:$Z$100,"N","")),0)),SUMPRODUCT((BCC_MA=$B20)*IFERROR(VALUE(SUBSTITUTE($AA$6:$AA$100,"N","")),0)),SUMPRODUCT((BCC_MA=$B20)*IFERROR(VALUE(SUBSTITUTE($AB$6:$AB$100,"N","")),0)),SUMPRODUCT((BCC_MA=$B20)*IFERROR(VALUE(SUBSTITUTE($AC$6:$AC$100,"N","")),0)),SUMPRODUCT((BCC_MA=$B20)*IFERROR(VALUE(SUBSTITUTE($AD$6:$AD$100,"N","")),0)),SUMPRODUCT((BCC_MA=$B20)*IFERROR(VALUE(SUBSTITUTE($AE$6:$AE$100,"N","")),0)),SUMPRODUCT((BCC_MA=$B20)*IFERROR(VALUE(SUBSTITUTE($AF$6:$AF$100,"N","")),0)),SUMPRODUCT((BCC_MA=$B20)*IFERROR(VALUE(SUBSTITUTE($AG$6:$AG$100,"N","")),0)),SUMPRODUCT((BCC_MA=$B20)*IFERROR(VALUE(SUBSTITUTE($AH$6:$AH$100,"N","")),0)),SUMPRODUCT((BCC_MA=$B20)*IFERROR(VALUE(SUBSTITUTE($AI$6:$AI$100,"N","")),0)),SUMPRODUCT((BCC_MA=$B20)*IFERROR(VALUE(SUBSTITUTE($AJ$6:$AJ$100,"N","")),0)),SUMPRODUCT((BCC_MA=$B20)*IFERROR(VALUE(SUBSTITUTE($AK$6:$AK$100,"N","")),0)))) -> 8
