Workbook

Sheet HDSD
A1: LƯƠNG THỜI GIAN – BẢNG CHẤM CÔNG & BẢNG LƯƠNG CHUẨN HOÁ (dùng chung HAPĐ – HAQT – APQT)
A2: Thay cho các sheet "BCC lương thời gian", "Chuyên cần", "Bảng lương", "BHXH" của 3 file lương nội bộ. Một bảng công duy nhất, một bộ ký hiệu, mọi ngoại lệ ghi ở DIEU_CHINH có lý do.
A4: QUY ƯỚC MÀU
A5: Chữ xanh, nền vàng nhạt | B5: Ô nhập liệu
A6: Nền vàng đậm | B6: Tham số/định mức – chỉ HCNS đổi khi có quyết định
A7: Chữ đen | B7: Công thức, đã khoá
A8: Nền xanh lá | B8: Kết quả cuối (Thực nhận, Tổng lương) – số đưa sang ĐNTT / chuyển khoản
A10: QUY TRÌNH HÀNG THÁNG
A11: 1. THAM_SO | B11: Nhập tháng, năm. Ngày lễ trong tháng nhập vào bảng ngày lễ (để cảnh báo nếu chấm giờ thường vào ngày lễ).
A12: 2. NHAN_VIEN | B12: Thêm/sửa người: pháp nhân, hình thức (Thời gian / Khoán tháng / Thử việc), công chuẩn 26 hay 30, lương CB, lương BHXH, phụ cấp cố định, nhóm chuyên cần. Người nghỉ: đổi Tình trạng, không xoá.
A13: 3. BCC | B13: Chấm 1 dòng/người, ô = số giờ (0–24, bội số 0,5) HOẶC mã trong KY_HIEU. Không gõ gì khác (ô sẽ báo đỏ). Điền Người chấm / Người duyệt.
A14: 4. DIEU_CHINH | B14: Tạm ứng, trả nợ, truy lĩnh, KPI, chuyên cần điều chỉnh… mỗi khoản 1 dòng, có lý do & người duyệt. KHÔNG sửa tay vào LUONG.
A15: 5. LUONG, BHXH | B15: Tự tính. Không có ô nhập.
A16: 6. KIEM_TRA | B16: Tất cả OK mới chốt. Sau đó lưu file với tên LUONG_TG_<YYYY-MM>_vN.xlsx.
A18: ĐỐI CHIẾU VỚI SHEET CŨ
A19: BCC lương thời gian + Chuyên cần (APQT có 2 bản trùng) | B19: → BCC (một bản duy nhất, Chuyên cần tính từ đây)
A20: Công thức AM/AN (SUM giờ + COUNTIF L1..L24 …) | B20: → BCC cột AJ–AP, dựa trên bảng KY_HIEU thay vì gõ trong công thức
A21: Bảng lương cột S (thời gian), T (chuyên cần), U (phép), V (lễ), X (BHXH), AC (thực nhận) | B21: → LUONG cột R, W, S, T, AA, AF
A22: Ghi chú "Trừ nợ 1,5tr/tháng đến 12/2027", "tạm ứng 3tr", chuyên cần sửa tay | B22: → DIEU_CHINH, có hiệu lực từ/đến
A23: Ngày 30/31 gõ cứng 1900-01-30 | B23: → BCC dòng 3–4 tự sinh theo tháng; cột ngày không tồn tại bị tô xám và khoá
A24: Tiêu đề/tháng gõ tay, "Bằng chữ" gõ tay | B24: → mọi tiêu đề lấy từ THAM_SO
A26: KIỂM CHỨNG | B26: Dữ liệu tháng 08/2026 của APQT (13 người) và HAQT (3 người) đã nạp làm mẫu; LUONG cột AF khớp cột AC "THỰC NHẬN" của file cũ sau khi đưa 3 khoản chuyên cần sửa tay vào DIEU_CHINH.

Sheet THAM_SO
A1: THAM SỐ KỲ LƯƠNG THỜI GIAN
B3: Tháng | C3: 8
B4: Năm | C4: 2026
B6: Số ngày chia lương phép / lễ / chế độ (theo lương BHXH) | C6: 26 | D6: File cũ luôn chia /26 kể cả người công chuẩn 30 (APQT U8 = 6.928.000/26×1)
B7: Tỷ lệ lương thử việc (nếu không khai lương thử việc riêng) | C7: 0.85
B8: Hệ số cộng thêm cho giờ làm ngày lễ (L1…L24) | C8: 1.5 | D8: File cũ: W = lương CB/công chuẩn × ngày lễ đi làm × 150%, cộng thêm ngoài giờ đã tính công
B9: Chuyên cần nhóm "Chung": ngưỡng công | C9: 29 | D9: APQT/HAPĐ: ≥ 29 công → 300.000; người khoán tháng / công chuẩn 30 không xét (nhóm "Không")
B10: Chuyên cần nhóm "Chung": tiền thưởng | C10: 300000
B11: Chuyên cần nhóm "Cơ điện": ngưỡng 1 (công) / tiền | C11: 26 | D11: Sheet "Chuyên cần điện" HAPĐ: >26 → 500.000; >40 → 700.000
B12: tiền mức 1 | C12: 500000
B13: ngưỡng 2 (công) | C13: 40
B14: tiền mức 2 | C14: 700000
B15: BHXH người lao động (8% + 1,5% + 1%) | C15: 0.105
B16: BHXH người sử dụng lao động (17,5% + 3% + 1%) | C16: 0.215
B17: Giờ của 1 công | C17: 8
B18: Làm tròn xuống thực nhận (đ) | C18: 1000
B19: Cảnh báo nếu giờ/ngày lớn hơn | C19: 12
B21: NGÀY LỄ TRONG THÁNG (để cảnh báo)
D22: Nhập ngày (vd 02/09/2026). Nếu ô chấm công ngày lễ là số giờ thường (không phải NL/L-n) → KIEM_TRA cảnh báo.

Sheet KY_HIEU
A1: BẢNG KÝ HIỆU CHẤM CÔNG DÙNG CHUNG
A2: Ô chấm công = số giờ (0–24, bội số 0,5) hoặc một mã dưới đây. Mỗi mã quy ra giờ cho từng loại. Thêm mã mới = thêm dòng, công thức BCC tự nhận.
A4: Mã | B4: Ý nghĩa | C4: Giờ tính lương | D4: Giờ phép | E4: Giờ nghỉ lễ | F4: Giờ làm ngày lễ (cộng thêm) | G4: Giờ chế độ cty (hiếu hỉ) | H4: Giờ công tác Lào | I4: Ghi chú
A5: P | B5: Nghỉ phép năm 1 ngày | C5: 0 | D5: 8 | E5: 0 | F5: 0 | G5: 0 | H5: 0
A6: P/2 | B6: Nghỉ phép 0,5 ngày | C6: 0 | D6: 4 | E6: 0 | F6: 0 | G6: 0 | H6: 0
A7: NL | B7: Nghỉ lễ hưởng lương | C7: 0 | D7: 0 | E7: 8 | F7: 0 | G7: 0 | H7: 0 | I7: File cũ ghi "NL"
A8: NL/2 | B8: Nghỉ lễ 0,5 ngày | C8: 0 | D8: 0 | E8: 4 | F8: 0 | G8: 0 | H8: 0 | I8: File cũ ghi "NL\"
A9: CTL | B9: Công tác Lào 1 ngày | C9: 8 | D9: 0 | E9: 0 | F9: 0 | G9: 0 | H9: 8 | I9: Tính 8h công + đếm ngày CTL
A10: CTL/2 | B10: Công tác Lào 0,5 ngày | C10: 4 | D10: 0 | E10: 0 | F10: 0 | G10: 0 | H10: 4
A11: CT | B11: Công tác (có công tác phí) | C11: 8 | D11: 0 | E11: 0 | F11: 0 | G11: 0 | H11: 0
A12: H | B12: Nghỉ chế độ công ty hiếu, hỉ 1 ngày | C12: 0 | D12: 0 | E12: 0 | F12: 0 | G12: 8 | H12: 0 | I12: HAPĐ
A13: H/2 | B13: Nghỉ chế độ 0,5 ngày | C13: 0 | D13: 0 | E13: 0 | F13: 0 | G13: 4 | H13: 0
A14: CĐ | B14: Nghỉ chế độ BHXH (ốm, thai sản…) | C14: 0 | D14: 0 | E14: 0 | F14: 0 | G14: 0 | H14: 0 | I14: Không tính lương; BHXH chi trả
A15: KL | B15: Nghỉ không lương | C15: 0 | D15: 0 | E15: 0 | F15: 0 | G15: 0 | H15: 0
A16: X | B16: Nghỉ không phép | C16: 0 | D16: 0 | E16: 0 | F16: 0 | G16: 0 | H16: 0 | I16: Cảnh báo ở KIEM_TRA
A17: L1 | B17: Nghỉ lễ nhưng đi làm 1 giờ | C17: 1 | D17: 0 | E17: 8 | F17: 1 | G17: 0 | H17: 0 | I17: File cũ: giờ vào công + 150% cộng thêm; ngày vẫn hưởng lễ
A18: L2 | B18: Nghỉ lễ nhưng đi làm 2 giờ | C18: 2 | D18: 0 | E18: 8 | F18: 2 | G18: 0 | H18: 0
A19: L3 | B19: Nghỉ lễ nhưng đi làm 3 giờ | C19: 3 | D19: 0 | E19: 8 | F19: 3 | G19: 0 | H19: 0
A20: L4 | B20: Nghỉ lễ nhưng đi làm 4 giờ | C20: 4 | D20: 0 | E20: 8 | F20: 4 | G20: 0 | H20: 0
A21: L5 | B21: Nghỉ lễ nhưng đi làm 5 giờ | C21: 5 | D21: 0 | E21: 8 | F21: 5 | G21: 0 | H21: 0
A22: L6 | B22: Nghỉ lễ nhưng đi làm 6 giờ | C22: 6 | D22: 0 | E22: 8 | F22: 6 | G22: 0 | H22: 0
A23: L7 | B23: Nghỉ lễ nhưng đi làm 7 giờ | C23: 7 | D23: 0 | E23: 8 | F23: 7 | G23: 0 | H23: 0
A24: L8 | B24: Nghỉ lễ nhưng đi làm 8 giờ | C24: 8 | D24: 0 | E24: 8 | F24: 8 | G24: 0 | H24: 0
A25: L9 | B25: Nghỉ lễ nhưng đi làm 9 giờ | C25: 9 | D25: 0 | E25: 8 | F25: 9 | G25: 0 | H25: 0
A26: L10 | B26: Nghỉ lễ nhưng đi làm 10 giờ | C26: 10 | D26: 0 | E26: 8 | F26: 10 | G26: 0 | H26: 0
A27: L11 | B27: Nghỉ lễ nhưng đi làm 11 giờ | C27: 11 | D27: 0 | E27: 8 | F27: 11 | G27: 0 | H27: 0
A28: L12 | B28: Nghỉ lễ nhưng đi làm 12 giờ | C28: 12 | D28: 0 | E28: 8 | F28: 12 | G28: 0 | H28: 0
A29: L13 | B29: Nghỉ lễ nhưng đi làm 13 giờ | C29: 13 | D29: 0 | E29: 8 | F29: 13 | G29: 0 | H29: 0
... A40: L24 | B40: Nghỉ lễ nhưng đi làm 24 giờ | C40: 24 | D40: 0 | E40: 8 | F40: 24 | G40: 0 | H40: 0

Sheet NHAN_VIEN
A1: DANH MỤC NHÂN VIÊN LƯƠNG THỜI GIAN (3 pháp nhân)
A2: Mã NV là khoá; mọi sheet tra theo mã. Không lưu CCCD/STK ở đây – để trong hồ sơ nhân sự có mật khẩu.
A4: STT | B4: Mã NV | C4: Họ và tên | D4: Pháp nhân | E4: Bộ phận | F4: Chức vụ | G4: Hình thức | H4: Công chuẩn | I4: Lương cơ bản | J4: Lương thử việc (nếu có) | K4: Lương BHXH | L4: Đóng BHXH | M4: Phụ cấp cố định/tháng | N4: Nhóm chuyên cần | O4: Ngày vào | P4: Tình trạng | Q4: Ghi chú
A5: 1 | B5: 046180000983 | C5: Hồ Thị Ngọc Á | D5: APQT | E5: Cơ khí chế tạo | F5: Kế toán trưởng | G5: Khoán tháng | H5: 26 | I5: 16000000 | K5: 6928000 | L5: Có | M5: 2000000 | N5: Không | O5: 18/07/2024 | P5: Chính thức
A6: 2 | B6: 045086000771 | C6: Nguyễn Nhật Tân | D6: APQT | E6: Cơ khí chế tạo | F6: Phó giám đốc | G6: Thời gian | H6: 30 | I6: 15000000 | K6: 6928000 | L6: Có | M6: 2000000 | N6: Không | O6: 01/05/2026 | P6: Chính thức
A7: 3 | B7: 046077009424 | C7: Đặng Quang Chung | D7: APQT | E7: Cơ khí chế tạo | F7: Tổ trưởng CKCT | G7: Thời gian | H7: 30 | I7: 17000000 | K7: 6928000 | L7: Có | M7: 0 | N7: Không | O7: 1/2017 | P7: Chính thức | Q7: Tăng lương lên 17tr từ 19/09 -31/12/2025 Tăng BHXH lên 6.928.000 từ 01/11/2025
A8: 4 | B8: 046086012110 | C8: Nguyễn Hào | D8: APQT | E8: Cơ khí chế tạo | F8: Nhân viên CKCT | G8: Thời gian | H8: 26 | I8: 9620000 | K8: 4375000 | L8: Có | M8: 0 | N8: Chung | O8: 2/12/2023 | P8: Chính thức
A9: 5 | B9: 046485004744 | C9: Nguyễn Mạnh Thắng | D9: APQT | E9: Cơ khí chế tạo | F9: Nhân viên CKCT | G9: Thời gian | H9: 26 | I9: 9620000 | K9: 4163000 | L9: Có | M9: 0 | N9: Chung | O9: 5/12/2023 | P9: Chính thức
A10: 6 | B10: 046092012558 | C10: Nguyễn Quang Quốc | D10: APQT | E10: Cơ khí chế tạo | F10: Nhân viên CKCT | G10: Thời gian | H10: 26 | I10: 9620000 | K10: 4163000 | L10: Có | M10: 0 | N10: Chung | O10: 8/12/2023 | P10: Chính thức
A11: 7 | B11: 046066004079 | C11: Trần Đình Chiến | D11: APQT | E11: Cơ khí chế tạo | F11: Nhân viên CKCT | G11: Thời gian | H11: 30 | I11: 15000000 | K11: 4163000 | L11: Có | M11: 500000 | N11: Không | O11: 03/03/2024 | P11: Chính thức | Q11: Đã có quyết định nâng lương lên 15tr từ 01/04/2026
A12: 8 | B12: 046078005974 | C12: Phạm Bá Vinh | D12: APQT | E12: Cơ khí chế tạo | F12: Tổ phó CKCT | G12: Thời gian | H12: 26 | I12: 9620000 | K12: 4163000 | L12: Có | M12: 500000 | N12: Chung | O12: 01/06/2025 | P12: Chính thức
A13: 9 | B13: 046080010214 | C13: Nguyễn Văn Cường | D13: APQT | E13: Cơ khí chế tạo | F13: Nhân viên CKCT | G13: Thời gian | H13: 26 | I13: 9620000 | K13: 4163000 | L13: Có | M13: 500000 | N13: Chung | O13: 01/06/2025 | P13: Chính thức | Q13: Trung báo có quyết định đổi thành tổ phó từ… nên có phụ cấp từ tháng 10/2025
A14: 10 | B14: 046097006456 | C14: Mai Bá Trung | D14: APQT | E14: Cơ khí chế tạo | F14: Nhân viên CKCT | G14: Thời gian | H14: 26 | I14: 9620000 | K14: 4163000 | L14: Có | M14: 0 | N14: Chung | O14: 01/06/2025 | P14: Chính thức
A15: 11 | B15: 046078006770 | C15: Cao Phước Tiến | D15: APQT | E15: Cơ khí chế tạo | F15: Nhân viên CKCT | G15: Thời gian | H15: 26 | I15: 10000000 | K15: 4163000 | L15: Có | M15: 1000000 | N15: Chung | O15: 01/06/2025 | P15: Chính thức | Q15: Trừ lương từ tháng 07/2025 đến hết tháng 12/2027 tiền nợ công ty, mỗi tháng thu 1,5 triệu, riêng tháng 12/2027 thu 900.000đ theo kế hoạch trả nợ
A16: 12 | B16: 046090009551 | C16: Nguyễn Ngọc Thanh | D16: APQT | E16: Cơ khí chế tạo | F16: Nhân viên CKCT | G16: Thời gian | H16: 26 | I16: 11600000 | K16: 4163000 | L16: Có | M16: 1000000 | N16: Chung | O16: 2025-09-19 00:00:00 | P16: Chính thức | Q16: Thử việc 9tr, BHXH từ 01/11/2025 Tính lương chính thức 11.6tr/26 công từ 21/10/2025, Lê Trung báo phụ cấp 1tr từ 01/02/2026, chưa trả hồ sơ
A17: 13 | B17: 046208001119 | C17: Dương Vinh Quang | D17: APQT | E17: Cơ khí chế tạo | F17: Phụ bảo dưỡng xe | G17: Thời gian | H17: 26 | I17: 8000000 | K17: 4163000 | L17: Có | M17: 0 | N17: Chung | O17: 22/05/2026 | P17: Chính thức | Q17: Ký hợp đồng ngày 22/05/2026
A18: 14 | B18: 045086003213 | C18: Hoàng Xuân Quang | D18: HAQT | E18: Cơ điện | F18: Cơ điện | G18: Thời gian | H18: 26 | I18: 9832000 | K18: 4920000 | L18: Có | M18: 2000000 | N18: Không | O18: 15/06/2024 | P18: Chính thức | Q18: PC mùa vụ 2.000.000 từ 15/05/2026
A19: 15 | B19: 044058002123 | C19: Trần Văn Khai | D19: HAQT | E19: Bảo vệ | F19: Nhân viên bảo vệ | G19: Khoán tháng | H19: 26 | I19: 6000000 | K19: 0 | L19: Không | M19: 1260000 | N19: Không | P19: Thời vụ | Q19: PC ăn bảo vệ 260.000 + PC mùa vụ 1.000.000
A20: 16 | B20: 045089005452 | C20: Lê Văn Dũng | D20: HAQT | E20: Bảo vệ | F20: Nhân viên bảo vệ | G20: Khoán tháng | H20: 26 | I20: 6000000 | K20: 0 | L20: Không | M20: 260000 | N20: Không | P20: Thời vụ | Q20: PC ăn bảo vệ 260.000
A21: 17 | B21: TV_MAU_01 | C21: (Ví dụ) Nguyễn Văn B | D21: HAPD | E21: Kỹ thuật | F21: NV bảo trì | G21: Thử việc | H21: 26 | I21: 9000000 | K21: 0 | L21: Không | M21: 0 | N21: Cơ điện | O21: 01/09/2026 | P21: Thử việc | Q21: DÒNG VÍ DỤ: thử việc 85% lương CB, chuyên cần nhóm Cơ điện

Sheet BCC
A1: BẢNG CHẤM CÔNG THỜI GIAN – một bảng duy nhất cho 3 pháp nhân
A2: Ô = số giờ hoặc mã KY_HIEU. Cột ngày không tồn tại trong tháng bị tô xám. Ô đỏ = giá trị không hợp lệ hoặc > giờ tối đa. Cột CN tô nhạt.
E3: =IF(0<DAY(EOMONTH(DATE(NAM,THANG,1),0)),DATE(NAM,THANG,1)+0,"") -> 46235 | F3: =IF(1<DAY(EOMONTH(DATE(NAM,THANG,1),0)),DATE(NAM,THANG,1)+1,"") -> 46236 | G3: =IF(2<DAY(EOMONTH(DATE(NAM,THANG,1),0)),DATE(NAM,THANG,1)+2,"") -> 46237 | H3: =IF(3<DAY(EOMONTH(DATE(NAM,THANG,1),0)),DATE(NAM,THANG,1)+3,"") -> 46238 | I3: =IF(4<DAY(EOMONTH(DATE(NAM,THANG,1),0)),DATE(NAM,THANG,1)+4,"") -> 46239 | J3: =IF(5<DAY(EOMONTH(DATE(NAM,THANG,1),0)),DATE(NAM,THANG,1)+5,"") -> 46240 | K3: =IF(6<DAY(EOMONTH(DATE(NAM,THANG,1),0)),DATE(NAM,THANG,1)+6,"") -> 46241 | L3: =IF(7<DAY(EOMONTH(DATE(NAM,THANG,1),0)),DATE(NAM,THANG,1)+7,"") -> 46242 | M3: =IF(8<DAY(EOMONTH(DATE(NAM,THANG,1),0)),DATE(NAM,THANG,1)+8,"") -> 46243 | N3: =IF(9<DAY(EOMONTH(DATE(NAM,THANG,1),0)),DATE(NAM,THANG,1)+9,"") -> 46244 | O3: =IF(10<DAY(EOMONTH(DATE(NAM,THANG,1),0)),DATE(NAM,THANG,1)+10,"") -> 46245 | P3: =IF(11<DAY(EOMONTH(DATE(NAM,THANG,1),0)),DATE(NAM,THANG,1)+11,"") -> 46246 | Q3: =IF(12<DAY(EOMONTH(DATE(NAM,THANG,1),0)),DATE(NAM,THANG,1)+12,"") -> 46247 | R3: =IF(13<DAY(EOMONTH(DATE(NAM,THANG,1),0)),DATE(NAM,THANG,1)+13,"") -> 46248 | S3: =IF(14<DAY(EOMONTH(DATE(NAM,THANG,1),0)),DATE(NAM,THANG,1)+14,"") -> 46249 | T3: =IF(15<DAY(EOMONTH(DATE(NAM,THANG,1),0)),DATE(NAM,THANG,1)+15,"") -> 46250 | U3: =IF(16<DAY(EOMONTH(DATE(NAM,THANG,1),0)),DATE(NAM,THANG,1)+16,"") -> 46251 | V3: =IF(17<DAY(EOMONTH(DATE(NAM,THANG,1),0)),DATE(NAM,THANG,1)+17,"") -> 46252 | W3: =IF(18<DAY(EOMONTH(DATE(NAM,THANG,1),0)),DATE(NAM,THANG,1)+18,"") -> 46253 | X3: =IF(19<DAY(EOMONTH(DATE(NAM,THANG,1),0)),DATE(NAM,THANG,1)+19,"") -> 46254 | Y3: =IF(20<DAY(EOMONTH(DATE(NAM,THANG,1),0)),DATE(NAM,THANG,1)+20,"") -> 46255 | Z3: =IF(21<DAY(EOMONTH(DATE(NAM,THANG,1),0)),DATE(NAM,THANG,1)+21,"") -> 46256 | AA3: =IF(22<DAY(EOMONTH(DATE(NAM,THANG,1),0)),DATE(NAM,THANG,1)+22,"") -> 46257 | AB3: =IF(23<DAY(EOMONTH(DATE(NAM,THANG,1),0)),DATE(NAM,THANG,1)+23,"") -> 46258 | AC3: =IF(24<DAY(EOMONTH(DATE(NAM,THANG,1),0)),DATE(NAM,THANG,1)+24,"") -> 46259 | AD3: =IF(25<DAY(EOMONTH(DATE(NAM,THANG,1),0)),DATE(NAM,THANG,1)+25,"") -> 46260 | AE3: =IF(26<DAY(EOMONTH(DATE(NAM,THANG,1),0)),DATE(NAM,THANG,1)+26,"") -> 46261 | AF3: =IF(27<DAY(EOMONTH(DATE(NAM,THANG,1),0)),DATE(NAM,THANG,1)+27,"") -> 46262 | AG3: =IF(28<DAY(EOMONTH(DATE(NAM,THANG,1),0)),DATE(NAM,THANG,1)+28,"") -> 46263 | AH3: =IF(29<DAY(EOMONTH(DATE(NAM,THANG,1),0)),DATE(NAM,THANG,1)+29,"") -> 46264 | AI3: =IF(30<DAY(EOMONTH(DATE(NAM,THANG,1),0)),DATE(NAM,THANG,1)+30,"") -> 46265
E4: =IF(E3="","",CHOOSE(WEEKDAY(E3),"CN","T2","T3","T4","T5","T6","T7")) -> T7 | F4: =IF(F3="","",CHOOSE(WEEKDAY(F3),"CN","T2","T3","T4","T5","T6","T7")) -> CN | G4: =IF(G3="","",CHOOSE(WEEKDAY(G3),"CN","T2","T3","T4","T5","T6","T7")) -> T2 | H4: =IF(H3="","",CHOOSE(WEEKDAY(H3),"CN","T2","T3","T4","T5","T6","T7")) -> T3 | I4: =IF(I3="","",CHOOSE(WEEKDAY(I3),"CN","T2","T3","T4","T5","T6","T7")) -> T4 | J4: =IF(J3="","",CHOOSE(WEEKDAY(J3),"CN","T2","T3","T4","T5","T6","T7")) -> T5 | K4: =IF(K3="","",CHOOSE(WEEKDAY(K3),"CN","T2","T3","T4","T5","T6","T7")) -> T6 | L4: =IF(L3="","",CHOOSE(WEEKDAY(L3),"CN","T2","T3","T4","T5","T6","T7")) -> T7 | ... AI4: =IF(AI3="","",CHOOSE(WEEKDAY(AI3),"CN","T2","T3","T4","T5","T6","T7")) -> T2
A5: STT | B5: Mã NV | C5: Họ và tên | D5: Pháp nhân | E5: 1 | F5: 2 | G5: 3 | H5: 4 | I5: 5 | J5: 6 | K5: 7 | L5: 8 | M5: 9 | N5: 10 | O5: 11 | P5: 12 | Q5: 13 | R5: 14 | S5: 15 | T5: 16 | U5: 17 | V5: 18 | W5: 19 | X5: 20 | Y5: 21 | Z5: 22 | AA5: 23 | AB5: 24 | AC5: 25 | AD5: 26 | AE5: 27 | AF5: 28 | AG5: 29 | AH5: 30 | AI5: 31 | AJ5: Giờ tính lương | AK5: Công | AL5: Phép (ngày) | AM5: Nghỉ lễ (ngày) | AN5: Giờ làm ngày lễ | AO5: Chế độ cty (ngày) | AP5: CT Lào (ngày) | AQ5: Người chấm | AR5: Người duyệt | AS5: Ghi chú
A6: 1 | B6: 046180000983 | C6: =IF(B6="","",IFERROR(INDEX(NV_TEN,MATCH(B6,NV_MA,0)),"MÃ KHÔNG CÓ")) -> Hồ Thị Ngọc Á | D6: =IF(B6="","",IFERROR(INDEX(NV_PN,MATCH(B6,NV_MA,0)),"")) -> APQT | E6: 8 | F6: 8 | G6: 8 | H6: 8 | J6: 8 | K6: 8 | L6: 8 | M6: 8 | N6: 8 | O6: 8 | Q6: 8 | R6: 8 | S6: 8 | T6: 8 | U6: 8 | V6: 8 | X6: 8 | Y6: 8 | Z6: 8 | AA6: 8 | AB6: 8 | AC6: 8 | AE6: 8 | AF6: 8 | AG6: 8 | AH6: 8 | AI6: 8 | AJ6: =IF(B6="","",SUM(E6:AI6)+SUMPRODUCT(COUNTIF(E6:AI6,KH_MA),KH_LUONG)) -> 216 | AK6: =IF(B6="","",AJ6/GIO_CONG) -> 27 | AL6: =IF(B6="","",SUMPRODUCT(COUNTIF(E6:AI6,KH_MA),KH_PHEP)/GIO_CONG) -> 0 | AM6: =IF(B6="","",SUMPRODUCT(COUNTIF(E6:AI6,KH_MA),KH_LE)/GIO_CONG) -> 0 | AN6: =IF(B6="","",SUMPRODUCT(COUNTIF(E6:AI6,KH_MA),KH_LEDL)) -> 0 | AO6: =IF(B6="","",SUMPRODUCT(COUNTIF(E6:AI6,KH_MA),KH_CD)/GIO_CONG) -> 0 | AP6: =IF(B6="","",SUMPRODUCT(COUNTIF(E6:AI6,KH_MA),KH_CTL)/GIO_CONG) -> 0
A7: 2 | B7: 045086000771 | C7: =IF(B7="","",IFERROR(INDEX(NV_TEN,MATCH(B7,NV_MA,0)),"MÃ KHÔNG CÓ")) -> Nguyễn Nhật Tân | D7: =IF(B7="","",IFERROR(INDEX(NV_PN,MATCH(B7,NV_MA,0)),"")) -> APQT | E7: 8 | F7: 8 | G7: 8 | H7: 8 | I7: 8 | J7: 8 | K7: 8 | L7: 8 | M7: 8 | N7: 8 | O7: 8 | P7: 8 | Q7: 8 | R7: 8 | S7: 8 | T7: 8 | U7: 8 | V7: 8 | W7: 8 | X7: 8 | Y7: 8 | Z7: 8 | AA7: 8 | AB7: 8 | AC7: 8 | AD7: 8 | AE7: 8 | AF7: 8 | AG7: 8 | AH7: 8 | AI7: 8 | AJ7: =IF(B7="","",SUM(E7:AI7)+SUMPRODUCT(COUNTIF(E7:AI7,KH_MA),KH_LUONG)) -> 248 | AK7: =IF(B7="","",AJ7/GIO_CONG) -> 31 | AL7: =IF(B7="","",SUMPRODUCT(COUNTIF(E7:AI7,KH_MA),KH_PHEP)/GIO_CONG) -> 0 | AM7: =IF(B7="","",SUMPRODUCT(COUNTIF(E7:AI7,KH_MA),KH_LE)/GIO_CONG) -> 0 | AN7: =IF(B7="","",SUMPRODUCT(COUNTIF(E7:AI7,KH_MA),KH_LEDL)) -> 0 | AO7: =IF(B7="","",SUMPRODUCT(COUNTIF(E7:AI7,KH_MA),KH_CD)/GIO_CONG) -> 0 | AP7: =IF(B7="","",SUMPRODUCT(COUNTIF(E7:AI7,KH_MA),KH_CTL)/GIO_CONG) -> 0
A8: 3 | B8: 046077009424 | C8: =IF(B8="","",IFERROR(INDEX(NV_TEN,MATCH(B8,NV_MA,0)),"MÃ KHÔNG CÓ")) -> Đặng Quang Chung | D8: =IF(B8="","",IFERROR(INDEX(NV_PN,MATCH(B8,NV_MA,0)),"")) -> APQT | E8: 8 | G8: 8 | H8: 8 | I8: 8 | J8: 8 | K8: 8 | L8: 8 | M8: 8 | N8: 8 | O8: 8 | P8: 16 | Q8: 8 | R8: 8 | S8: 8 | U8: 8 | V8: 8 | W8: 8 | X8: 8 | Y8: 16 | Z8: P | AA8: 8 | AB8: 10 | AC8: 8 | AD8: 8 | AE8: 8 | AF8: 8 | AG8: 8 | AH8: 14 | AI8: 8 | AJ8: =IF(B8="","",SUM(E8:AI8)+SUMPRODUCT(COUNTIF(E8:AI8,KH_MA),KH_LUONG)) -> 248 | AK8: =IF(B8="","",AJ8/GIO_CONG) -> 31 | AL8: =IF(B8="","",SUMPRODUCT(COUNTIF(E8:AI8,KH_MA),KH_PHEP)/GIO_CONG) -> 1 | AM8: =IF(B8="","",SUMPRODUCT(COUNTIF(E8:AI8,KH_MA),KH_LE)/GIO_CONG) -> 0 | AN8: =IF(B8="","",SUMPRODUCT(COUNTIF(E8:AI8,KH_MA),KH_LEDL)) -> 0 | AO8: =IF(B8="","",SUMPRODUCT(COUNTIF(E8:AI8,KH_MA),KH_CD)/GIO_CONG) -> 0 | AP8: =IF(B8="","",SUMPRODUCT(COUNTIF(E8:AI8,KH_MA),KH_CTL)/GIO_CONG) -> 0
A9: 4 | B9: 046086012110 | C9: =IF(B9="","",IFERROR(INDEX(NV_TEN,MATCH(B9,NV_MA,0)),"MÃ KHÔNG CÓ")) -> Nguyễn Hào | D9: =IF(B9="","",IFERROR(INDEX(NV_PN,MATCH(B9,NV_MA,0)),"")) -> APQT | E9: 8 | F9: 8 | G9: 8 | H9: 8 | I9: 8 | J9: 8 | K9: 8 | M9: 8 | N9: 8 | O9: 8 | P9: 8 | Q9: 8 | R9: 8 | S9: 8 | T9: 16 | V9: 8 | W9: 8 | X9: 8 | Y9: 8 | Z9: 8 | AA9: 8 | AB9: 8 | AC9: 8 | AD9: 8 | AE9: 8 | AF9: 8 | AG9: 8 | AH9: 8 | AJ9: =IF(B9="","",SUM(E9:AI9)+SUMPRODUCT(COUNTIF(E9:AI9,KH_MA),KH_LUONG)) -> 232 | AK9: =IF(B9="","",AJ9/GIO_CONG) -> 29 | AL9: =IF(B9="","",SUMPRODUCT(COUNTIF(E9:AI9,KH_MA),KH_PHEP)/GIO_CONG) -> 0 | AM9: =IF(B9="","",SUMPRODUCT(COUNTIF(E9:AI9,KH_MA),KH_LE)/GIO_CONG) -> 0 | AN9: =IF(B9="","",SUMPRODUCT(COUNTIF(E9:AI9,KH_MA),KH_LEDL)) -> 0 | AO9: =IF(B9="","",SUMPRODUCT(COUNTIF(E9:AI9,KH_MA),KH_CD)/GIO_CONG) -> 0 | AP9: =IF(B9="","",SUMPRODUCT(COUNTIF(E9:AI9,KH_MA),KH_CTL)/GIO_CONG) -> 0
A10: 5 | B10: 046485004744 | C10: =IF(B10="","",IFERROR(INDEX(NV_TEN,MATCH(B10,NV_MA,0)),"MÃ KHÔNG CÓ")) -> Nguyễn Mạnh Thắng | D10: =IF(B10="","",IFERROR(INDEX(NV_PN,MATCH(B10,NV_MA,0)),"")) -> APQT | E10: 8 | G10: 8 | H10: 8 | I10: 8 | J10: 8 | K10: 8 | M10: 8 | N10: 8 | O10: 8 | P10: 8 | Q10: 8 | R10: 8 | S10: 8 | T10: 16 | V10: 8 | W10: 8 | X10: 8 | Y10: 8 | Z10: 8 | AA10: 8 | AB10: 12 | AC10: 8 | AD10: 8 | AF10: 8 | AJ10: =IF(B10="","",SUM(E10:AI10)+SUMPRODUCT(COUNTIF(E10:AI10,KH_MA),KH_LUONG)) -> 204 | AK10: =IF(B10="","",AJ10/GIO_CONG) -> 25.5 | AL10: =IF(B10="","",SUMPRODUCT(COUNTIF(E10:AI10,KH_MA),KH_PHEP)/GIO_CONG) -> 0 | AM10: =IF(B10="","",SUMPRODUCT(COUNTIF(E10:AI10,KH_MA),KH_LE)/GIO_CONG) -> 0 | AN10: =IF(B10="","",SUMPRODUCT(COUNTIF(E10:AI10,KH_MA),KH_LEDL)) -> 0 | AO10: =IF(B10="","",SUMPRODUCT(COUNTIF(E10:AI10,KH_MA),KH_CD)/GIO_CONG) -> 0 | AP10: =IF(B10="","",SUMPRODUCT(COUNTIF(E10:AI10,KH_MA),KH_CTL)/GIO_CONG) -> 0
A11: 6 | B11: 046092012558 | C11: =IF(B11="","",IFERROR(INDEX(NV_TEN,MATCH(B11,NV_MA,0)),"MÃ KHÔNG CÓ")) -> Nguyễn Quang Quốc | D11: =IF(B11="","",IFERROR(INDEX(NV_PN,MATCH(B11,NV_MA,0)),"")) -> APQT | E11: 12 | G11: 12 | H11: 12 | I11: 12 | K11: 8 | L11: 8 | N11: 8 | O11: 8 | P11: 12 | Q11: 12 | R11: 12 | S11: 12 | T11: 8 | U11: 8 | V11: 8 | W11: 8 | X11: P | Y11: 16 | Z11: 12 | AA11: 8 | AB11: 12 | AC11: 12 | AD11: 12 | AE11: 16 | AF11: 8 | AG11: 8 | AH11: 16 | AI11: 8 | AJ11: =IF(B11="","",SUM(E11:AI11)+SUMPRODUCT(COUNTIF(E11:AI11,KH_MA),KH_LUONG)) -> 288 | AK11: =IF(B11="","",AJ11/GIO_CONG) -> 36 | AL11: =IF(B11="","",SUMPRODUCT(COUNTIF(E11:AI11,KH_MA),KH_PHEP)/GIO_CONG) -> 1 | AM11: =IF(B11="","",SUMPRODUCT(COUNTIF(E11:AI11,KH_MA),KH_LE)/GIO_CONG) -> 0 | AN11: =IF(B11="","",SUMPRODUCT(COUNTIF(E11:AI11,KH_MA),KH_LEDL)) -> 0 | AO11: =IF(B11="","",SUMPRODUCT(COUNTIF(E11:AI11,KH_MA),KH_CD)/GIO_CONG) -> 0 | AP11: =IF(B11="","",SUMPRODUCT(COUNTIF(E11:AI11,KH_MA),KH_CTL)/GIO_CONG) -> 0
A12: 7 | B12: 046066004079 | C12: =IF(B12="","",IFERROR(INDEX(NV_TEN,MATCH(B12,NV_MA,0)),"MÃ KHÔNG CÓ")) -> Trần Đình Chiến | D12: =IF(B12="","",IFERROR(INDEX(NV_PN,MATCH(B12,NV_MA,0)),"")) -> APQT | E12: 8 | G12: 8 | H12: 8 | I12: 8 | J12: 8 | K12: P | L12: P | N12: 8 | O12: 8 | P12: 8 | Q12: 8 | R12: 8 | S12: 8 | T12: 8 | V12: 8 | W12: 8 | X12: 8 | Y12: 8 | Z12: 8 | AB12: 8 | AC12: 8 | AD12: 8 | AE12: 8 | AF12: 8 | AG12: 8 | AH12: 8 | AI12: 8 | AJ12: =IF(B12="","",SUM(E12:AI12)+SUMPRODUCT(COUNTIF(E12:AI12,KH_MA),KH_LUONG)) -> 200 | AK12: =IF(B12="","",AJ12/GIO_CONG) -> 25 | AL12: =IF(B12="","",SUMPRODUCT(COUNTIF(E12:AI12,KH_MA),KH_PHEP)/GIO_CONG) -> 2 | AM12: =IF(B12="","",SUMPRODUCT(COUNTIF(E12:AI12,KH_MA),KH_LE)/GIO_CONG) -> 0 | AN12: =IF(B12="","",SUMPRODUCT(COUNTIF(E12:AI12,KH_MA),KH_LEDL)) -> 0 | AO12: =IF(B12="","",SUMPRODUCT(COUNTIF(E12:AI12,KH_MA),KH_CD)/GIO_CONG) -> 0 | AP12: =IF(B12="","",SUMPRODUCT(COUNTIF(E12:AI12,KH_MA),KH_CTL)/GIO_CONG) -> 0
A13: 8 | B13: 046078005974 | C13: =IF(B13="","",IFERROR(INDEX(NV_TEN,MATCH(B13,NV_MA,0)),"MÃ KHÔNG CÓ")) -> Phạm Bá Vinh | D13: =IF(B13="","",IFERROR(INDEX(NV_PN,MATCH(B13,NV_MA,0)),"")) -> APQT | E13: 12 | G13: 12 | H13: 12 | I13: 12 | K13: 8 | L13: 8 | N13: 8 | O13: 8 | Q13: 12 | R13: 12 | S13: 12 | T13: 12 | U13: 8 | V13: 8 | W13: 8 | X13: 8 | Y13: 16 | Z13: 12 | AA13: 8 | AB13: 12 | AC13: 12 | AD13: 12 | AE13: 16 | AF13: 12 | AG13: 8 | AI13: 8 | AJ13: =IF(B13="","",SUM(E13:AI13)+SUMPRODUCT(COUNTIF(E13:AI13,KH_MA),KH_LUONG)) -> 276 | AK13: =IF(B13="","",AJ13/GIO_CONG) -> 34.5 | AL13: =IF(B13="","",SUMPRODUCT(COUNTIF(E13:AI13,KH_MA),KH_PHEP)/GIO_CONG) -> 0 | AM13: =IF(B13="","",SUMPRODUCT(COUNTIF(E13:AI13,KH_MA),KH_LE)/GIO_CONG) -> 0 | AN13: =IF(B13="","",SUMPRODUCT(COUNTIF(E13:AI13,KH_MA),KH_LEDL)) -> 0 | AO13: =IF(B13="","",SUMPRODUCT(COUNTIF(E13:AI13,KH_MA),KH_CD)/GIO_CONG) -> 0 | AP13: =IF(B13="","",SUMPRODUCT(COUNTIF(E13:AI13,KH_MA),KH_CTL)/GIO_CONG) -> 0
A14: 9 | B14: 046080010214 | C14: =IF(B14="","",IFERROR(INDEX(NV_TEN,MATCH(B14,NV_MA,0)),"MÃ KHÔNG CÓ")) -> Nguyễn Văn Cường | D14: =IF(B14="","",IFERROR(INDEX(NV_PN,MATCH(B14,NV_MA,0)),"")) -> APQT | E14: P | F14: 12 | G14: 12 | H14: 12 | I14: 12 | J14: 12 | K14: 8 | L14: 8 | M14: 8 | N14: P | O14: 16 | P14: 12 | Q14: 12 | R14: 12 | S14: P | T14: 8 | U14: 8 | V14: 8 | W14: 8 | X14: 8 | Y14: 8 | AA14: 16 | AB14: 12 | AC14: 12 | AD14: 12 | AE14: P | AF14: 8 | AG14: 16 | AH14: 8 | AI14: 8 | AJ14: =IF(B14="","",SUM(E14:AI14)+SUMPRODUCT(COUNTIF(E14:AI14,KH_MA),KH_LUONG)) -> 276 | AK14: =IF(B14="","",AJ14/GIO_CONG) -> 34.5 | AL14: =IF(B14="","",SUMPRODUCT(COUNTIF(E14:AI14,KH_MA),KH_PHEP)/GIO_CONG) -> 4 | AM14: =IF(B14="","",SUMPRODUCT(COUNTIF(E14:AI14,KH_MA),KH_LE)/GIO_CONG) -> 0 | AN14: =IF(B14="","",SUMPRODUCT(COUNTIF(E14:AI14,KH_MA),KH_LEDL)) -> 0 | AO14: =IF(B14="","",SUMPRODUCT(COUNTIF(E14:AI14,KH_MA),KH_CD)/GIO_CONG) -> 0 | AP14: =IF(B14="","",SUMPRODUCT(COUNTIF(E14:AI14,KH_MA),KH_CTL)/GIO_CONG) -> 0
A15: 10 | B15: 046097006456 | C15: =IF(B15="","",IFERROR(INDEX(NV_TEN,MATCH(B15,NV_MA,0)),"MÃ KHÔNG CÓ")) -> Mai Bá Trung | D15: =IF(B15="","",IFERROR(INDEX(NV_PN,MATCH(B15,NV_MA,0)),"")) -> APQT | E15: P | F15: 12 | G15: 12 | H15: 12 | I15: 12 | J15: 12 | K15: 8 | L15: 8 | M15: P | N15: 8 | O15: 16 | P15: 12 | Q15: 12 | R15: 12 | S15: P | T15: 8 | U15: 8 | V15: 8 | W15: 8 | X15: 8 | Y15: 8 | Z15: 12 | AA15: 16 | AB15: 12 | AC15: 12 | AD15: 12 | AF15: 8 | AG15: 8 | AH15: 8 | AI15: 8 | AJ15: =IF(B15="","",SUM(E15:AI15)+SUMPRODUCT(COUNTIF(E15:AI15,KH_MA),KH_LUONG)) -> 280 | AK15: =IF(B15="","",AJ15/GIO_CONG) -> 35 | AL15: =IF(B15="","",SUMPRODUCT(COUNTIF(E15:AI15,KH_MA),KH_PHEP)/GIO_CONG) -> 3 | AM15: =IF(B15="","",SUMPRODUCT(COUNTIF(E15:AI15,KH_MA),KH_LE)/GIO_CONG) -> 0 | AN15: =IF(B15="","",SUMPRODUCT(COUNTIF(E15:AI15,KH_MA),KH_LEDL)) -> 0 | AO15: =IF(B15="","",SUMPRODUCT(COUNTIF(E15:AI15,KH_MA),KH_CD)/GIO_CONG) -> 0 | AP15: =IF(B15="","",SUMPRODUCT(COUNTIF(E15:AI15,KH_MA),KH_CTL)/GIO_CONG) -> 0
A16: 11 | B16: 046078006770 | C16: =IF(B16="","",IFERROR(INDEX(NV_TEN,MATCH(B16,NV_MA,0)),"MÃ KHÔNG CÓ")) -> Cao Phước Tiến | D16: =IF(B16="","",IFERROR(INDEX(NV_PN,MATCH(B16,NV_MA,0)),"")) -> APQT | E16: 8 | G16: 8 | H16: 12 | I16: 12 | J16: 8 | K16: 8 | L16: 8 | N16: 8 | O16: 8 | P16: 8 | Q16: 8 | R16: 8 | S16: 8 | T16: 8 | U16: 14 | V16: 8 | W16: 8 | X16: 8 | Y16: 14 | Z16: 4 | AB16: 8 | AC16: 8 | AD16: 8 | AE16: 8 | AF16: 8 | AG16: 8 | AJ16: =IF(B16="","",SUM(E16:AI16)+SUMPRODUCT(COUNTIF(E16:AI16,KH_MA),KH_LUONG)) -> 224 | AK16: =IF(B16="","",AJ16/GIO_CONG) -> 28 | AL16: =IF(B16="","",SUMPRODUCT(COUNTIF(E16:AI16,KH_MA),KH_PHEP)/GIO_CONG) -> 0 | AM16: =IF(B16="","",SUMPRODUCT(COUNTIF(E16:AI16,KH_MA),KH_LE)/GIO_CONG) -> 0 | AN16: =IF(B16="","",SUMPRODUCT(COUNTIF(E16:AI16,KH_MA),KH_LEDL)) -> 0 | AO16: =IF(B16="","",SUMPRODUCT(COUNTIF(E16:AI16,KH_MA),KH_CD)/GIO_CONG) -> 0 | AP16: =IF(B16="","",SUMPRODUCT(COUNTIF(E16:AI16,KH_MA),KH_CTL)/GIO_CONG) -> 0
A17: 12 | B17: 046090009551 | C17: =IF(B17="","",IFERROR(INDEX(NV_TEN,MATCH(B17,NV_MA,0)),"MÃ KHÔNG CÓ")) -> Nguyễn Ngọc Thanh | D17: =IF(B17="","",IFERROR(INDEX(NV_PN,MATCH(B17,NV_MA,0)),"")) -> APQT | E17: 8 | F17: 8 | G17: 8 | H17: 8 | I17: 8 | J17: 8 | K17: 8 | L17: 8 | N17: 8 | O17: 8 | P17: 8 | Q17: 8 | R17: 8 | S17: 8 | U17: 8 | V17: 8 | W17: 8 | X17: 8 | Y17: 8 | Z17: 8 | AB17: 8 | AC17: 8 | AD17: 8 | AE17: 8 | AF17: 8 | AG17: 8 | AI17: 8 | AJ17: =IF(B17="","",SUM(E17:AI17)+SUMPRODUCT(COUNTIF(E17:AI17,KH_MA),KH_LUONG)) -> 216 | AK17: =IF(B17="","",AJ17/GIO_CONG) -> 27 | AL17: =IF(B17="","",SUMPRODUCT(COUNTIF(E17:AI17,KH_MA),KH_PHEP)/GIO_CONG) -> 0 | AM17: =IF(B17="","",SUMPRODUCT(COUNTIF(E17:AI17,KH_MA),KH_LE)/GIO_CONG) -> 0 | AN17: =IF(B17="","",SUMPRODUCT(COUNTIF(E17:AI17,KH_MA),KH_LEDL)) -> 0 | AO17: =IF(B17="","",SUMPRODUCT(COUNTIF(E17:AI17,KH_MA),KH_CD)/GIO_CONG) -> 0 | AP17: =IF(B17="","",SUMPRODUCT(COUNTIF(E17:AI17,KH_MA),KH_CTL)/GIO_CONG) -> 0
A18: 13 | B18: 046208001119 | C18: =IF(B18="","",IFERROR(INDEX(NV_TEN,MATCH(B18,NV_MA,0)),"MÃ KHÔNG CÓ")) -> Dương Vinh Quang | D18: =IF(B18="","",IFERROR(INDEX(NV_PN,MATCH(B18,NV_MA,0)),"")) -> APQT | E18: 12 | G18: 8 | H18: 8 | I18: 8 | J18: 8 | K18: 8 | L18: 8 | N18: 8 | O18: 8 | P18: 8 | Q18: 8 | R18: 8 | S18: 12 | U18: 8 | V18: 8 | W18: 8 | X18: 8 | Y18: 8 | Z18: 8 | AB18: 8 | AC18: 8 | AD18: 8 | AE18: 8 | AF18: 8 | AG18: 8 | AI18: 8 | AJ18: =IF(B18="","",SUM(E18:AI18)+SUMPRODUCT(COUNTIF(E18:AI18,KH_MA),KH_LUONG)) -> 216 | AK18: =IF(B18="","",AJ18/GIO_CONG) -> 27 | AL18: =IF(B18="","",SUMPRODUCT(COUNTIF(E18:AI18,KH_MA),KH_PHEP)/GIO_CONG) -> 0 | AM18: =IF(B18="","",SUMPRODUCT(COUNTIF(E18:AI18,KH_MA),KH_LE)/GIO_CONG) -> 0 | AN18: =IF(B18="","",SUMPRODUCT(COUNTIF(E18:AI18,KH_MA),KH_LEDL)) -> 0 | AO18: =IF(B18="","",SUMPRODUCT(COUNTIF(E18:AI18,KH_MA),KH_CD)/GIO_CONG) -> 0 | AP18: =IF(B18="","",SUMPRODUCT(COUNTIF(E18:AI18,KH_MA),KH_CTL)/GIO_CONG) -> 0
A19: 14 | B19: 045086003213 | C19: =IF(B19="","",IFERROR(INDEX(NV_TEN,MATCH(B19,NV_MA,0)),"MÃ KHÔNG CÓ")) -> Hoàng Xuân Quang | D19: =IF(B19="","",IFERROR(INDEX(NV_PN,MATCH(B19,NV_MA,0)),"")) -> HAQT | E19: 8 | F19: 8 | G19: 12 | H19: 12 | I19: 8 | J19: 8 | K19: 8 | L19: 8 | M19: 12 | N19: 8 | O19: 8 | P19: 8 | Q19: 16 | R19: 8 | S19: 12 | T19: 12 | U19: 8 | V19: 8 | X19: 10 | Y19: 8 | Z19: 8 | AA19: 8 | AB19: 8 | AC19: 10 | AD19: 10 | AE19: 10 | AF19: 8 | AG19: 8 | AH19: 12 | AI19: 8 | AJ19: =IF(B19="","",SUM(E19:AI19)+SUMPRODUCT(COUNTIF(E19:AI19,KH_MA),KH_LUONG)) -> 280 | AK19: =IF(B19="","",AJ19/GIO_CONG) -> 35 | AL19: =IF(B19="","",SUMPRODUCT(COUNTIF(E19:AI19,KH_MA),KH_PHEP)/GIO_CONG) -> 0 | AM19: =IF(B19="","",SUMPRODUCT(COUNTIF(E19:AI19,KH_MA),KH_LE)/GIO_CONG) -> 0 | AN19: =IF(B19="","",SUMPRODUCT(COUNTIF(E19:AI19,KH_MA),KH_LEDL)) -> 0 | AO19: =IF(B19="","",SUMPRODUCT(COUNTIF(E19:AI19,KH_MA),KH_CD)/GIO_CONG) -> 0 | AP19: =IF(B19="","",SUMPRODUCT(COUNTIF(E19:AI19,KH_MA),KH_CTL)/GIO_CONG) -> 0
A20: 15 | B20: 044058002123 | C20: =IF(B20="","",IFERROR(INDEX(NV_TEN,MATCH(B20,NV_MA,0)),"MÃ KHÔNG CÓ")) -> Trần Văn Khai | D20: =IF(B20="","",IFERROR(INDEX(NV_PN,MATCH(B20,NV_MA,0)),"")) -> HAQT | E20: 8 | F20: 8 | G20: 8 | H20: 8 | I20: 8 | J20: 8 | K20: 8 | L20: 8 | M20: 8 | N20: 8 | O20: 8 | P20: 8 | Q20: 8 | R20: 8 | S20: 8 | T20: 8 | U20: 8 | V20: 8 | W20: 8 | X20: 8 | Y20: 8 | Z20: 8 | AA20: 8 | AB20: 8 | AC20: 8 | AD20: 8 | AE20: 8 | AF20: 8 | AG20: 8 | AH20: 8 | AI20: 8 | AJ20: =IF(B20="","",SUM(E20:AI20)+SUMPRODUCT(COUNTIF(E20:AI20,KH_MA),KH_LUONG)) -> 248 | AK20: =IF(B20="","",AJ20/GIO_CONG) -> 31 | AL20: =IF(B20="","",SUMPRODUCT(COUNTIF(E20:AI20,KH_MA),KH_PHEP)/GIO_CONG) -> 0 | AM20: =IF(B20="","",SUMPRODUCT(COUNTIF(E20:AI20,KH_MA),KH_LE)/GIO_CONG) -> 0 | AN20: =IF(B20="","",SUMPRODUCT(COUNTIF(E20:AI20,KH_MA),KH_LEDL)) -> 0 | AO20: =IF(B20="","",SUMPRODUCT(COUNTIF(E20:AI20,KH_MA),KH_CD)/GIO_CONG) -> 0 | AP20: =IF(B20="","",SUMPRODUCT(COUNTIF(E20:AI20,KH_MA),KH_CTL)/GIO_CONG) -> 0
A21: 16 | B21: 045089005452 | C21: =IF(B21="","",IFERROR(INDEX(NV_TEN,MATCH(B21,NV_MA,0)),"MÃ KHÔNG CÓ")) -> Lê Văn Dũng | D21: =IF(B21="","",IFERROR(INDEX(NV_PN,MATCH(B21,NV_MA,0)),"")) -> HAQT | E21: 8 | F21: 8 | G21: 8 | H21: 8 | I21: 8 | J21: 8 | K21: 8 | L21: 8 | M21: 8 | N21: 8 | O21: 8 | P21: 8 | Q21: 8 | R21: 8 | S21: 8 | T21: 8 | U21: 8 | V21: 8 | W21: 8 | X21: 8 | Y21: 8 | Z21: 8 | AA21: 8 | AB21: 8 | AC21: 8 | AD21: 8 | AE21: 8 | AF21: 8 | AG21: 8 | AH21: 8 | AI21: 8 | AJ21: =IF(B21="","",SUM(E21:AI21)+SUMPRODUCT(COUNTIF(E21:AI21,KH_MA),KH_LUONG)) -> 248 | AK21: =IF(B21="","",AJ21/GIO_CONG) -> 31 | AL21: =IF(B21="","",SUMPRODUCT(COUNTIF(E21:AI21,KH_MA),KH_PHEP)/GIO_CONG) -> 0 | AM21: =IF(B21="","",SUMPRODUCT(COUNTIF(E21:AI21,KH_MA),KH_LE)/GIO_CONG) -> 0 | AN21: =IF(B21="","",SUMPRODUCT(COUNTIF(E21:AI21,KH_MA),KH_LEDL)) -> 0 | AO21: =IF(B21="","",SUMPRODUCT(COUNTIF(E21:AI21,KH_MA),KH_CD)/GIO_CONG) -> 0 | AP21: =IF(B21="","",SUMPRODUCT(COUNTIF(E21:AI21,KH_MA),KH_CTL)/GIO_CONG) -> 0
B22: TV_MAU_01 | C22: =IF(B22="","",IFERROR(INDEX(NV_TEN,MATCH(B22,NV_MA,0)),"MÃ KHÔNG CÓ")) -> (Ví dụ) Nguyễn Văn B | D22: =IF(B22="","",IFERROR(INDEX(NV_PN,MATCH(B22,NV_MA,0)),"")) -> HAPD | E22: 8 | F22: P | G22: 8 | H22: 8 | I22: 8 | L22: 8 | N22: 8 | O22: 8 | P22: 8 | R22: L4 | S22: 8 | U22: 8 | V22: 8 | W22: 8 | Y22: H/2 | Z22: 8 | AB22: 8 | AC22: 8 | AD22: 8 | AG22: 8 | AI22: 8 | AJ22: =IF(B22="","",SUM(E22:AI22)+SUMPRODUCT(COUNTIF(E22:AI22,KH_MA),KH_LUONG)) -> 148 | AK22: =IF(B22="","",AJ22/GIO_CONG) -> 18.5 | AL22: =IF(B22="","",SUMPRODUCT(COUNTIF(E22:AI22,KH_MA),KH_PHEP)/GIO_CONG) -> 1 | AM22: =IF(B22="","",SUMPRODUCT(COUNTIF(E22:AI22,KH_MA),KH_LE)/GIO_CONG) -> 1 | AN22: =IF(B22="","",SUMPRODUCT(COUNTIF(E22:AI22,KH_MA),KH_LEDL)) -> 4 | AO22: =IF(B22="","",SUMPRODUCT(COUNTIF(E22:AI22,KH_MA),KH_CD)/GIO_CONG) -> 0.5 | AP22: =IF(B22="","",SUMPRODUCT(COUNTIF(E22:AI22,KH_MA),KH_CTL)/GIO_CONG) -> 0 | AS22: Dòng ví dụ: có P, L4, H/2 để xem cách tính
A23: =IF(B23="","",ROW()-5) | C23: =IF(B23="","",IFERROR(INDEX(NV_TEN,MATCH(B23,NV_MA,0)),"MÃ KHÔNG CÓ")) | D23: =IF(B23="","",IFERROR(INDEX(NV_PN,MATCH(B23,NV_MA,0)),"")) | AJ23: =IF(B23="","",SUM(E23:AI23)+SUMPRODUCT(COUNTIF(E23:AI23,KH_MA),KH_LUONG)) | AK23: =IF(B23="","",AJ23/GIO_CONG) | AL23: =IF(B23="","",SUMPRODUCT(COUNTIF(E23:AI23,KH_MA),KH_PHEP)/GIO_CONG) | AM23: =IF(B23="","",SUMPRODUCT(COUNTIF(E23:AI23,KH_MA),KH_LE)/GIO_CONG) | AN23: =IF(B23="","",SUMPRODUCT(COUNTIF(E23:AI23,KH_MA),KH_LEDL)) | AO23: =IF(B23="","",SUMPRODUCT(COUNTIF(E23:AI23,KH_MA),KH_CD)/GIO_CONG) | AP23: =IF(B23="","",SUMPRODUCT(COUNTIF(E23:AI23,KH_MA),KH_CTL)/GIO_CONG)
A24: =IF(B24="","",ROW()-5) | C24: =IF(B24="","",IFERROR(INDEX(NV_TEN,MATCH(B24,NV_MA,0)),"MÃ KHÔNG CÓ")) | D24: =IF(B24="","",IFERROR(INDEX(NV_PN,MATCH(B24,NV_MA,0)),"")) | AJ24: =IF(B24="","",SUM(E24:AI24)+SUMPRODUCT(COUNTIF(E24:AI24,KH_MA),KH_LUONG)) | AK24: =IF(B24="","",AJ24/GIO_CONG) | AL24: =IF(B24="","",SUMPRODUCT(COUNTIF(E24:AI24,KH_MA),KH_PHEP)/GIO_CONG) | AM24: =IF(B24="","",SUMPRODUCT(COUNTIF(E24:AI24,KH_MA),KH_LE)/GIO_CONG) | AN24: =IF(B24="","",SUMPRODUCT(COUNTIF(E24:AI24,KH_MA),KH_LEDL)) | AO24: =IF(B24="","",SUMPRODUCT(COUNTIF(E24:AI24,KH_MA),KH_CD)/GIO_CONG) | AP24: =IF(B24="","",SUMPRODUCT(COUNTIF(E24:AI24,KH_MA),KH_CTL)/GIO_CONG)
A25: =IF(B25="","",ROW()-5) | C25: =IF(B25="","",IFERROR(INDEX(NV_TEN,MATCH(B25,NV_MA,0)),"MÃ KHÔNG CÓ")) | D25: =IF(B25="","",IFERROR(INDEX(NV_PN,MATCH(B25,NV_MA,0)),"")) | AJ25: =IF(B25="","",SUM(E25:AI25)+SUMPRODUCT(COUNTIF(E25:AI25,KH_MA),KH_LUONG)) | AK25: =IF(B25="","",AJ25/GIO_CONG) | AL25: =IF(B25="","",SUMPRODUCT(COUNTIF(E25:AI25,KH_MA),KH_PHEP)/GIO_CONG) | AM25: =IF(B25="","",SUMPRODUCT(COUNTIF(E25:AI25,KH_MA),KH_LE)/GIO_CONG) | AN25: =IF(B25="","",SUMPRODUCT(COUNTIF(E25:AI25,KH_MA),KH_LEDL)) | AO25: =IF(B25="","",SUMPRODUCT(COUNTIF(E25:AI25,KH_MA),KH_CD)/GIO_CONG) | AP25: =IF(B25="","",SUMPRODUCT(COUNTIF(E25:AI25,KH_MA),KH_CTL)/GIO_CONG)
A26: =IF(B26="","",ROW()-5) | C26: =IF(B26="","",IFERROR(INDEX(NV_TEN,MATCH(B26,NV_MA,0)),"MÃ KHÔNG CÓ")) | D26: =IF(B26="","",IFERROR(INDEX(NV_PN,MATCH(B26,NV_MA,0)),"")) | AJ26: =IF(B26="","",SUM(E26:AI26)+SUMPRODUCT(COUNTIF(E26:AI26,KH_MA),KH_LUONG)) | AK26: =IF(B26="","",AJ26/GIO_CONG) | AL26: =IF(B26="","",SUMPRODUCT(COUNTIF(E26:AI26,KH_MA),KH_PHEP)/GIO_CONG) | AM26: =IF(B26="","",SUMPRODUCT(COUNTIF(E26:AI26,KH_MA),KH_LE)/GIO_CONG) | AN26: =IF(B26="","",SUMPRODUCT(COUNTIF(E26:AI26,KH_MA),KH_LEDL)) | AO26: =IF(B26="","",SUMPRODUCT(COUNTIF(E26:AI26,KH_MA),KH_CD)/GIO_CONG) | AP26: =IF(B26="","",SUMPRODUCT(COUNTIF(E26:AI26,KH_MA),KH_CTL)/GIO_CONG)
A27: =IF(B27="","",ROW()-5) | C27: =IF(B27="","",IFERROR(INDEX(NV_TEN,MATCH(B27,NV_MA,0)),"MÃ KHÔNG CÓ")) | D27: =IF(B27="","",IFERROR(INDEX(NV_PN,MATCH(B27,NV_MA,0)),"")) | AJ27: =IF(B27="","",SUM(E27:AI27)+SUMPRODUCT(COUNTIF(E27:AI27,KH_MA),KH_LUONG)) | AK27: =IF(B27="","",AJ27/GIO_CONG) | AL27: =IF(B27="","",SUMPRODUCT(COUNTIF(E27:AI27,KH_MA),KH_PHEP)/GIO_CONG) | AM27: =IF(B27="","",SUMPRODUCT(COUNTIF(E27:AI27,KH_MA),KH_LE)/GIO_CONG) | AN27: =IF(B27="","",SUMPRODUCT(COUNTIF(E27:AI27,KH_MA),KH_LEDL)) | AO27: =IF(B27="","",SUMPRODUCT(COUNTIF(E27:AI27,KH_MA),KH_CD)/GIO_CONG) | AP27: =IF(B27="","",SUMPRODUCT(COUNTIF(E27:AI27,KH_MA),KH_CTL)/GIO_CONG)
A28: =IF(B28="","",ROW()-5) | C28: =IF(B28="","",IFERROR(INDEX(NV_TEN,MATCH(B28,NV_MA,0)),"MÃ KHÔNG CÓ")) | D28: =IF(B28="","",IFERROR(INDEX(NV_PN,MATCH(B28,NV_MA,0)),"")) | AJ28: =IF(B28="","",SUM(E28:AI28)+SUMPRODUCT(COUNTIF(E28:AI28,KH_MA),KH_LUONG)) | AK28: =IF(B28="","",AJ28/GIO_CONG) | AL28: =IF(B28="","",SUMPRODUCT(COUNTIF(E28:AI28,KH_MA),KH_PHEP)/GIO_CONG) | AM28: =IF(B28="","",SUMPRODUCT(COUNTIF(E28:AI28,KH_MA),KH_LE)/GIO_CONG) | AN28: =IF(B28="","",SUMPRODUCT(COUNTIF(E28:AI28,KH_MA),KH_LEDL)) | AO28: =IF(B28="","",SUMPRODUCT(COUNTIF(E28:AI28,KH_MA),KH_CD)/GIO_CONG) | AP28: =IF(B28="","",SUMPRODUCT(COUNTIF(E28:AI28,KH_MA),KH_CTL)/GIO_CONG)
A29: =IF(B29="","",ROW()-5) | C29: =IF(B29="","",IFERROR(INDEX(NV_TEN,MATCH(B29,NV_MA,0)),"MÃ KHÔNG CÓ")) | D29: =IF(B29="","",IFERROR(INDEX(NV_PN,MATCH(B29,NV_MA,0)),"")) | AJ29: =IF(B29="","",SUM(E29:AI29)+SUMPRODUCT(COUNTIF(E29:AI29,KH_MA),KH_LUONG)) | AK29: =IF(B29="","",AJ29/GIO_CONG) | AL29: =IF(B29="","",SUMPRODUCT(COUNTIF(E29:AI29,KH_MA),KH_PHEP)/GIO_CONG) | AM29: =IF(B29="","",SUMPRODUCT(COUNTIF(E29:AI29,KH_MA),KH_LE)/GIO_CONG) | AN29: =IF(B29="","",SUMPRODUCT(COUNTIF(E29:AI29,KH_MA),KH_LEDL)) | AO29: =IF(B29="","",SUMPRODUCT(COUNTIF(E29:AI29,KH_MA),KH_CD)/GIO_CONG) | AP29: =IF(B29="","",SUMPRODUCT(COUNTIF(E29:AI29,KH_MA),KH_CTL)/GIO_CONG)
A30: =IF(B30="","",ROW()-5) | C30: =IF(B30="","",IFERROR(INDEX(NV_TEN,MATCH(B30,NV_MA,0)),"MÃ KHÔNG CÓ")) | D30: =IF(B30="","",IFERROR(INDEX(NV_PN,MATCH(B30,NV_MA,0)),"")) | AJ30: =IF(B30="","",SUM(E30:AI30)+SUMPRODUCT(COUNTIF(E30:AI30,KH_MA),KH_LUONG)) | AK30: =IF(B30="","",AJ30/GIO_CONG) | AL30: =IF(B30="","",SUMPRODUCT(COUNTIF(E30:AI30,KH_MA),KH_PHEP)/GIO_CONG) | AM30: =IF(B30="","",SUMPRODUCT(COUNTIF(E30:AI30,KH_MA),KH_LE)/GIO_CONG) | AN30: =IF(B30="","",SUMPRODUCT(COUNTIF(E30:AI30,KH_MA),KH_LEDL)) | AO30: =IF(B30="","",SUMPRODUCT(COUNTIF(E30:AI30,KH_MA),KH_CD)/GIO_CONG) | AP30: =IF(B30="","",SUMPRODUCT(COUNTIF(E30:AI30,KH_MA),KH_CTL)/GIO_CONG)
A31: =IF(B31="","",ROW()-5) | C31: =IF(B31="","",IFERROR(INDEX(NV_TEN,MATCH(B31,NV_MA,0)),"MÃ KHÔNG CÓ")) | D31: =IF(B31="","",IFERROR(INDEX(NV_PN,MATCH(B31,NV_MA,0)),"")) | AJ31: =IF(B31="","",SUM(E31:AI31)+SUMPRODUCT(COUNTIF(E31:AI31,KH_MA),KH_LUONG)) | AK31: =IF(B31="","",AJ31/GIO_CONG) | AL31: =IF(B31="","",SUMPRODUCT(COUNTIF(E31:AI31,KH_MA),KH_PHEP)/GIO_CONG) | AM31: =IF(B31="","",SUMPRODUCT(COUNTIF(E31:AI31,KH_MA),KH_LE)/GIO_CONG) | AN31: =IF(B31="","",SUMPRODUCT(COUNTIF(E31:AI31,KH_MA),KH_LEDL)) | AO31: =IF(B31="","",SUMPRODUCT(COUNTIF(E31:AI31,KH_MA),KH_CD)/GIO_CONG) | AP31: =IF(B31="","",SUMPRODUCT(COUNTIF(E31:AI31,KH_MA),KH_CTL)/GIO_CONG)
A32: =IF(B32="","",ROW()-5) | C32: =IF(B32="","",IFERROR(INDEX(NV_TEN,MATCH(B32,NV_MA,0)),"MÃ KHÔNG CÓ")) | D32: =IF(B32="","",IFERROR(INDEX(NV_PN,MATCH(B32,NV_MA,0)),"")) | AJ32: =IF(B32="","",SUM(E32:AI32)+SUMPRODUCT(COUNTIF(E32:AI32,KH_MA),KH_LUONG)) | AK32: =IF(B32="","",AJ32/GIO_CONG) | AL32: =IF(B32="","",SUMPRODUCT(COUNTIF(E32:AI32,KH_MA),KH_PHEP)/GIO_CONG) | AM32: =IF(B32="","",SUMPRODUCT(COUNTIF(E32:AI32,KH_MA),KH_LE)/GIO_CONG) | AN32: =IF(B32="","",SUMPRODUCT(COUNTIF(E32:AI32,KH_MA),KH_LEDL)) | AO32: =IF(B32="","",SUMPRODUCT(COUNTIF(E32:AI32,KH_MA),KH_CD)/GIO_CONG) | AP32: =IF(B32="","",SUMPRODUCT(COUNTIF(E32:AI32,KH_MA),KH_CTL)/GIO_CONG)
A33: =IF(B33="","",ROW()-5) | C33: =IF(B33="","",IFERROR(INDEX(NV_TEN,MATCH(B33,NV_MA,0)),"MÃ KHÔNG CÓ")) | D33: =IF(B33="","",IFERROR(INDEX(NV_PN,MATCH(B33,NV_MA,0)),"")) | AJ33: =IF(B33="","",SUM(E33:AI33)+SUMPRODUCT(COUNTIF(E33:AI33,KH_MA),KH_LUONG)) | AK33: =IF(B33="","",AJ33/GIO_CONG) | AL33: =IF(B33="","",SUMPRODUCT(COUNTIF(E33:AI33,KH_MA),KH_PHEP)/GIO_CONG) | AM33: =IF(B33="","",SUMPRODUCT(COUNTIF(E33:AI33,KH_MA),KH_LE)/GIO_CONG) | AN33: =IF(B33="","",SUMPRODUCT(COUNTIF(E33:AI33,KH_MA),KH_LEDL)) | AO33: =IF(B33="","",SUMPRODUCT(COUNTIF(E33:AI33,KH_MA),KH_CD)/GIO_CONG) | AP33: =IF(B33="","",SUMPRODUCT(COUNTIF(E33:AI33,KH_MA),KH_CTL)/GIO_CONG)
A34: =IF(B34="","",ROW()-5) | C34: =IF(B34="","",IFERROR(INDEX(NV_TEN,MATCH(B34,NV_MA,0)),"MÃ KHÔNG CÓ")) | D34: =IF(B34="","",IFERROR(INDEX(NV_PN,MATCH(B34,NV_MA,0)),"")) | AJ34: =IF(B34="","",SUM(E34:AI34)+SUMPRODUCT(COUNTIF(E34:AI34,KH_MA),KH_LUONG)) | AK34: =IF(B34="","",AJ34/GIO_CONG) | AL34: =IF(B34="","",SUMPRODUCT(COUNTIF(E34:AI34,KH_MA),KH_PHEP)/GIO_CONG) | AM34: =IF(B34="","",SUMPRODUCT(COUNTIF(E34:AI34,KH_MA),KH_LE)/GIO_CONG) | AN34: =IF(B34="","",SUMPRODUCT(COUNTIF(E34:AI34,KH_MA),KH_LEDL)) | AO34: =IF(B34="","",SUMPRODUCT(COUNTIF(E34:AI34,KH_MA),KH_CD)/GIO_CONG) | AP34: =IF(B34="","",SUMPRODUCT(COUNTIF(E34:AI34,KH_MA),KH_CTL)/GIO_CONG)
... A120: =IF(B120="","",ROW()-5) | C120: =IF(B120="","",IFERROR(INDEX(NV_TEN,MATCH(B120,NV_MA,0)),"MÃ KHÔNG CÓ")) | D120: =IF(B120="","",IFERROR(INDEX(NV_PN,MATCH(B120,NV_MA,0)),"")) | AJ120: =IF(B120="","",SUM(E120:AI120)+SUMPRODUCT(COUNTIF(E120:AI120,KH_MA),KH_LUONG)) | AK120: =IF(B120="","",AJ120/GIO_CONG) | AL120: =IF(B120="","",SUMPRODUCT(COUNTIF(E120:AI120,KH_MA),KH_PHEP)/GIO_CONG) | AM120: =IF(B120="","",SUMPRODUCT(COUNTIF(E120:AI120,KH_MA),KH_LE)/GIO_CONG) | AN120: =IF(B120="","",SUMPRODUCT(COUNTIF(E120:AI120,KH_MA),KH_LEDL)) | AO120: =IF(B120="","",SUMPRODUCT(COUNTIF(E120:AI120,KH_MA),KH_CD)/GIO_CONG) | AP120: =IF(B120="","",SUMPRODUCT(COUNTIF(E120:AI120,KH_MA),KH_CTL)/GIO_CONG)
C122: TỔNG | AJ122: =SUM(AJ6:AJ120) -> 4048 | AK122: =SUM(AK6:AK120) -> 506 | AL122: =SUM(AL6:AL120) -> 12 | AM122: =SUM(AM6:AM120) -> 1 | AN122: =SUM(AN6:AN120) -> 4 | AO122: =SUM(AO6:AO120) -> 0.5 | AP122: =SUM(AP6:AP120) -> 0

Sheet DIEU_CHINH
A1: ĐIỀU CHỈNH THEO NGƯỜI – mỗi khoản một dòng, có lý do và người duyệt
A2: Thay cho ghi chú bằng chữ và các ô sửa tay trong Bảng lương cũ. Chỉ dòng có hiệu lực trùng kỳ (THAM_SO) mới được cộng vào LUONG.
A4: STT | B4: Mã NV | C4: Họ và tên | D4: Loại | E4: Số tiền (+ cộng / − trừ theo Loại) | F4: Hiệu lực từ (tháng) | G4: Hiệu lực đến (tháng) | H4: Lý do / căn cứ | I4: Người duyệt | J4: Đang áp dụng kỳ này?
A5: 1 | B5: 046090009551 | C5: =IF(B5="","",IFERROR(INDEX(NV_TEN,MATCH(B5,NV_MA,0)),"MÃ KHÔNG CÓ")) -> Nguyễn Ngọc Thanh | D5: Tạm ứng | E5: 3000000 | F5: 2026-08 | G5: 2026-08 | H5: Tạm ứng lương (Bảng lương cũ cột Y) | I5: KTT | J5: =IF(B5="","",IF(AND(F5<=TEXT(DATE(NAM,THANG,1),"yyyy-mm"),OR(G5="",G5>=TEXT(DATE(NAM,THANG,1),"yyyy-mm"))),"Có","Không")) -> Có
A6: 2 | B6: 046078006770 | C6: =IF(B6="","",IFERROR(INDEX(NV_TEN,MATCH(B6,NV_MA,0)),"MÃ KHÔNG CÓ")) -> Cao Phước Tiến | D6: Trừ khác | E6: 1500000 | F6: 2025-07 | G6: 2027-12 | H6: Thu nợ công ty theo kế hoạch trả nợ 1,5tr/tháng; riêng 12/2027 thu 900.000 (sửa dòng riêng) | I6: BGĐ | J6: =IF(B6="","",IF(AND(F6<=TEXT(DATE(NAM,THANG,1),"yyyy-mm"),OR(G6="",G6>=TEXT(DATE(NAM,THANG,1),"yyyy-mm"))),"Có","Không")) -> Có
A7: 3 | B7: 046086012110 | C7: =IF(B7="","",IFERROR(INDEX(NV_TEN,MATCH(B7,NV_MA,0)),"MÃ KHÔNG CÓ")) -> Nguyễn Hào | D7: Chuyên cần | E7: -300000 | F7: 2026-08 | G7: 2026-08 | H7: File cũ ghi tay 0 dù 29 công – HCNS CẦN XÁC NHẬN LÝ DO | I7: ? | J7: =IF(B7="","",IF(AND(F7<=TEXT(DATE(NAM,THANG,1),"yyyy-mm"),OR(G7="",G7>=TEXT(DATE(NAM,THANG,1),"yyyy-mm"))),"Có","Không")) -> Có
A8: 4 | B8: 046078005974 | C8: =IF(B8="","",IFERROR(INDEX(NV_TEN,MATCH(B8,NV_MA,0)),"MÃ KHÔNG CÓ")) -> Phạm Bá Vinh | D8: Chuyên cần | E8: -300000 | F8: 2026-08 | G8: 2026-08 | H8: File cũ ghi tay 0% dù 34,5 công – HCNS CẦN XÁC NHẬN LÝ DO | I8: ? | J8: =IF(B8="","",IF(AND(F8<=TEXT(DATE(NAM,THANG,1),"yyyy-mm"),OR(G8="",G8>=TEXT(DATE(NAM,THANG,1),"yyyy-mm"))),"Có","Không")) -> Có
A9: 5 | B9: 046208001119 | C9: =IF(B9="","",IFERROR(INDEX(NV_TEN,MATCH(B9,NV_MA,0)),"MÃ KHÔNG CÓ")) -> Dương Vinh Quang | D9: Chuyên cần | E9: 300000 | F9: 2026-08 | G9: 2026-08 | H9: File cũ ghi tay 300.000 dù chỉ 27 công – HCNS CẦN XÁC NHẬN LÝ DO | I9: ? | J9: =IF(B9="","",IF(AND(F9<=TEXT(DATE(NAM,THANG,1),"yyyy-mm"),OR(G9="",G9>=TEXT(DATE(NAM,THANG,1),"yyyy-mm"))),"Có","Không")) -> Có
C10: =IF(B10="","",IFERROR(INDEX(NV_TEN,MATCH(B10,NV_MA,0)),"MÃ KHÔNG CÓ")) | J10: =IF(B10="","",IF(AND(F10<=TEXT(DATE(NAM,THANG,1),"yyyy-mm"),OR(G10="",G10>=TEXT(DATE(NAM,THANG,1),"yyyy-mm"))),"Có","Không"))
C11: =IF(B11="","",IFERROR(INDEX(NV_TEN,MATCH(B11,NV_MA,0)),"MÃ KHÔNG CÓ")) | J11: =IF(B11="","",IF(AND(F11<=TEXT(DATE(NAM,THANG,1),"yyyy-mm"),OR(G11="",G11>=TEXT(DATE(NAM,THANG,1),"yyyy-mm"))),"Có","Không"))
C12: =IF(B12="","",IFERROR(INDEX(NV_TEN,MATCH(B12,NV_MA,0)),"MÃ KHÔNG CÓ")) | J12: =IF(B12="","",IF(AND(F12<=TEXT(DATE(NAM,THANG,1),"yyyy-mm"),OR(G12="",G12>=TEXT(DATE(NAM,THANG,1),"yyyy-mm"))),"Có","Không"))
C13: =IF(B13="","",IFERROR(INDEX(NV_TEN,MATCH(B13,NV_MA,0)),"MÃ KHÔNG CÓ")) | J13: =IF(B13="","",IF(AND(F13<=TEXT(DATE(NAM,THANG,1),"yyyy-mm"),OR(G13="",G13>=TEXT(DATE(NAM,THANG,1),"yyyy-mm"))),"Có","Không"))
C14: =IF(B14="","",IFERROR(INDEX(NV_TEN,MATCH(B14,NV_MA,0)),"MÃ KHÔNG CÓ")) | J14: =IF(B14="","",IF(AND(F14<=TEXT(DATE(NAM,THANG,1),"yyyy-mm"),OR(G14="",G14>=TEXT(DATE(NAM,THANG,1),"yyyy-mm"))),"Có","Không"))
C15: =IF(B15="","",IFERROR(INDEX(NV_TEN,MATCH(B15,NV_MA,0)),"MÃ KHÔNG CÓ")) | J15: =IF(B15="","",IF(AND(F15<=TEXT(DATE(NAM,THANG,1),"yyyy-mm"),OR(G15="",G15>=TEXT(DATE(NAM,THANG,1),"yyyy-mm"))),"Có","Không"))
C16: =IF(B16="","",IFERROR(INDEX(NV_TEN,MATCH(B16,NV_MA,0)),"MÃ KHÔNG CÓ")) | J16: =IF(B16="","",IF(AND(F16<=TEXT(DATE(NAM,THANG,1),"yyyy-mm"),OR(G16="",G16>=TEXT(DATE(NAM,THANG,1),"yyyy-mm"))),"Có","Không"))
C17: =IF(B17="","",IFERROR(INDEX(NV_TEN,MATCH(B17,NV_MA,0)),"MÃ KHÔNG CÓ")) | J17: =IF(B17="","",IF(AND(F17<=TEXT(DATE(NAM,THANG,1),"yyyy-mm"),OR(G17="",G17>=TEXT(DATE(NAM,THANG,1),"yyyy-mm"))),"Có","Không"))
C18: =IF(B18="","",IFERROR(INDEX(NV_TEN,MATCH(B18,NV_MA,0)),"MÃ KHÔNG CÓ")) | J18: =IF(B18="","",IF(AND(F18<=TEXT(DATE(NAM,THANG,1),"yyyy-mm"),OR(G18="",G18>=TEXT(DATE(NAM,THANG,1),"yyyy-mm"))),"Có","Không"))
C19: =IF(B19="","",IFERROR(INDEX(NV_TEN,MATCH(B19,NV_MA,0)),"MÃ KHÔNG CÓ")) | J19: =IF(B19="","",IF(AND(F19<=TEXT(DATE(NAM,THANG,1),"yyyy-mm"),OR(G19="",G19>=TEXT(DATE(NAM,THANG,1),"yyyy-mm"))),"Có","Không"))
C20: =IF(B20="","",IFERROR(INDEX(NV_TEN,MATCH(B20,NV_MA,0)),"MÃ KHÔNG CÓ")) | J20: =IF(B20="","",IF(AND(F20<=TEXT(DATE(NAM,THANG,1),"yyyy-mm"),OR(G20="",G20>=TEXT(DATE(NAM,THANG,1),"yyyy-mm"))),"Có","Không"))
C21: =IF(B21="","",IFERROR(INDEX(NV_TEN,MATCH(B21,NV_MA,0)),"MÃ KHÔNG CÓ")) | J21: =IF(B21="","",IF(AND(F21<=TEXT(DATE(NAM,THANG,1),"yyyy-mm"),OR(G21="",G21>=TEXT(DATE(NAM,THANG,1),"yyyy-mm"))),"Có","Không"))
... C199: =IF(B199="","",IFERROR(INDEX(NV_TEN,MATCH(B199,NV_MA,0)),"MÃ KHÔNG CÓ")) | J199: =IF(B199="","",IF(AND(F199<=TEXT(DATE(NAM,THANG,1),"yyyy-mm"),OR(G199="",G199>=TEXT(DATE(NAM,THANG,1),"yyyy-mm"))),"Có","Không"))
B202: Loại: Tạm ứng / Trừ khác / KPI trừ = số dương, bị trừ. Cộng khác / Truy lĩnh = cộng. Chuyên cần = cộng/trừ vào tiền chuyên cần tính theo quy tắc. Hiệu lực ghi dạng yyyy-mm.

Sheet LUONG
A1: BẢNG LƯƠNG THỜI GIAN
A2: Toàn bộ là công thức. Cột AF THỰC NHẬN là số đưa sang ĐNTT / file chuyển khoản. Dòng 5 ghi cột tương ứng ở Bảng lương cũ (APQT).
A4: STT | B4: Mã NV | C4: Họ và tên | D4: Pháp nhân | E4: Hình thức | F4: Công chuẩn | G4: Lương cơ bản | H4: Lương thử việc | I4: Lương BHXH | J4: Đóng BHXH | K4: Phụ cấp cố định | L4: Nhóm CC | M4: Công | N4: Phép (ngày) | O4: Nghỉ lễ (ngày) | P4: Giờ làm lễ | Q4: Chế độ cty (ngày) | R4: Lương thời gian | S4: Lương phép | T4: Lương nghỉ lễ | U4: Lương làm ngày lễ (+) | V4: Lương chế độ cty | W4: Chuyên cần | X4: Phụ cấp | Y4: Truy lĩnh / cộng khác | Z4: TỔNG LƯƠNG | AA4: BHXH NLĐ | AB4: Tạm ứng | AC4: Trừ khác (nợ…) | AD4: KPI trừ | AE4: Tổng trừ | AF4: THỰC NHẬN | AG4: Ghi chú
B5: Cũ: C | C5: Cũ: D | E5: Cũ: H | F5: Cũ: AH | G5: Cũ: O | H5: Cũ: N | I5: Cũ: M | K5: Cũ: Q | M5: Cũ: J | N5: Cũ: K | O5: Cũ: L | R5: Cũ: S | S5: Cũ: U | T5: Cũ: V | W5: Cũ: T | X5: Cũ: Q | Y5: Cũ: P | Z5: Cũ: W | AA5: Cũ: X | AB5: Cũ: Y | AC5: Cũ: AA | AD5: Cũ: Z | AE5: Cũ: AB | AF5: Cũ: AC | AG5: Cũ: AG
A6: =IF(B6="","",ROW()-5) -> 1 | B6: =IF(BCC!B6="","",BCC!B6) -> 046180000983 | C6: =IF(B6="","",IFERROR(INDEX(NV_TEN,MATCH(B6,NV_MA,0)),"MÃ KHÔNG CÓ")) -> Hồ Thị Ngọc Á | D6: =IF(B6="","",IFERROR(INDEX(NV_PN,MATCH(B6,NV_MA,0)),"")) -> APQT | E6: =IF(B6="","",IFERROR(INDEX(NV_HT,MATCH(B6,NV_MA,0)),"")) -> Khoán tháng | F6: =IF(B6="","",IFERROR(INDEX(NV_CC,MATCH(B6,NV_MA,0)),"")) -> 26 | G6: =IF(B6="","",IFERROR(INDEX(NV_CB,MATCH(B6,NV_MA,0)),"")) -> 16000000 | H6: =IF(B6="","",IFERROR(INDEX(NV_TV,MATCH(B6,NV_MA,0)),"")) -> 0 | I6: =IF(B6="","",IFERROR(INDEX(NV_BHXH,MATCH(B6,NV_MA,0)),"")) -> 6928000 | J6: =IF(B6="","",IFERROR(INDEX(NV_DONG,MATCH(B6,NV_MA,0)),"")) -> Có | K6: =IF(B6="","",IFERROR(INDEX(NV_PC,MATCH(B6,NV_MA,0)),"")) -> 2000000 | L6: =IF(B6="","",IFERROR(INDEX(NV_NHOMCC,MATCH(B6,NV_MA,0)),"")) -> Không | M6: =IF(B6="","",IFERROR(INDEX(BCC_CONG,MATCH(B6,BCC_MA,0)),0)) -> 27 | N6: =IF(B6="","",IFERROR(INDEX(BCC_PHEP,MATCH(B6,BCC_MA,0)),0)) -> 0 | O6: =IF(B6="","",IFERROR(INDEX(BCC_LE,MATCH(B6,BCC_MA,0)),0)) -> 0 | P6: =IF(B6="","",IFERROR(INDEX(BCC_LEDL,MATCH(B6,BCC_MA,0)),0)) -> 0 | Q6: =IF(B6="","",IFERROR(INDEX(BCC_CD,MATCH(B6,BCC_MA,0)),0)) -> 0 | R6: =IF(B6="","",IF(E6="Khoán tháng",G6,IF(E6="Thử việc",IF(N(H6)>0,H6,G6*TL_THUVIEC),G6)/F6*M6)) -> 16000000 | S6: =IF(B6="","",IF(E6="Khoán tháng",0,I6/NGAY_CHIA*N6)) -> 0 | T6: =IF(B6="","",IF(E6="Khoán tháng",0,I6/NGAY_CHIA*O6)) -> 0 | U6: =IF(B6="","",IF(E6="Khoán tháng",0,G6/F6/GIO_CONG*P6*HS_LE)) -> 0 | V6: =IF(B6="","",IF(E6="Khoán tháng",0,I6/NGAY_CHIA*Q6)) -> 0 | W6: =IF(B6="","",IF(L6="Chung",IF(M6>=CC_NGUONG,CC_TIEN,0),IF(L6="Cơ điện",IF(M6>CD_N2,CD_T2,IF(M6>CD_N1,CD_T1,0)),0))+SUMIFS(DC_TIEN,DC_MA,$B6,DC_LOAI,"Chuyên cần",DC_AP,"Có")) -> 0 | X6: =IF(B6="","",N(K6)) -> 2000000 | Y6: =IF(B6="","",SUMIFS(DC_TIEN,DC_MA,$B6,DC_LOAI,"Truy lĩnh",DC_AP,"Có")+SUMIFS(DC_TIEN,DC_MA,$B6,DC_LOAI,"Cộng khác",DC_AP,"Có")) -> 0 | Z6: =IF(B6="","",SUM(R6:Y6)) -> 18000000 | AA6: =IF(B6="","",IF(J6="Có",I6*BHXH_NLD,0)) -> 727440 | AB6: =IF(B6="","",SUMIFS(DC_TIEN,DC_MA,$B6,DC_LOAI,"Tạm ứng",DC_AP,"Có")) -> 0 | AC6: =IF(B6="","",SUMIFS(DC_TIEN,DC_MA,$B6,DC_LOAI,"Trừ khác",DC_AP,"Có")) -> 0 | AD6: =IF(B6="","",SUMIFS(DC_TIEN,DC_MA,$B6,DC_LOAI,"KPI trừ",DC_AP,"Có")) -> 0 | AE6: =IF(B6="","",SUM(AA6:AD6)) -> 727440 | AF6: =IF(B6="","",ROUNDDOWN(Z6-AE6,-3)) -> 17272000
A7: =IF(B7="","",ROW()-5) -> 2 | B7: =IF(BCC!B7="","",BCC!B7) -> 045086000771 | C7: =IF(B7="","",IFERROR(INDEX(NV_TEN,MATCH(B7,NV_MA,0)),"MÃ KHÔNG CÓ")) -> Nguyễn Nhật Tân | D7: =IF(B7="","",IFERROR(INDEX(NV_PN,MATCH(B7,NV_MA,0)),"")) -> APQT | E7: =IF(B7="","",IFERROR(INDEX(NV_HT,MATCH(B7,NV_MA,0)),"")) -> Thời gian | F7: =IF(B7="","",IFERROR(INDEX(NV_CC,MATCH(B7,NV_MA,0)),"")) -> 30 | G7: =IF(B7="","",IFERROR(INDEX(NV_CB,MATCH(B7,NV_MA,0)),"")) -> 15000000 | H7: =IF(B7="","",IFERROR(INDEX(NV_TV,MATCH(B7,NV_MA,0)),"")) -> 0 | I7: =IF(B7="","",IFERROR(INDEX(NV_BHXH,MATCH(B7,NV_MA,0)),"")) -> 6928000 | J7: =IF(B7="","",IFERROR(INDEX(NV_DONG,MATCH(B7,NV_MA,0)),"")) -> Có | K7: =IF(B7="","",IFERROR(INDEX(NV_PC,MATCH(B7,NV_MA,0)),"")) -> 2000000 | L7: =IF(B7="","",IFERROR(INDEX(NV_NHOMCC,MATCH(B7,NV_MA,0)),"")) -> Không | M7: =IF(B7="","",IFERROR(INDEX(BCC_CONG,MATCH(B7,BCC_MA,0)),0)) -> 31 | N7: =IF(B7="","",IFERROR(INDEX(BCC_PHEP,MATCH(B7,BCC_MA,0)),0)) -> 0 | O7: =IF(B7="","",IFERROR(INDEX(BCC_LE,MATCH(B7,BCC_MA,0)),0)) -> 0 | P7: =IF(B7="","",IFERROR(INDEX(BCC_LEDL,MATCH(B7,BCC_MA,0)),0)) -> 0 | Q7: =IF(B7="","",IFERROR(INDEX(BCC_CD,MATCH(B7,BCC_MA,0)),0)) -> 0 | R7: =IF(B7="","",IF(E7="Khoán tháng",G7,IF(E7="Thử việc",IF(N(H7)>0,H7,G7*TL_THUVIEC),G7)/F7*M7)) -> 15500000 | S7: =IF(B7="","",IF(E7="Khoán tháng",0,I7/NGAY_CHIA*N7)) -> 0 | T7: =IF(B7="","",IF(E7="Khoán tháng",0,I7/NGAY_CHIA*O7)) -> 0 | U7: =IF(B7="","",IF(E7="Khoán tháng",0,G7/F7/GIO_CONG*P7*HS_LE)) -> 0 | V7: =IF(B7="","",IF(E7="Khoán tháng",0,I7/NGAY_CHIA*Q7)) -> 0 | W7: =IF(B7="","",IF(L7="Chung",IF(M7>=CC_NGUONG,CC_TIEN,0),IF(L7="Cơ điện",IF(M7>CD_N2,CD_T2,IF(M7>CD_N1,CD_T1,0)),0))+SUMIFS(DC_TIEN,DC_MA,$B7,DC_LOAI,"Chuyên cần",DC_AP,"Có")) -> 0 | X7: =IF(B7="","",N(K7)) -> 2000000 | Y7: =IF(B7="","",SUMIFS(DC_TIEN,DC_MA,$B7,DC_LOAI,"Truy lĩnh",DC_AP,"Có")+SUMIFS(DC_TIEN,DC_MA,$B7,DC_LOAI,"Cộng khác",DC_AP,"Có")) -> 0 | Z7: =IF(B7="","",SUM(R7:Y7)) -> 17500000 | AA7: =IF(B7="","",IF(J7="Có",I7*BHXH_NLD,0)) -> 727440 | AB7: =IF(B7="","",SUMIFS(DC_TIEN,DC_MA,$B7,DC_LOAI,"Tạm ứng",DC_AP,"Có")) -> 0 | AC7: =IF(B7="","",SUMIFS(DC_TIEN,DC_MA,$B7,DC_LOAI,"Trừ khác",DC_AP,"Có")) -> 0 | AD7: =IF(B7="","",SUMIFS(DC_TIEN,DC_MA,$B7,DC_LOAI,"KPI trừ",DC_AP,"Có")) -> 0 | AE7: =IF(B7="","",SUM(AA7:AD7)) -> 727440 | AF7: =IF(B7="","",ROUNDDOWN(Z7-AE7,-3)) -> 16772000
A8: =IF(B8="","",ROW()-5) -> 3 | B8: =IF(BCC!B8="","",BCC!B8) -> 046077009424 | C8: =IF(B8="","",IFERROR(INDEX(NV_TEN,MATCH(B8,NV_MA,0)),"MÃ KHÔNG CÓ")) -> Đặng Quang Chung | D8: =IF(B8="","",IFERROR(INDEX(NV_PN,MATCH(B8,NV_MA,0)),"")) -> APQT | E8: =IF(B8="","",IFERROR(INDEX(NV_HT,MATCH(B8,NV_MA,0)),"")) -> Thời gian | F8: =IF(B8="","",IFERROR(INDEX(NV_CC,MATCH(B8,NV_MA,0)),"")) -> 30 | G8: =IF(B8="","",IFERROR(INDEX(NV_CB,MATCH(B8,NV_MA,0)),"")) -> 17000000 | H8: =IF(B8="","",IFERROR(INDEX(NV_TV,MATCH(B8,NV_MA,0)),"")) -> 0 | I8: =IF(B8="","",IFERROR(INDEX(NV_BHXH,MATCH(B8,NV_MA,0)),"")) -> 6928000 | J8: =IF(B8="","",IFERROR(INDEX(NV_DONG,MATCH(B8,NV_MA,0)),"")) -> Có | K8: =IF(B8="","",IFERROR(INDEX(NV_PC,MATCH(B8,NV_MA,0)),"")) -> 0 | L8: =IF(B8="","",IFERROR(INDEX(NV_NHOMCC,MATCH(B8,NV_MA,0)),"")) -> Không | M8: =IF(B8="","",IFERROR(INDEX(BCC_CONG,MATCH(B8,BCC_MA,0)),0)) -> 31 | N8: =IF(B8="","",IFERROR(INDEX(BCC_PHEP,MATCH(B8,BCC_MA,0)),0)) -> 1 | O8: =IF(B8="","",IFERROR(INDEX(BCC_LE,MATCH(B8,BCC_MA,0)),0)) -> 0 | P8: =IF(B8="","",IFERROR(INDEX(BCC_LEDL,MATCH(B8,BCC_MA,0)),0)) -> 0 | Q8: =IF(B8="","",IFERROR(INDEX(BCC_CD,MATCH(B8,BCC_MA,0)),0)) -> 0 | R8: =IF(B8="","",IF(E8="Khoán tháng",G8,IF(E8="Thử việc",IF(N(H8)>0,H8,G8*TL_THUVIEC),G8)/F8*M8)) -> 17566667 | S8: =IF(B8="","",IF(E8="Khoán tháng",0,I8/NGAY_CHIA*N8)) -> 266461.54 | T8: =IF(B8="","",IF(E8="Khoán tháng",0,I8/NGAY_CHIA*O8)) -> 0 | U8: =IF(B8="","",IF(E8="Khoán tháng",0,G8/F8/GIO_CONG*P8*HS_LE)) -> 0 | V8: =IF(B8="","",IF(E8="Khoán tháng",0,I8/NGAY_CHIA*Q8)) -> 0 | W8: =IF(B8="","",IF(L8="Chung",IF(M8>=CC_NGUONG,CC_TIEN,0),IF(L8="Cơ điện",IF(M8>CD_N2,CD_T2,IF(M8>CD_N1,CD_T1,0)),0))+SUMIFS(DC_TIEN,DC_MA,$B8,DC_LOAI,"Chuyên cần",DC_AP,"Có")) -> 0 | X8: =IF(B8="","",N(K8)) -> 0 | Y8: =IF(B8="","",SUMIFS(DC_TIEN,DC_MA,$B8,DC_LOAI,"Truy lĩnh",DC_AP,"Có")+SUMIFS(DC_TIEN,DC_MA,$B8,DC_LOAI,"Cộng khác",DC_AP,"Có")) -> 0 | Z8: =IF(B8="","",SUM(R8:Y8)) -> 17833128 | AA8: =IF(B8="","",IF(J8="Có",I8*BHXH_NLD,0)) -> 727440 | AB8: =IF(B8="","",SUMIFS(DC_TIEN,DC_MA,$B8,DC_LOAI,"Tạm ứng",DC_AP,"Có")) -> 0 | AC8: =IF(B8="","",SUMIFS(DC_TIEN,DC_MA,$B8,DC_LOAI,"Trừ khác",DC_AP,"Có")) -> 0 | AD8: =IF(B8="","",SUMIFS(DC_TIEN,DC_MA,$B8,DC_LOAI,"KPI trừ",DC_AP,"Có")) -> 0 | AE8: =IF(B8="","",SUM(AA8:AD8)) -> 727440 | AF8: =IF(B8="","",ROUNDDOWN(Z8-AE8,-3)) -> 17105000
A9: =IF(B9="","",ROW()-5) -> 4 | B9: =IF(BCC!B9="","",BCC!B9) -> 046086012110 | C9: =IF(B9="","",IFERROR(INDEX(NV_TEN,MATCH(B9,NV_MA,0)),"MÃ KHÔNG CÓ")) -> Nguyễn Hào | D9: =IF(B9="","",IFERROR(INDEX(NV_PN,MATCH(B9,NV_MA,0)),"")) -> APQT | E9: =IF(B9="","",IFERROR(INDEX(NV_HT,MATCH(B9,NV_MA,0)),"")) -> Thời gian | F9: =IF(B9="","",IFERROR(INDEX(NV_CC,MATCH(B9,NV_MA,0)),"")) -> 26 | G9: =IF(B9="","",IFERROR(INDEX(NV_CB,MATCH(B9,NV_MA,0)),"")) -> 9620000 | H9: =IF(B9="","",IFERROR(INDEX(NV_TV,MATCH(B9,NV_MA,0)),"")) -> 0 | I9: =IF(B9="","",IFERROR(INDEX(NV_BHXH,MATCH(B9,NV_MA,0)),"")) -> 4375000 | J9: =IF(B9="","",IFERROR(INDEX(NV_DONG,MATCH(B9,NV_MA,0)),"")) -> Có | K9: =IF(B9="","",IFERROR(INDEX(NV_PC,MATCH(B9,NV_MA,0)),"")) -> 0 | L9: =IF(B9="","",IFERROR(INDEX(NV_NHOMCC,MATCH(B9,NV_MA,0)),"")) -> Chung | M9: =IF(B9="","",IFERROR(INDEX(BCC_CONG,MATCH(B9,BCC_MA,0)),0)) -> 29 | N9: =IF(B9="","",IFERROR(INDEX(BCC_PHEP,MATCH(B9,BCC_MA,0)),0)) -> 0 | O9: =IF(B9="","",IFERROR(INDEX(BCC_LE,MATCH(B9,BCC_MA,0)),0)) -> 0 | P9: =IF(B9="","",IFERROR(INDEX(BCC_LEDL,MATCH(B9,BCC_MA,0)),0)) -> 0 | Q9: =IF(B9="","",IFERROR(INDEX(BCC_CD,MATCH(B9,BCC_MA,0)),0)) -> 0 | R9: =IF(B9="","",IF(E9="Khoán tháng",G9,IF(E9="Thử việc",IF(N(H9)>0,H9,G9*TL_THUVIEC),G9)/F9*M9)) -> 10730000 | S9: =IF(B9="","",IF(E9="Khoán tháng",0,I9/NGAY_CHIA*N9)) -> 0 | T9: =IF(B9="","",IF(E9="Khoán tháng",0,I9/NGAY_CHIA*O9)) -> 0 | U9: =IF(B9="","",IF(E9="Khoán tháng",0,G9/F9/GIO_CONG*P9*HS_LE)) -> 0 | V9: =IF(B9="","",IF(E9="Khoán tháng",0,I9/NGAY_CHIA*Q9)) -> 0 | W9: =IF(B9="","",IF(L9="Chung",IF(M9>=CC_NGUONG,CC_TIEN,0),IF(L9="Cơ điện",IF(M9>CD_N2,CD_T2,IF(M9>CD_N1,CD_T1,0)),0))+SUMIFS(DC_TIEN,DC_MA,$B9,DC_LOAI,"Chuyên cần",DC_AP,"Có")) -> 0 | X9: =IF(B9="","",N(K9)) -> 0 | Y9: =IF(B9="","",SUMIFS(DC_TIEN,DC_MA,$B9,DC_LOAI,"Truy lĩnh",DC_AP,"Có")+SUMIFS(DC_TIEN,DC_MA,$B9,DC_LOAI,"Cộng khác",DC_AP,"Có")) -> 0 | Z9: =IF(B9="","",SUM(R9:Y9)) -> 10730000 | AA9: =IF(B9="","",IF(J9="Có",I9*BHXH_NLD,0)) -> 459375 | AB9: =IF(B9="","",SUMIFS(DC_TIEN,DC_MA,$B9,DC_LOAI,"Tạm ứng",DC_AP,"Có")) -> 0 | AC9: =IF(B9="","",SUMIFS(DC_TIEN,DC_MA,$B9,DC_LOAI,"Trừ khác",DC_AP,"Có")) -> 0 | AD9: =IF(B9="","",SUMIFS(DC_TIEN,DC_MA,$B9,DC_LOAI,"KPI trừ",DC_AP,"Có")) -> 0 | AE9: =IF(B9="","",SUM(AA9:AD9)) -> 459375 | AF9: =IF(B9="","",ROUNDDOWN(Z9-AE9,-3)) -> 10270000
A10: =IF(B10="","",ROW()-5) -> 5 | B10: =IF(BCC!B10="","",BCC!B10) -> 046485004744 | C10: =IF(B10="","",IFERROR(INDEX(NV_TEN,MATCH(B10,NV_MA,0)),"MÃ KHÔNG CÓ")) -> Nguyễn Mạnh Thắng | D10: =IF(B10="","",IFERROR(INDEX(NV_PN,MATCH(B10,NV_MA,0)),"")) -> APQT | E10: =IF(B10="","",IFERROR(INDEX(NV_HT,MATCH(B10,NV_MA,0)),"")) -> Thời gian | F10: =IF(B10="","",IFERROR(INDEX(NV_CC,MATCH(B10,NV_MA,0)),"")) -> 26 | G10: =IF(B10="","",IFERROR(INDEX(NV_CB,MATCH(B10,NV_MA,0)),"")) -> 9620000 | H10: =IF(B10="","",IFERROR(INDEX(NV_TV,MATCH(B10,NV_MA,0)),"")) -> 0 | I10: =IF(B10="","",IFERROR(INDEX(NV_BHXH,MATCH(B10,NV_MA,0)),"")) -> 4163000 | J10: =IF(B10="","",IFERROR(INDEX(NV_DONG,MATCH(B10,NV_MA,0)),"")) -> Có | K10: =IF(B10="","",IFERROR(INDEX(NV_PC,MATCH(B10,NV_MA,0)),"")) -> 0 | L10: =IF(B10="","",IFERROR(INDEX(NV_NHOMCC,MATCH(B10,NV_MA,0)),"")) -> Chung | M10: =IF(B10="","",IFERROR(INDEX(BCC_CONG,MATCH(B10,BCC_MA,0)),0)) -> 25.5 | N10: =IF(B10="","",IFERROR(INDEX(BCC_PHEP,MATCH(B10,BCC_MA,0)),0)) -> 0 | O10: =IF(B10="","",IFERROR(INDEX(BCC_LE,MATCH(B10,BCC_MA,0)),0)) -> 0 | P10: =IF(B10="","",IFERROR(INDEX(BCC_LEDL,MATCH(B10,BCC_MA,0)),0)) -> 0 | Q10: =IF(B10="","",IFERROR(INDEX(BCC_CD,MATCH(B10,BCC_MA,0)),0)) -> 0 | R10: =IF(B10="","",IF(E10="Khoán tháng",G10,IF(E10="Thử việc",IF(N(H10)>0,H10,G10*TL_THUVIEC),G10)/F10*M10)) -> 9435000 | S10: =IF(B10="","",IF(E10="Khoán tháng",0,I10/NGAY_CHIA*N10)) -> 0 | T10: =IF(B10="","",IF(E10="Khoán tháng",0,I10/NGAY_CHIA*O10)) -> 0 | U10: =IF(B10="","",IF(E10="Khoán tháng",0,G10/F10/GIO_CONG*P10*HS_LE)) -> 0 | V10: =IF(B10="","",IF(E10="Khoán tháng",0,I10/NGAY_CHIA*Q10)) -> 0 | W10: =IF(B10="","",IF(L10="Chung",IF(M10>=CC_NGUONG,CC_TIEN,0),IF(L10="Cơ điện",IF(M10>CD_N2,CD_T2,IF(M10>CD_N1,CD_T1,0)),0))+SUMIFS(DC_TIEN,DC_MA,$B10,DC_LOAI,"Chuyên cần",DC_AP,"Có")) -> 0 | X10: =IF(B10="","",N(K10)) -> 0 | Y10: =IF(B10="","",SUMIFS(DC_TIEN,DC_MA,$B10,DC_LOAI,"Truy lĩnh",DC_AP,"Có")+SUMIFS(DC_TIEN,DC_MA,$B10,DC_LOAI,"Cộng khác",DC_AP,"Có")) -> 0 | Z10: =IF(B10="","",SUM(R10:Y10)) -> 9435000 | AA10: =IF(B10="","",IF(J10="Có",I10*BHXH_NLD,0)) -> 437115 | AB10: =IF(B10="","",SUMIFS(DC_TIEN,DC_MA,$B10,DC_LOAI,"Tạm ứng",DC_AP,"Có")) -> 0 | AC10: =IF(B10="","",SUMIFS(DC_TIEN,DC_MA,$B10,DC_LOAI,"Trừ khác",DC_AP,"Có")) -> 0 | AD10: =IF(B10="","",SUMIFS(DC_TIEN,DC_MA,$B10,DC_LOAI,"KPI trừ",DC_AP,"Có")) -> 0 | AE10: =IF(B10="","",SUM(AA10:AD10)) -> 437115 | AF10: =IF(B10="","",ROUNDDOWN(Z10-AE10,-3)) -> 8997000
