Workbook

Sheet HDSD
A1: LƯƠNG KHOÁN SẢN XUẤT & ĐỘI XE CONTAINER – FILE CHUẨN HOÁ
A2: Bản chuẩn hoá từ sheet "BCC sx khoán" (file Lương nội bộ HAPĐ T8/2026) và file "Theo dõi chi phí đội xe container". Bước đệm trước khi đưa lên ERP.
A4: QUY ƯỚC MÀU
A5: Chữ xanh dương, nền vàng nhạt | B5: Ô NHẬP LIỆU – người dùng gõ vào. Không gõ vào bất kỳ ô nào khác.
A6: Nền vàng đậm | B6: Tham số/đơn giá CẦN HCNS – KẾ TOÁN XÁC NHẬN (giá trị hiện tại lấy từ file cũ hoặc là ví dụ).
A7: Chữ đen | B7: Công thức – không sửa. Sheet đã khoá vùng công thức (mật khẩu trống, bỏ khoá: Review → Unprotect).
A8: Nền xanh lá | B8: Kết quả cuối – là số đưa sang Bảng lương (cột "Lương khoán + ăn khoán" và "Số ngày công khoán").
A10: QUY TRÌNH HÀNG THÁNG – SẢN XUẤT KHOÁN
A11: 1. THAM_SO | B11: Nhập tháng/năm, tổng tấn chế biến, tấn hàng hanging, tấn hàng chèn. Các đơn giá/định mức chỉ sửa khi có quyết định mới.
A12: 2. NHAN_VIEN | B12: Thêm người mới (mã NV lấy từ máy chấm công), hệ số, hình thức Khoán / Công nhật. Người nghỉ: đổi Tình trạng, không xoá dòng.
A13: 3. KHOAN_KHAC | B13: Nhập các việc khoán khác (chèn hàng, vệ sinh máy, khẩu trang…) và khoản trừ (thời vụ A Lưới). Để trống "Mã NV nhận" = chia chung theo giờ; điền mã = trả đích danh người đó.
A14: 4. BCC_KHOAN | B14: Nhập số giờ từng ngày cho từng mã NV (đúng như sheet cũ). Ngày/thứ tự sinh theo tháng.
A15: 5. LUONG_KHOAN | B15: Tự tính. Cột "Tổng lương khoán" và "Tiền ăn" là số đưa sang Bảng lương. Không có ô nào phải gõ.
A16: 6. KIEM_TRA | B16: Mọi dòng phải là OK trước khi chốt. Có dòng LỖI thì xem ghi chú bên cạnh.
A18: QUY TRÌNH HÀNG THÁNG – ĐỘI XE
A19: 1. XE_THAM_SO / XE_TUYEN | B19: Bảng đơn giá theo tuyến, hỗ trợ vượt ngày, hỗ trợ dầu, tỷ giá kíp. Đây là phần file cũ CHƯA CÓ – số hiện tại là VÍ DỤ, HCNS phải điền theo quy chế lương tài xế.
A20: 2. XE_CHUYEN | B20: Mỗi chuyến một dòng (tài xế, tuyến, ngày đi/về, km, số PĐĐ). Lương chuyến tự tính.
A21: 3. XE_CHI_PHI | B21: Mỗi khoản tạm ứng / chi phí một dòng, ghi rõ tiền tệ (VND/LAK) và "Được tính" (Có/Không). Thay cho việc ghi xen kẽ trong 6 sheet tài xế.
A22: 4. XE_LUONG | B22: Tự tổng hợp theo tài xế: lương khoán chuyến (đưa sang Bảng lương cột X), quyết toán tạm ứng.
A24: ĐỐI CHIẾU VỚI SHEET CŨ "BCC sx khoán"
A25: W2 Khối lượng chế biến | B25: → THAM_SO!C6
A26: AH2/AH3 Hàng hanging | B26: → THAM_SO!C7, C8
A27: AN2/AN3 Hàng chèn | B27: → THAM_SO!C9, C10
A28: W4 = W3/42 | B28: → 42 = THAM_SO!C11 "Số LĐ định mức" (trước đây gõ cứng trong công thức)
A29: (W2*500*41) tiền ăn | B29: → THAM_SO!C12 = 20.500 đ/tấn (trước đây gõ cứng)
A30: (M15 − 400.000) và +100.000/+200.000 | B30: → KHOAN_KHAC: để trống mã = chia chung; điền mã = đích danh. Không còn số cứng.
A31: '[5]HS sx'!B4:C16 (file ngoài) | B31: → sheet HS_SX trong file này
A32: Bảng công nhật T6:AN14 | B32: → NHAN_VIEN với Hình thức = "Công nhật" + chấm giờ chung trong BCC_KHOAN
A33: Cột AS "Tổng lương khoán", AU "Tiền ăn sau khoán" | B33: → LUONG_KHOAN cột Q, R (công thức giống hệt, đã kiểm chứng bằng số liệu T8/2026)

Sheet THAM_SO
A1: THAM SỐ KỲ LƯƠNG KHOÁN SẢN XUẤT
A2: Ô xanh/nền vàng nhạt: nhập mỗi tháng. Ô nền vàng đậm: định mức – chỉ đổi khi có quyết định. Phần "Tính toán" là công thức.
B3: Tháng | C3: 8
B4: Năm | C4: 2026
B6: Khối lượng chế biến trong tháng (tấn) | C6: 1077.49 | D6: Ô W2 cũ. Đã gồm hàng hanging, đã trích lại 10%, không gồm hàng chèn.
B7: Khối lượng hàng hanging (tấn) | C7: 0 | D7: Ô AH2 cũ
B8: Đơn giá cộng thêm hàng hanging (đ/tấn) | C8: 252000 | D8: Ô AH3 cũ
B9: Khối lượng hàng chèn (tấn) | C9: 105.37 | D9: Ô AN2 cũ. Hàng chèn đã nhập kho nên không nằm trong tấn chế biến.
B10: Đơn giá hàng chèn (đ/tấn) | C10: 140000 | D10: Ô AN3 cũ
B11: Số lao động định mức (N) | C11: 42 | D11: Số 42 gõ cứng trong công thức W4 = W3/42. Ghi chú A1 sheet cũ: "check số lượng nhân công khoán sửa lại số nhân". CẦN XÁC NHẬN đây là hằng số định mức hay là số người thực tế.
B12: Định mức tiền ăn theo sản lượng (đ/tấn) | C12: 20500 | D12: Bằng 500 × 41 gõ cứng trong công thức tiền ăn cũ (W2*500*41). CẦN XÁC NHẬN.
B13: Số giờ của 1 công | C13: 8
B14: Đơn giá công nhật mặc định (đ/công) | C14: 270000 | D14: Sheet cũ: 270.000/8 và 300.000/8 – đơn giá riêng từng người khai ở NHAN_VIEN cột G
B15: Làm tròn xuống đến (đ) | C15: 1000 | D15: ROUNDDOWN(…, -3)
B17: TÍNH TOÁN (không sửa)
B18: Tổng giờ công khoán trong tháng (giờ) | C18: =SUMIFS(LUONG_KHOAN!$G$6:$G$100,LUONG_KHOAN!$D$6:$D$100,"Khoán") -> 455 | D18: Ô W3 cũ (=AN64)
B19: Số giờ làm trung bình / người | C19: =IF(C11>0,C18/C11,0) -> 10.833333 | D19: Ô W4 cũ = W3/42
B20: Quỹ hàng hanging (đ) | C20: =C7*C8 -> 0 | D20: Ô AH4 cũ
B21: Quỹ hàng chèn (đ) | C21: =C9*C10 -> 14751800 | D21: Ô AN4 cũ
B22: Quỹ khoán CV khác chia chung theo giờ (đ) | C22: =SUMIFS(KHOAN_KHAC!$F$5:$F$39,KHOAN_KHAC!$G$5:$G$39,"") -> -22450000 | D22: Ô (M15 − 400.000) cũ. Gồm cả khoản trừ (số âm).
B23: Tổng CV khác trả đích danh (đ) | C23: =SUMIFS(KHOAN_KHAC!$F$5:$F$39,KHOAN_KHAC!$G$5:$G$39,"<>") -> 400000 | D23: Các khoản +100.000/+200.000 gõ tay trong cột AQ cũ
B24: Tổng lương công nhật trừ khỏi quỹ khoán (đ) | C24: =SUMIFS(LUONG_KHOAN!$P$6:$P$100,LUONG_KHOAN!$D$6:$D$100,"Công nhật") -> 0 | D24: Ô AL14 cũ
B25: Tổng công tính tiền ăn (khoán + công nhật) | C25: =SUM(LUONG_KHOAN!$H$6:$H$100) -> 56.875 | D25: Ô (AT64 + AF14/8) cũ
B26: Quỹ tiền ăn theo sản lượng (đ) | C26: =C6*C12 -> 22088545 | D26: W2*500*41 cũ
B27: Tiền ăn cho 1 công (đ/công) | C27: =IF(C25>0,C26/C25,0) -> 388370.02
B28: Tổng quỹ lương khoán sản phẩm phân bổ (đ) | C28: =SUMIFS(LUONG_KHOAN!$J$6:$J$100,LUONG_KHOAN!$D$6:$D$100,"Khoán") -> 3.4073218e+08 | D28: Tương đương tấn × 42 × đơn giá bình quân
B29: Chi phí lương khoán bình quân (đ/tấn chế biến) | C29: =IF(C6>0,C28/C6,0) -> 316227.69 | D29: Chỉ số quản trị để so sánh giữa các tháng

Sheet HS_SX
A1: BẢNG ĐƠN GIÁ KHOÁN THEO HỆ SỐ (thay cho file ngoài '[5]HS sx')
A2: 10 cặp giá trị dưới đây lấy từ giá trị đã tính trong sheet cũ. Cột D là quy luật suy ra (400 + 6.000 × hệ số) để kiểm tra – CẦN đối chiếu với file "HS sx" gốc và bổ sung hệ số còn thiếu.
A4: Hệ số | B4: Đơn giá khoán (đ/tấn) | C4: Kiểm tra quy luật 400+6000×hs | D4: Lệch
A5: 0.9 | B5: 5800 | C5: =400+6000*A5 -> 5800 | D5: =B5-C5 -> 0
A6: 1 | B6: 6400 | C6: =400+6000*A6 -> 6400 | D6: =B6-C6 -> 0
A7: 1.05 | B7: 6700 | C7: =400+6000*A7 -> 6700 | D7: =B7-C7 -> 0
A8: 1.1 | B8: 7100 | C8: =400+6000*A8 -> 7000 | D8: =B8-C8 -> 100
A9: 1.15 | B9: 7400 | C9: =400+6000*A9 -> 7300 | D9: =B9-C9 -> 100
A10: 1.2 | B10: 7700 | C10: =400+6000*A10 -> 7600 | D10: =B10-C10 -> 100
A11: 1.25 | B11: 8000 | C11: =400+6000*A11 -> 7900 | D11: =B11-C11 -> 100
A12: 1.3 | B12: 8300 | C12: =400+6000*A12 -> 8200 | D12: =B12-C12 -> 100
A13: 1.35 | B13: 8600 | C13: =400+6000*A13 -> 8500 | D13: =B13-C13 -> 100
A14: 1.4 | B14: 8800 | C14: =400+6000*A14 -> 8800 | D14: =B14-C14 -> 0 | E14: Hệ số 1.4 không có trong dữ liệu tháng 8 – giá trị suy ra từ quy luật, CẦN XÁC NHẬN
A15: 1.5 | B15: 9600 | C15: =400+6000*A15 -> 9400 | D15: =B15-C15 -> 200

Sheet NHAN_VIEN
A1: DANH MỤC NHÂN VIÊN KHOÁN SẢN XUẤT & TÀI XẾ
A2: Mã NV là khoá duy nhất (dùng mã máy chấm công / CCCD như file cũ). Mọi sheet khác tra cứu theo mã, không theo tên. Không xoá dòng người nghỉ – đổi Tình trạng.
A4: STT | B4: Mã NV | C4: Họ và tên | D4: Chức vụ | E4: Bộ phận | F4: Hình thức | G4: Hệ số khoán | H4: Đơn giá công nhật (đ/công) | I4: Tình trạng | J4: Ghi chú
A5: 1 | B5: 046085007061 | C5: Lê Vang | D5: Quản lý SX | E5: Sản xuất | F5: Khoán | G5: 1.5 | I5: Chính thức
A6: 2 | B6: 046077003925 | C6: Trần Đình Mạnh | D6: Tổ phó ca sản xuất | E6: Sản xuất | F6: Khoán | G6: 1.35 | I6: Chính thức
A7: 3 | B7: 046177012486 | C7: Lê Thị Bình | D7: Công nhân Chế biến | E7: Sản xuất | F7: Khoán | G7: 1.1 | I7: Chính thức
A8: 4 | B8: 046179008435 | C8: Trần Thị Tích | D8: Công nhân Chế biến | E8: Sản xuất | F8: Khoán | G8: 1.15 | I8: Chính thức
A9: 5 | B9: 046175005132 | C9: Lê Thị Nga | D9: Công nhân Chế biến | E9: Sản xuất | F9: Khoán | G9: 1.15 | I9: Chính thức
A10: 6 | B10: 046090006706 | C10: Phạm Bá Lượng | D10: Công nhân Chế biến | E10: Sản xuất | F10: Khoán | G10: 1.3 | I10: Chính thức
A11: 7 | B11: 046178011746 | C11: Văn Thị Vinh | D11: Công nhân Chế biến | E11: Sản xuất | F11: Khoán | G11: 1.1 | I11: Chính thức
A12: 8 | B12: 046172008975 | C12: Nguyễn Thị Điệp | D12: Công nhân Chế biến | E12: Sản xuất | F12: Khoán | G12: 1.1 | I12: Chính thức
A13: 9 | B13: NV_KIMANH | C13: Lê Thị Kim Anh | D13: Công nhân Chế biến | E13: Sản xuất | F13: Khoán | G13: 1 | I13: Chính thức | J13: File cũ không có mã NV – tạm đặt, cần bổ sung
A14: 10 | B14: 046074011254 | C14: Trần Đức Phúc | D14: Công nhân Chế biến | E14: Sản xuất | F14: Khoán | G14: 1.1 | I14: Chính thức
A15: 11 | B15: 046172013837 | C15: Nguyễn Thị Nhung | D15: Công nhân Chế biến | E15: Sản xuất | F15: Khoán | G15: 0.9 | I15: Chính thức
A16: 12 | B16: 046175008129 | C16: Lê Thị Thu Hữu | D16: Công nhân Chế biến | E16: Sản xuất | F16: Khoán | G16: 1.1 | I16: Chính thức
A17: 13 | B17: 046206004482 | C17: Trần Đình Lĩnh | D17: Công nhân Chế biến | E17: Sản xuất | F17: Khoán | G17: 1.05 | I17: Thử việc
A18: 14 | B18: 046178006439 | C18: Nguyễn Thị Thúy Vân | D18: Công nhân Chế biến | E18: Sản xuất | F18: Khoán | G18: 1.15 | I18: Chính thức
A19: 15 | B19: 046172008914 | C19: Trần Thị Thùy | D19: Công nhân Chế biến | E19: Sản xuất | F19: Khoán | G19: 1.1 | I19: Chính thức
A20: 16 | B20: 046177011413 | C20: Lê Thị Thơ | D20: Công nhân Chế biến | E20: Sản xuất | F20: Khoán | G20: 1.1 | I20: Chính thức
A21: 17 | B21: 046176012012 | C21: Lê Thị Hồng Lan | D21: Công nhân Chế biến | E21: Sản xuất | F21: Khoán | G21: 1 | I21: Chính thức
A22: 18 | B22: 046091004633 | C22: Nguyễn Quang Thọ | D22: Công nhân Chế biến | E22: Sản xuất | F22: Khoán | G22: 0.9 | I22: Chính thức | J22: File cũ mã có khoảng trắng thừa – đã cắt
A23: 19 | B23: 046074013724 | C23: Nguyễn Ngọc Phương | D23: Công nhân Chế biến | E23: Sản xuất | F23: Khoán | G23: 1.3 | I23: Chính thức
A24: 20 | B24: 046099007864 | C24: Lê Lộc | D24: Công nhân Chế biến | E24: Sản xuất | F24: Khoán | G24: 1.15 | I24: Chính thức
A25: 21 | B25: 002191001272 | C25: Thèn Thị Giang | D25: Công nhân Chế biến | E25: Sản xuất | F25: Khoán | G25: 1.15 | I25: Thử việc
A26: 22 | B26: 046087002473 | C26: Nguyễn Tình | D26: Công nhân Chế biến | E26: Sản xuất | F26: Khoán | G26: 0.9 | I26: Thử việc
A27: 23 | B27: 046178010147 | C27: Đặng Thị Huế | D27: Công nhân Chế biến | E27: Sản xuất | F27: Khoán | G27: 1.1 | I27: Chính thức
A28: 24 | B28: 046089009803 | C28: Trần Văn Trình | D28: Tổ trưởng ca sản xuất | E28: Sản xuất | F28: Khoán | G28: 0.9 | I28: Chính thức
A29: 25 | B29: 046084009142 | C29: Trần Văn Hiền | D29: Tổ phó ca sản xuất | E29: Sản xuất | F29: Khoán | G29: 1.5 | I29: Chính thức
A30: 26 | B30: 046207415351 | C30: Trần Văn Tâm | D30: Công nhân Chế biến | E30: Sản xuất | F30: Khoán | G30: 1.15 | I30: Chính thức
A31: 27 | B31: NV_DINHHAI | C31: Trần Đình Hải | D31: Công nhân Chế biến | E31: Sản xuất | F31: Khoán | G31: 1.2 | I31: Chính thức | J31: File cũ dùng TRÙNG mã với Trần Văn Tâm – tạm đặt, cần bổ sung mã đúng
A32: 28 | B32: 046064009756 | C32: Hoàng Lự | D32: Công nhân Chế biến | E32: Sản xuất | F32: Khoán | G32: 1.1 | I32: Chính thức
A33: 29 | B33: 046172013307 | C33: Ngô Thị Thủy | D33: Công nhân Chế biến | E33: Sản xuất | F33: Khoán | G33: 1.1 | I33: Chính thức
A34: 30 | B34: 046165007228 | C34: Lê Thị Hương | D34: Công nhân Chế biến | E34: Sản xuất | F34: Khoán | G34: 1 | I34: Chính thức
A35: 31 | B35: 046181009164 | C35: Hoàng Thị Nhung | D35: Công nhân Chế biến | E35: Sản xuất | F35: Khoán | G35: 1.15 | I35: Chính thức
A36: 32 | B36: 046173005614 | C36: Trần Thị Thu Thủy | D36: Công nhân Chế biến | E36: Sản xuất | F36: Khoán | G36: 1.1 | I36: Chính thức
A37: 33 | B37: 046180005626 | C37: Trần Thị Cẩm Hà | D37: Công nhân Chế biến | E37: Sản xuất | F37: Khoán | G37: 1.15 | I37: Chính thức
A38: 34 | B38: 046177004568 | C38: Nguyễn Thị Kim Tin | D38: Công nhân Chế biến | E38: Sản xuất | F38: Khoán | G38: 1.15 | I38: Chính thức
A39: 35 | B39: 046176012968 | C39: Nguyễn Thị Loan | D39: Công nhân Chế biến | E39: Sản xuất | F39: Khoán | G39: 1.1 | I39: Chính thức
A40: 36 | B40: 046183006914 | C40: Nguyễn Thị Thu Hà | D40: Công nhân Chế biến | E40: Sản xuất | F40: Khoán | G40: 1.1 | I40: Chính thức
A41: 37 | B41: 046077008985 | C41: Ngô Văn Đính | D41: Công nhân Chế biến | E41: Sản xuất | F41: Khoán | G41: 1.25 | I41: Chính thức
...

Sheet KHOAN_KHAC
A1: KHOÁN CÔNG VIỆC KHÁC & CÁC KHOẢN CỘNG/TRỪ VÀO QUỸ KHOÁN
A2: Thay bảng C6:P15 cũ. Để trống "Mã NV nhận" → chia chung theo giờ cho cả tổ (ô M15−400.000 cũ). Điền mã → trả đích danh (các ô +100.000/+200.000 gõ tay cũ). Khoản trừ nhập đơn giá âm.
A4: STT | B4: Ngày | C4: Nội dung công việc | D4: Số công | E4: Đơn giá (đ/công) | F4: Thành tiền | G4: Mã NV nhận (đích danh) | H4: Tên (tự tra) | I4: Ghi chú
A5: 1 | B5: 06/07/2026 | C5: Chèn hàng băng tải – phần Lê Vang | D5: 0.5 | E5: 200000 | F5: =D5*E5 -> 100000 | G5: 046085007061 | H5: =IF(G5="","",IFERROR(INDEX(NV_TEN,MATCH(G5,NV_MA,0)),"MÃ KHÔNG CÓ")) -> Lê Vang | I5: Sheet cũ: 2 công × 200.000 = 400.000 rồi chia tay +100k/+100k/+200k
A6: 2 | B6: 06/07/2026 | C6: Chèn hàng băng tải – phần Phạm Bá Lượng | D6: 0.5 | E6: 200000 | F6: =D6*E6 -> 100000 | G6: 046090006706 | H6: =IF(G6="","",IFERROR(INDEX(NV_TEN,MATCH(G6,NV_MA,0)),"MÃ KHÔNG CÓ")) -> Phạm Bá Lượng
A7: 3 | B7: 06/07/2026 | C7: Chèn hàng băng tải – phần Trần Văn Hiền | D7: 1 | E7: 200000 | F7: =D7*E7 -> 200000 | G7: 046084009142 | H7: =IF(G7="","",IFERROR(INDEX(NV_TEN,MATCH(G7,NV_MA,0)),"MÃ KHÔNG CÓ")) -> Trần Văn Hiền
A8: 4 | B8: 22/07/2026 | C8: Xử lý hàng 3L chất vào thùng đóng SW | D8: 4 | E8: 200000 | F8: =D8*E8 -> 800000 | H8: =IF(G8="","",IFERROR(INDEX(NV_TEN,MATCH(G8,NV_MA,0)),"MÃ KHÔNG CÓ"))
A9: 5 | B9: 29/07/2026 | C9: Thay bao dày, đóng kiện SW | D9: 5 | E9: 200000 | F9: =D9*E9 -> 1000000 | H9: =IF(G9="","",IFERROR(INDEX(NV_TEN,MATCH(G9,NV_MA,0)),"MÃ KHÔNG CÓ"))
A10: 6 | B10: 30/07/2026 | C10: Chất hàng đóng SW RSS1 | D10: 10 | E10: 200000 | F10: =D10*E10 -> 2000000 | H10: =IF(G10="","",IFERROR(INDEX(NV_TEN,MATCH(G10,NV_MA,0)),"MÃ KHÔNG CÓ"))
A11: 7 | B11: 08/2026 | C11: Khẩu trang tháng 08 | D11: 4 | E11: 100000 | F11: =D11*E11 -> 400000 | H11: =IF(G11="","",IFERROR(INDEX(NV_TEN,MATCH(G11,NV_MA,0)),"MÃ KHÔNG CÓ"))
A12: 8 | B12: 08/2026 | C12: Khấu trừ CN thời vụ A Lưới làm sản xuất (trừ khỏi quỹ) | D12: 101.5 | E12: -300000 | F12: =D12*E12 -> -30450000 | H12: =IF(G12="","",IFERROR(INDEX(NV_TEN,MATCH(G12,NV_MA,0)),"MÃ KHÔNG CÓ")) | I12: Lấy từ file lương thời vụ A Lưới; đơn giá âm = trừ
A13: 9 | B13: 08/2026 | C13: Vệ sinh máy mix 38 ca | D13: 38 | E13: 100000 | F13: =D13*E13 -> 3800000 | H13: =IF(G13="","",IFERROR(INDEX(NV_TEN,MATCH(G13,NV_MA,0)),"MÃ KHÔNG CÓ"))
F14: =IF(D14="",0,D14*E14) -> 0 | H14: =IF(G14="","",IFERROR(INDEX(NV_TEN,MATCH(G14,NV_MA,0)),"MÃ KHÔNG CÓ"))
F15: =IF(D15="",0,D15*E15) -> 0 | H15: =IF(G15="","",IFERROR(INDEX(NV_TEN,MATCH(G15,NV_MA,0)),"MÃ KHÔNG CÓ"))
F16: =IF(D16="",0,D16*E16) -> 0 | H16: =IF(G16="","",IFERROR(INDEX(NV_TEN,MATCH(G16,NV_MA,0)),"MÃ KHÔNG CÓ"))
F17: =IF(D17="",0,D17*E17) -> 0 | H17: =IF(G17="","",IFERROR(INDEX(NV_TEN,MATCH(G17,NV_MA,0)),"MÃ KHÔNG CÓ"))
F18: =IF(D18="",0,D18*E18) -> 0 | H18: =IF(G18="","",IFERROR(INDEX(NV_TEN,MATCH(G18,NV_MA,0)),"MÃ KHÔNG CÓ"))
F19: =IF(D19="",0,D19*E19) -> 0 | H19: =IF(G19="","",IFERROR(INDEX(NV_TEN,MATCH(G19,NV_MA,0)),"MÃ KHÔNG CÓ"))
F20: =IF(D20="",0,D20*E20) -> 0 | H20: =IF(G20="","",IFERROR(INDEX(NV_TEN,MATCH(G20,NV_MA,0)),"MÃ KHÔNG CÓ"))
F21: =IF(D21="",0,D21*E21) -> 0 | H21: =IF(G21="","",IFERROR(INDEX(NV_TEN,MATCH(G21,NV_MA,0)),"MÃ KHÔNG CÓ"))
F22: =IF(D22="",0,D22*E22) -> 0 | H22: =IF(G22="","",IFERROR(INDEX(NV_TEN,MATCH(G22,NV_MA,0)),"MÃ KHÔNG CÓ"))
F23: =IF(D23="",0,D23*E23) -> 0 | H23: =IF(G23="","",IFERROR(INDEX(NV_TEN,MATCH(G23,NV_MA,0)),"MÃ KHÔNG CÓ"))
F24: =IF(D24="",0,D24*E24) -> 0 | H24: =IF(G24="","",IFERROR(INDEX(NV_TEN,MATCH(G24,NV_MA,0)),"MÃ KHÔNG CÓ"))
F25: =IF(D25="",0,D25*E25) -> 0 | H25: =IF(G25="","",IFERROR(INDEX(NV_TEN,MATCH(G25,NV_MA,0)),"MÃ KHÔNG CÓ"))
... F39: =IF(D39="",0,D39*E39) -> 0 | H39: =IF(G39="","",IFERROR(INDEX(NV_TEN,MATCH(G39,NV_MA,0)),"MÃ KHÔNG CÓ"))
C41: Tổng chia chung theo giờ | F41: =SUMIFS(F5:F39,G5:G39,"") -> -22450000
C42: Tổng trả đích danh | F42: =SUMIFS(F5:F39,G5:G39,"<>") -> 400000
C43: Tổng cộng (ô M15 cũ) | F43: =F41+F42 -> -22050000

Sheet BCC_KHOAN
A1: BẢNG CHẤM CÔNG KHOÁN SẢN XUẤT (giờ/ngày)
A2: Nhập số giờ vào ô xanh. Chỉ nhập số. Ngày lễ nghỉ để trống. Mã NV tra tên tự động; dòng có mã lạ sẽ báo "MÃ KHÔNG CÓ".
A3: Ngày → | E3: =IF(0<DAY(EOMONTH(DATE(NAM,THANG,1),0)),DATE(NAM,THANG,1)+0,"") -> 46235 | F3: =IF(1<DAY(EOMONTH(DATE(NAM,THANG,1),0)),DATE(NAM,THANG,1)+1,"") -> 46236 | G3: =IF(2<DAY(EOMONTH(DATE(NAM,THANG,1),0)),DATE(NAM,THANG,1)+2,"") -> 46237 | H3: =IF(3<DAY(EOMONTH(DATE(NAM,THANG,1),0)),DATE(NAM,THANG,1)+3,"") -> 46238 | I3: =IF(4<DAY(EOMONTH(DATE(NAM,THANG,1),0)),DATE(NAM,THANG,1)+4,"") -> 46239 | J3: =IF(5<DAY(EOMONTH(DATE(NAM,THANG,1),0)),DATE(NAM,THANG,1)+5,"") -> 46240 | K3: =IF(6<DAY(EOMONTH(DATE(NAM,THANG,1),0)),DATE(NAM,THANG,1)+6,"") -> 46241 | L3: =IF(7<DAY(EOMONTH(DATE(NAM,THANG,1),0)),DATE(NAM,THANG,1)+7,"") -> 46242 | M3: =IF(8<DAY(EOMONTH(DATE(NAM,THANG,1),0)),DATE(NAM,THANG,1)+8,"") -> 46243 | N3: =IF(9<DAY(EOMONTH(DATE(NAM,THANG,1),0)),DATE(NAM,THANG,1)+9,"") -> 46244 | O3: =IF(10<DAY(EOMONTH(DATE(NAM,THANG,1),0)),DATE(NAM,THANG,1)+10,"") -> 46245 | P3: =IF(11<DAY(EOMONTH(DATE(NAM,THANG,1),0)),DATE(NAM,THANG,1)+11,"") -> 46246 | Q3: =IF(12<DAY(EOMONTH(DATE(NAM,THANG,1),0)),DATE(NAM,THANG,1)+12,"") -> 46247 | R3: =IF(13<DAY(EOMONTH(DATE(NAM,THANG,1),0)),DATE(NAM,THANG,1)+13,"") -> 46248 | S3: =IF(14<DAY(EOMONTH(DATE(NAM,THANG,1),0)),DATE(NAM,THANG,1)+14,"") -> 46249 | T3: =IF(15<DAY(EOMONTH(DATE(NAM,THANG,1),0)),DATE(NAM,THANG,1)+15,"") -> 46250 | U3: =IF(16<DAY(EOMONTH(DATE(NAM,THANG,1),0)),DATE(NAM,THANG,1)+16,"") -> 46251 | V3: =IF(17<DAY(EOMONTH(DATE(NAM,THANG,1),0)),DATE(NAM,THANG,1)+17,"") -> 46252 | W3: =IF(18<DAY(EOMONTH(DATE(NAM,THANG,1),0)),DATE(NAM,THANG,1)+18,"") -> 46253 | X3: =IF(19<DAY(EOMONTH(DATE(NAM,THANG,1),0)),DATE(NAM,THANG,1)+19,"") -> 46254 | Y3: =IF(20<DAY(EOMONTH(DATE(NAM,THANG,1),0)),DATE(NAM,THANG,1)+20,"") -> 46255 | Z3: =IF(21<DAY(EOMONTH(DATE(NAM,THANG,1),0)),DATE(NAM,THANG,1)+21,"") -> 46256 | AA3: =IF(22<DAY(EOMONTH(DATE(NAM,THANG,1),0)),DATE(NAM,THANG,1)+22,"") -> 46257 | AB3: =IF(23<DAY(EOMONTH(DATE(NAM,THANG,1),0)),DATE(NAM,THANG,1)+23,"") -> 46258 | AC3: =IF(24<DAY(EOMONTH(DATE(NAM,THANG,1),0)),DATE(NAM,THANG,1)+24,"") -> 46259 | AD3: =IF(25<DAY(EOMONTH(DATE(NAM,THANG,1),0)),DATE(NAM,THANG,1)+25,"") -> 46260 | AE3: =IF(26<DAY(EOMONTH(DATE(NAM,THANG,1),0)),DATE(NAM,THANG,1)+26,"") -> 46261 | AF3: =IF(27<DAY(EOMONTH(DATE(NAM,THANG,1),0)),DATE(NAM,THANG,1)+27,"") -> 46262 | AG3: =IF(28<DAY(EOMONTH(DATE(NAM,THANG,1),0)),DATE(NAM,THANG,1)+28,"") -> 46263 | AH3: =IF(29<DAY(EOMONTH(DATE(NAM,THANG,1),0)),DATE(NAM,THANG,1)+29,"") -> 46264 | AI3: =IF(30<DAY(EOMONTH(DATE(NAM,THANG,1),0)),DATE(NAM,THANG,1)+30,"") -> 46265
E4: =IF(E3="","",CHOOSE(WEEKDAY(E3),"CN","T2","T3","T4","T5","T6","T7")) -> T7 | F4: =IF(F3="","",CHOOSE(WEEKDAY(F3),"CN","T2","T3","T4","T5","T6","T7")) -> CN | G4: =IF(G3="","",CHOOSE(WEEKDAY(G3),"CN","T2","T3","T4","T5","T6","T7")) -> T2 | H4: =IF(H3="","",CHOOSE(WEEKDAY(H3),"CN","T2","T3","T4","T5","T6","T7")) -> T3 | I4: =IF(I3="","",CHOOSE(WEEKDAY(I3),"CN","T2","T3","T4","T5","T6","T7")) -> T4 | J4: =IF(J3="","",CHOOSE(WEEKDAY(J3),"CN","T2","T3","T4","T5","T6","T7")) -> T5 | K4: =IF(K3="","",CHOOSE(WEEKDAY(K3),"CN","T2","T3","T4","T5","T6","T7")) -> T6 | L4: =IF(L3="","",CHOOSE(WEEKDAY(L3),"CN","T2","T3","T4","T5","T6","T7")) -> T7 | ... AI4: =IF(AI3="","",CHOOSE(WEEKDAY(AI3),"CN","T2","T3","T4","T5","T6","T7")) -> T2
A5: STT | B5: Mã NV | C5: Họ và tên | D5: Hình thức | E5: 1 | F5: 2 | G5: 3 | H5: 4 | I5: 5 | J5: 6 | K5: 7 | L5: 8 | M5: 9 | N5: 10 | O5: 11 | P5: 12 | Q5: 13 | R5: 14 | S5: 15 | T5: 16 | U5: 17 | V5: 18 | W5: 19 | X5: 20 | Y5: 21 | Z5: 22 | AA5: 23 | AB5: 24 | AC5: 25 | AD5: 26 | AE5: 27 | AF5: 28 | AG5: 29 | AH5: 30 | AI5: 31 | AJ5: Tổng giờ | AK5: Công
A6: 1 | B6: 046085007061 | C6: =IFERROR(INDEX(NV_TEN,MATCH(B6,NV_MA,0)),"MÃ KHÔNG CÓ") -> Lê Vang | D6: =IFERROR(INDEX(NV_HINHTHUC,MATCH(B6,NV_MA,0)),"") -> Khoán | AJ6: =SUM(E6:AI6) -> 0 | AK6: =IF(AJ6=0,0,AJ6/GIO_CONG) -> 0
A7: 2 | B7: 046077003925 | C7: =IFERROR(INDEX(NV_TEN,MATCH(B7,NV_MA,0)),"MÃ KHÔNG CÓ") -> Trần Đình Mạnh | D7: =IFERROR(INDEX(NV_HINHTHUC,MATCH(B7,NV_MA,0)),"") -> Khoán | AJ7: =SUM(E7:AI7) -> 0 | AK7: =IF(AJ7=0,0,AJ7/GIO_CONG) -> 0
A8: 3 | B8: 046177012486 | C8: =IFERROR(INDEX(NV_TEN,MATCH(B8,NV_MA,0)),"MÃ KHÔNG CÓ") -> Lê Thị Bình | D8: =IFERROR(INDEX(NV_HINHTHUC,MATCH(B8,NV_MA,0)),"") -> Khoán | AJ8: =SUM(E8:AI8) -> 0 | AK8: =IF(AJ8=0,0,AJ8/GIO_CONG) -> 0
A9: 4 | B9: 046179008435 | C9: =IFERROR(INDEX(NV_TEN,MATCH(B9,NV_MA,0)),"MÃ KHÔNG CÓ") -> Trần Thị Tích | D9: =IFERROR(INDEX(NV_HINHTHUC,MATCH(B9,NV_MA,0)),"") -> Khoán | AJ9: =SUM(E9:AI9) -> 0 | AK9: =IF(AJ9=0,0,AJ9/GIO_CONG) -> 0
A10: 5 | B10: 046175005132 | C10: =IFERROR(INDEX(NV_TEN,MATCH(B10,NV_MA,0)),"MÃ KHÔNG CÓ") -> Lê Thị Nga | D10: =IFERROR(INDEX(NV_HINHTHUC,MATCH(B10,NV_MA,0)),"") -> Khoán | AJ10: =SUM(E10:AI10) -> 0 | AK10: =IF(AJ10=0,0,AJ10/GIO_CONG) -> 0
A11: 6 | B11: 046090006706 | C11: =IFERROR(INDEX(NV_TEN,MATCH(B11,NV_MA,0)),"MÃ KHÔNG CÓ") -> Phạm Bá Lượng | D11: =IFERROR(INDEX(NV_HINHTHUC,MATCH(B11,NV_MA,0)),"") -> Khoán | AJ11: =SUM(E11:AI11) -> 0 | AK11: =IF(AJ11=0,0,AJ11/GIO_CONG) -> 0
A12: 7 | B12: 046178011746 | C12: =IFERROR(INDEX(NV_TEN,MATCH(B12,NV_MA,0)),"MÃ KHÔNG CÓ") -> Văn Thị Vinh | D12: =IFERROR(INDEX(NV_HINHTHUC,MATCH(B12,NV_MA,0)),"") -> Khoán | AJ12: =SUM(E12:AI12) -> 0 | AK12: =IF(AJ12=0,0,AJ12/GIO_CONG) -> 0
A13: 8 | B13: 046172008975 | C13: =IFERROR(INDEX(NV_TEN,MATCH(B13,NV_MA,0)),"MÃ KHÔNG CÓ") -> Nguyễn Thị Điệp | D13: =IFERROR(INDEX(NV_HINHTHUC,MATCH(B13,NV_MA,0)),"") -> Khoán | AJ13: =SUM(E13:AI13) -> 0 | AK13: =IF(AJ13=0,0,AJ13/GIO_CONG) -> 0
A14: 9 | B14: NV_KIMANH | C14: =IFERROR(INDEX(NV_TEN,MATCH(B14,NV_MA,0)),"MÃ KHÔNG CÓ") -> Lê Thị Kim Anh | D14: =IFERROR(INDEX(NV_HINHTHUC,MATCH(B14,NV_MA,0)),"") -> Khoán | AJ14: =SUM(E14:AI14) -> 0 | AK14: =IF(AJ14=0,0,AJ14/GIO_CONG) -> 0
A15: 10 | B15: 046074011254 | C15: =IFERROR(INDEX(NV_TEN,MATCH(B15,NV_MA,0)),"MÃ KHÔNG CÓ") -> Trần Đức Phúc | D15: =IFERROR(INDEX(NV_HINHTHUC,MATCH(B15,NV_MA,0)),"") -> Khoán | AJ15: =SUM(E15:AI15) -> 0 | AK15: =IF(AJ15=0,0,AJ15/GIO_CONG) -> 0
A16: 11 | B16: 046172013837 | C16: =IFERROR(INDEX(NV_TEN,MATCH(B16,NV_MA,0)),"MÃ KHÔNG CÓ") -> Nguyễn Thị Nhung | D16: =IFERROR(INDEX(NV_HINHTHUC,MATCH(B16,NV_MA,0)),"") -> Khoán | AJ16: =SUM(E16:AI16) -> 0 | AK16: =IF(AJ16=0,0,AJ16/GIO_CONG) -> 0
A17: 12 | B17: 046175008129 | C17: =IFERROR(INDEX(NV_TEN,MATCH(B17,NV_MA,0)),"MÃ KHÔNG CÓ") -> Lê Thị Thu Hữu | D17: =IFERROR(INDEX(NV_HINHTHUC,MATCH(B17,NV_MA,0)),"") -> Khoán | AJ17: =SUM(E17:AI17) -> 0 | AK17: =IF(AJ17=0,0,AJ17/GIO_CONG) -> 0
... A23: 18 | B23: 046091004633 | C23: =IFERROR(INDEX(NV_TEN,MATCH(B23,NV_MA,0)),"MÃ KHÔNG CÓ") -> Nguyễn Quang Thọ | D23: =IFERROR(INDEX(NV_HINHTHUC,MATCH(B23,NV_MA,0)),"") -> Khoán | AJ23: =SUM(E23:AI23) -> 0 | AK23: =IF(AJ23=0,0,AJ23/GIO_CONG) -> 0
A24: 19 | B24: 046074013724 | C24: =IFERROR(INDEX(NV_TEN,MATCH(B24,NV_MA,0)),"MÃ KHÔNG CÓ") -> Nguyễn Ngọc Phương | D24: =IFERROR(INDEX(NV_HINHTHUC,MATCH(B24,NV_MA,0)),"") -> Khoán | G24: 8 | I24: 8 | O24: 8 | P24: 12 | Q24: 8 | R24: 12 | Z24: 12 | AA24: 16 | AB24: 12 | AC24: 4 | AD24: 12 | AE24: 8 | AF24: 4 | AG24: 8 | AJ24: =SUM(E24:AI24) -> 132 | AK24: =IF(AJ24=0,0,AJ24/GIO_CONG) -> 16.5
A25: 20 | B25: 046099007864 | C25: =IFERROR(INDEX(NV_TEN,MATCH(B25,NV_MA,0)),"MÃ KHÔNG CÓ") -> Lê Lộc | D25: =IFERROR(INDEX(NV_HINHTHUC,MATCH(B25,NV_MA,0)),"") -> Khoán | AJ25: =SUM(E25:AI25) -> 0 | AK25: =IF(AJ25=0,0,AJ25/GIO_CONG) -> 0
A26: 21 | B26: 002191001272 | C26: =IFERROR(INDEX(NV_TEN,MATCH(B26,NV_MA,0)),"MÃ KHÔNG CÓ") -> Thèn Thị Giang | D26: =IFERROR(INDEX(NV_HINHTHUC,MATCH(B26,NV_MA,0)),"") -> Khoán | AJ26: =SUM(E26:AI26) -> 0 | AK26: =IF(AJ26=0,0,AJ26/GIO_CONG) -> 0
A27: 22 | B27: 046087002473 | C27: =IFERROR(INDEX(NV_TEN,MATCH(B27,NV_MA,0)),"MÃ KHÔNG CÓ") -> Nguyễn Tình | D27: =IFERROR(INDEX(NV_HINHTHUC,MATCH(B27,NV_MA,0)),"") -> Khoán | AJ27: =SUM(E27:AI27) -> 0 | AK27: =IF(AJ27=0,0,AJ27/GIO_CONG) -> 0
A28: 23 | B28: 046178010147 | C28: =IFERROR(INDEX(NV_TEN,MATCH(B28,NV_MA,0)),"MÃ KHÔNG CÓ") -> Đặng Thị Huế | D28: =IFERROR(INDEX(NV_HINHTHUC,MATCH(B28,NV_MA,0)),"") -> Khoán | AJ28: =SUM(E28:AI28) -> 0 | AK28: =IF(AJ28=0,0,AJ28/GIO_CONG) -> 0
A29: 24 | B29: 046089009803 | C29: =IFERROR(INDEX(NV_TEN,MATCH(B29,NV_MA,0)),"MÃ KHÔNG CÓ") -> Trần Văn Trình | D29: =IFERROR(INDEX(NV_HINHTHUC,MATCH(B29,NV_MA,0)),"") -> Khoán | AJ29: =SUM(E29:AI29) -> 0 | AK29: =IF(AJ29=0,0,AJ29/GIO_CONG) -> 0
A30: 25 | B30: 046084009142 | C30: =IFERROR(INDEX(NV_TEN,MATCH(B30,NV_MA,0)),"MÃ KHÔNG CÓ") -> Trần Văn Hiền | D30: =IFERROR(INDEX(NV_HINHTHUC,MATCH(B30,NV_MA,0)),"") -> Khoán | AJ30: =SUM(E30:AI30) -> 0 | AK30: =IF(AJ30=0,0,AJ30/GIO_CONG) -> 0
A31: 26 | B31: 046207415351 | C31: =IFERROR(INDEX(NV_TEN,MATCH(B31,NV_MA,0)),"MÃ KHÔNG CÓ") -> Trần Văn Tâm | D31: =IFERROR(INDEX(NV_HINHTHUC,MATCH(B31,NV_MA,0)),"") -> Khoán | G31: 8 | I31: 8 | O31: 8 | P31: 12 | Q31: 8 | R31: 12 | Z31: 3 | AA31: 16 | AB31: 12 | AC31: 4 | AD31: 12 | AE31: 8 | AF31: 4 | AG31: 8 | AJ31: =SUM(E31:AI31) -> 123 | AK31: =IF(AJ31=0,0,AJ31/GIO_CONG) -> 15.375
A32: 27 | B32: NV_DINHHAI | C32: =IFERROR(INDEX(NV_TEN,MATCH(B32,NV_MA,0)),"MÃ KHÔNG CÓ") -> Trần Đình Hải | D32: =IFERROR(INDEX(NV_HINHTHUC,MATCH(B32,NV_MA,0)),"") -> Khoán | AJ32: =SUM(E32:AI32) -> 0 | AK32: =IF(AJ32=0,0,AJ32/GIO_CONG) -> 0
A33: 28 | B33: 046064009756 | C33: =IFERROR(INDEX(NV_TEN,MATCH(B33,NV_MA,0)),"MÃ KHÔNG CÓ") -> Hoàng Lự | D33: =IFERROR(INDEX(NV_HINHTHUC,MATCH(B33,NV_MA,0)),"") -> Khoán | AJ33: =SUM(E33:AI33) -> 0 | AK33: =IF(AJ33=0,0,AJ33/GIO_CONG) -> 0
A34: 29 | B34: 046172013307 | C34: =IFERROR(INDEX(NV_TEN,MATCH(B34,NV_MA,0)),"MÃ KHÔNG CÓ") -> Ngô Thị Thủy | D34: =IFERROR(INDEX(NV_HINHTHUC,MATCH(B34,NV_MA,0)),"") -> Khoán | AJ34: =SUM(E34:AI34) -> 0 | AK34: =IF(AJ34=0,0,AJ34/GIO_CONG) -> 0
A35: 30 | B35: 046165007228 | C35: =IFERROR(INDEX(NV_TEN,MATCH(B35,NV_MA,0)),"MÃ KHÔNG CÓ") -> Lê Thị Hương | D35: =IFERROR(INDEX(NV_HINHTHUC,MATCH(B35,NV_MA,0)),"") -> Khoán | AJ35: =SUM(E35:AI35) -> 0 | AK35: =IF(AJ35=0,0,AJ35/GIO_CONG) -> 0
A36: 31 | B36: 046181009164 | C36: =IFERROR(INDEX(NV_TEN,MATCH(B36,NV_MA,0)),"MÃ KHÔNG CÓ") -> Hoàng Thị Nhung | D36: =IFERROR(INDEX(NV_HINHTHUC,MATCH(B36,NV_MA,0)),"") -> Khoán | AJ36: =SUM(E36:AI36) -> 0 | AK36: =IF(AJ36=0,0,AJ36/GIO_CONG) -> 0
A37: 32 | B37: 046173005614 | C37: =IFERROR(INDEX(NV_TEN,MATCH(B37,NV_MA,0)),"MÃ KHÔNG CÓ") -> Trần Thị Thu Thủy | D37: =IFERROR(INDEX(NV_HINHTHUC,MATCH(B37,NV_MA,0)),"") -> Khoán | AJ37: =SUM(E37:AI37) -> 0 | AK37: =IF(AJ37=0,0,AJ37/GIO_CONG) -> 0
A38: 33 | B38: 046180005626 | C38: =IFERROR(INDEX(NV_TEN,MATCH(B38,NV_MA,0)),"MÃ KHÔNG CÓ") -> Trần Thị Cẩm Hà | D38: =IFERROR(INDEX(NV_HINHTHUC,MATCH(B38,NV_MA,0)),"") -> Khoán | AJ38: =SUM(E38:AI38) -> 0 | AK38: =IF(AJ38=0,0,AJ38/GIO_CONG) -> 0
A39: 34 | B39: 046177004568 | C39: =IFERROR(INDEX(NV_TEN,MATCH(B39,NV_MA,0)),"MÃ KHÔNG CÓ") -> Nguyễn Thị Kim Tin | D39: =IFERROR(INDEX(NV_HINHTHUC,MATCH(B39,NV_MA,0)),"") -> Khoán | AJ39: =SUM(E39:AI39) -> 0 | AK39: =IF(AJ39=0,0,AJ39/GIO_CONG) -> 0
A40: 35 | B40: 046176012968 | C40: =IFERROR(INDEX(NV_TEN,MATCH(B40,NV_MA,0)),"MÃ KHÔNG CÓ") -> Nguyễn Thị Loan | D40: =IFERROR(INDEX(NV_HINHTHUC,MATCH(B40,NV_MA,0)),"") -> Khoán | AJ40: =SUM(E40:AI40) -> 0 | AK40: =IF(AJ40=0,0,AJ40/GIO_CONG) -> 0
A41: 36 | B41: 046183006914 | C41: =IFERROR(INDEX(NV_TEN,MATCH(B41,NV_MA,0)),"MÃ KHÔNG CÓ") -> Nguyễn Thị Thu Hà | D41: =IFERROR(INDEX(NV_HINHTHUC,MATCH(B41,NV_MA,0)),"") -> Khoán | AJ41: =SUM(E41:AI41) -> 0 | AK41: =IF(AJ41=0,0,AJ41/GIO_CONG) -> 0
A42: 37 | B42: 046077008985 | C42: =IFERROR(INDEX(NV_TEN,MATCH(B42,NV_MA,0)),"MÃ KHÔNG CÓ") -> Ngô Văn Đính | D42: =IFERROR(INDEX(NV_HINHTHUC,MATCH(B42,NV_MA,0)),"") -> Khoán | AJ42: =SUM(E42:AI42) -> 0 | AK42: =IF(AJ42=0,0,AJ42/GIO_CONG) -> 0
A43: 38 | B43: 046180009217 | C43: =IFERROR(INDEX(NV_TEN,MATCH(B43,NV_MA,0)),"MÃ KHÔNG CÓ") -> Ngô Thị Quý | D43: =IFERROR(INDEX(NV_HINHTHUC,MATCH(B43,NV_MA,0)),"") -> Khoán | AJ43: =SUM(E43:AI43) -> 0 | AK43: =IF(AJ43=0,0,AJ43/GIO_CONG) -> 0
... A47: 42 | B47: 046095008572 | C47: =IFERROR(INDEX(NV_TEN,MATCH(B47,NV_MA,0)),"MÃ KHÔNG CÓ") -> Trần Văn Tấn | D47: =IFERROR(INDEX(NV_HINHTHUC,MATCH(B47,NV_MA,0)),"") -> Khoán | AJ47: =SUM(E47:AI47) -> 0 | AK47: =IF(AJ47=0,0,AJ47/GIO_CONG) -> 0
A48: 43 | B48: 045200002742 | C48: =IFERROR(INDEX(NV_TEN,MATCH(B48,NV_MA,0)),"MÃ KHÔNG CÓ") -> Hoàng Văn Anh | D48: =IFERROR(INDEX(NV_HINHTHUC,MATCH(B48,NV_MA,0)),"") -> Khoán | E48: 8 | F48: 8 | G48: 8 | H48: 8 | I48: 8 | J48: 8 | K48: 8 | L48: 8 | M48: 8 | N48: 8 | O48: 8 | P48: 8 | Q48: 8 | R48: 8 | S48: 8 | T48: 8 | U48: 8 | V48: 8 | W48: 8 | X48: 8 | Y48: 8 | Z48: 8 | AA48: 8 | AB48: 8 | AC48: 8 | AJ48: =SUM(E48:AI48) -> 200 | AK48: =IF(AJ48=0,0,AJ48/GIO_CONG) -> 25
...

Sheet LUONG_KHOAN
A1: BẢNG TÍNH LƯƠNG KHOÁN SẢN XUẤT
A2: Toàn bộ là công thức. Cột Q, R, S (nền xanh) là số đưa sang Bảng lương. Cột tham chiếu sheet cũ ghi ở dòng 5.
A4: STT | B4: Mã NV | C4: Họ và tên | D4: Hình thức | E4: Hệ số | F4: Đơn giá khoán (đ/tấn) | G4: Tổng giờ công | H4: Ngày công | I4: Tấn quy đổi/người | J4: Lương khoán SP | K4: Lương hàng hanging | L4: CV khác chia chung | M4: CV khác đích danh | N4: Lương hàng chèn | O4: Phân bổ trừ lương công nhật | P4: Lương công nhật | Q4: TỔNG LƯƠNG KHOÁN (→ Bảng lương) | R4: TIỀN ĂN SAU KHOÁN (→ Bảng lương) | S4: TỔNG CỘNG | T4: Ghi chú
B5: Cũ: B | C5: Cũ: C | E5: Cũ: AL | F5: Cũ: AM | G5: Cũ: AN | H5: Cũ: AT | I5: Cũ: AO | J5: Cũ: AP (phần 1) | K5: Cũ: AP (phần 2) | L5: Cũ: AQ | M5: Cũ: AQ (+100k/200k) | N5: Cũ: AR | O5: Cũ: AS (−AL14/W3×giờ) | P5: Cũ: AL bảng công nhật | Q5: Cũ: AS | R5: Cũ: AU | S5: Cũ: X Bảng lương
A6: =IF(B6="","",1) -> 1 | B6: =IF(BCC_KHOAN!B6="","",BCC_KHOAN!B6) -> 046085007061 | C6: =IF(B6="","",IFERROR(INDEX(NV_TEN,MATCH(B6,NV_MA,0)),"MÃ KHÔNG CÓ")) -> Lê Vang | D6: =IF(B6="","",IFERROR(INDEX(NV_HINHTHUC,MATCH(B6,NV_MA,0)),"")) -> Khoán | E6: =IF(D6="Khoán",IFERROR(INDEX(NV_HESO,MATCH(B6,NV_MA,0)),0),"") -> 1.5 | F6: =IF(D6="Khoán",IFERROR(INDEX(HS_SX!$B$5:$B$30,MATCH(E6,HS_SX!$A$5:$A$30,0)),0),"") -> 9600 | G6: =IF(B6="","",IFERROR(INDEX(BCC_GIO,MATCH(B6,BCC_MA,0)),0)) -> 0 | H6: =IF(B6="","",G6/GIO_CONG) -> 0 | I6: =IF(D6="Khoán",IF(GIO_TB>0,G6/GIO_TB*KL_CHEBIEN,0),0) -> 0 | J6: =IF(D6="Khoán",F6*I6,0) -> 0 | K6: =IF(D6="Khoán",IF(TONG_GIO_KHOAN>0,QUY_HANGING/TONG_GIO_KHOAN*G6,0),0) -> 0 | L6: =IF(D6="Khoán",IF(TONG_GIO_KHOAN>0,QUY_KHAC/TONG_GIO_KHOAN*G6,0),0) -> 0 | M6: =IF(B6="",0,SUMIFS(KHOAN_KHAC!$F$5:$F$39,KHOAN_KHAC!$G$5:$G$39,B6)) -> 100000 | N6: =IF(D6="Khoán",IF(TONG_GIO_KHOAN>0,QUY_CHEN/TONG_GIO_KHOAN*G6,0),0) -> 0 | O6: =IF(D6="Khoán",IF(TONG_GIO_KHOAN>0,-TONG_CONGNHAT/TONG_GIO_KHOAN*G6,0),0) -> 0 | P6: =IF(D6="Công nhật",H6*IFERROR(IF(INDEX(NV_DGCN,MATCH(B6,NV_MA,0))="",DG_CONGNHAT,INDEX(NV_DGCN,MATCH(B6,NV_MA,0))),DG_CONGNHAT),0) -> 0 | Q6: =IF(B6="","",IF(D6="Khoán",ROUNDDOWN(J6+K6+L6+M6+N6+O6,-3),P6+M6)) -> 100000 | R6: =IF(B6="","",ROUNDDOWN(TIENAN_CONG*H6,-3)) -> 0 | S6: =IF(B6="","",Q6+R6) -> 100000
A7: =IF(B7="","",2) -> 2 | B7: =IF(BCC_KHOAN!B7="","",BCC_KHOAN!B7) -> 046077003925 | C7: =IF(B7="","",IFERROR(INDEX(NV_TEN,MATCH(B7,NV_MA,0)),"MÃ KHÔNG CÓ")) -> Trần Đình Mạnh | D7: =IF(B7="","",IFERROR(INDEX(NV_HINHTHUC,MATCH(B7,NV_MA,0)),"")) -> Khoán | E7: =IF(D7="Khoán",IFERROR(INDEX(NV_HESO,MATCH(B7,NV_MA,0)),0),"") -> 1.35 | F7: =IF(D7="Khoán",IFERROR(INDEX(HS_SX!$B$5:$B$30,MATCH(E7,HS_SX!$A$5:$A$30,0)),0),"") -> 8600 | G7: =IF(B7="","",IFERROR(INDEX(BCC_GIO,MATCH(B7,BCC_MA,0)),0)) -> 0 | H7: =IF(B7="","",G7/GIO_CONG) -> 0 | I7: =IF(D7="Khoán",IF(GIO_TB>0,G7/GIO_TB*KL_CHEBIEN,0),0) -> 0 | J7: =IF(D7="Khoán",F7*I7,0) -> 0 | K7: =IF(D7="Khoán",IF(TONG_GIO_KHOAN>0,QUY_HANGING/TONG_GIO_KHOAN*G7,0),0) -> 0 | L7: =IF(D7="Khoán",IF(TONG_GIO_KHOAN>0,QUY_KHAC/TONG_GIO_KHOAN*G7,0),0) -> 0 | M7: =IF(B7="",0,SUMIFS(KHOAN_KHAC!$F$5:$F$39,KHOAN_KHAC!$G$5:$G$39,B7)) -> 0 | N7: =IF(D7="Khoán",IF(TONG_GIO_KHOAN>0,QUY_CHEN/TONG_GIO_KHOAN*G7,0),0) -> 0 | O7: =IF(D7="Khoán",IF(TONG_GIO_KHOAN>0,-TONG_CONGNHAT/TONG_GIO_KHOAN*G7,0),0) -> 0 | P7: =IF(D7="Công nhật",H7*IFERROR(IF(INDEX(NV_DGCN,MATCH(B7,NV_MA,0))="",DG_CONGNHAT,INDEX(NV_DGCN,MATCH(B7,NV_MA,0))),DG_CONGNHAT),0) -> 0 | Q7: =IF(B7="","",IF(D7="Khoán",ROUNDDOWN(J7+K7+L7+M7+N7+O7,-3),P7+M7)) -> 0 | R7: =IF(B7="","",ROUNDDOWN(TIENAN_CONG*H7,-3)) -> 0 | S7: =IF(B7="","",Q7+R7) -> 0
A8: =IF(B8="","",3) -> 3 | B8: =IF(BCC_KHOAN!B8="","",BCC_KHOAN!B8) -> 046177012486 | C8: =IF(B8="","",IFERROR(INDEX(NV_TEN,MATCH(B8,NV_MA,0)),"MÃ KHÔNG CÓ")) -> Lê Thị Bình | D8: =IF(B8="","",IFERROR(INDEX(NV_HINHTHUC,MATCH(B8,NV_MA,0)),"")) -> Khoán | E8: =IF(D8="Khoán",IFERROR(INDEX(NV_HESO,MATCH(B8,NV_MA,0)),0),"") -> 1.1 | F8: =IF(D8="Khoán",IFERROR(INDEX(HS_SX!$B$5:$B$30,MATCH(E8,HS_SX!$A$5:$A$30,0)),0),"") -> 7100 | G8: =IF(B8="","",IFERROR(INDEX(BCC_GIO,MATCH(B8,BCC_MA,0)),0)) -> 0 | H8: =IF(B8="","",G8/GIO_CONG) -> 0 | I8: =IF(D8="Khoán",IF(GIO_TB>0,G8/GIO_TB*KL_CHEBIEN,0),0) -> 0 | J8: =IF(D8="Khoán",F8*I8,0) -> 0 | K8: =IF(D8="Khoán",IF(TONG_GIO_KHOAN>0,QUY_HANGING/TONG_GIO_KHOAN*G8,0),0) -> 0 | L8: =IF(D8="Khoán",IF(TONG_GIO_KHOAN>0,QUY_KHAC/TONG_GIO_KHOAN*G8,0),0) -> 0 | M8: =IF(B8="",0,SUMIFS(KHOAN_KHAC!$F$5:$F$39,KHOAN_KHAC!$G$5:$G$39,B8)) -> 0 | N8: =IF(D8="Khoán",IF(TONG_GIO_KHOAN>0,QUY_CHEN/TONG_GIO_KHOAN*G8,0),0) -> 0 | O8: =IF(D8="Khoán",IF(TONG_GIO_KHOAN>0,-TONG_CONGNHAT/TONG_GIO_KHOAN*G8,0),0) -> 0 | P8: =IF(D8="Công nhật",H8*IFERROR(IF(INDEX(NV_DGCN,MATCH(B8,NV_MA,0))="",DG_CONGNHAT,INDEX(NV_DGCN,MATCH(B8,NV_MA,0))),DG_CONGNHAT),0) -> 0 | Q8: =IF(B8="","",IF(D8="Khoán",ROUNDDOWN(J8+K8+L8+M8+N8+O8,-3),P8+M8)) -> 0 | R8: =IF(B8="","",ROUNDDOWN(TIENAN_CONG*H8,-3)) -> 0 | S8: =IF(B8="","",Q8+R8) -> 0
A9: =IF(B9="","",4) -> 4 | B9: =IF(BCC_KHOAN!B9="","",BCC_KHOAN!B9) -> 046179008435 | C9: =IF(B9="","",IFERROR(INDEX(NV_TEN,MATCH(B9,NV_MA,0)),"MÃ KHÔNG CÓ")) -> Trần Thị Tích | D9: =IF(B9="","",IFERROR(INDEX(NV_HINHTHUC,MATCH(B9,NV_MA,0)),"")) -> Khoán | E9: =IF(D9="Khoán",IFERROR(INDEX(NV_HESO,MATCH(B9,NV_MA,0)),0),"") -> 1.15 | F9: =IF(D9="Khoán",IFERROR(INDEX(HS_SX!$B$5:$B$30,MATCH(E9,HS_SX!$A$5:$A$30,0)),0),"") -> 7400 | G9: =IF(B9="","",IFERROR(INDEX(BCC_GIO,MATCH(B9,BCC_MA,0)),0)) -> 0 | H9: =IF(B9="","",G9/GIO_CONG) -> 0 | I9: =IF(D9="Khoán",IF(GIO_TB>0,G9/GIO_TB*KL_CHEBIEN,0),0) -> 0 | J9: =IF(D9="Khoán",F9*I9,0) -> 0 | K9: =IF(D9="Khoán",IF(TONG_GIO_KHOAN>0,QUY_HANGING/TONG_GIO_KHOAN*G9,0),0) -> 0 | L9: =IF(D9="Khoán",IF(TONG_GIO_KHOAN>0,QUY_KHAC/TONG_GIO_KHOAN*G9,0),0) -> 0 | M9: =IF(B9="",0,SUMIFS(KHOAN_KHAC!$F$5:$F$39,KHOAN_KHAC!$G$5:$G$39,B9)) -> 0 | N9: =IF(D9="Khoán",IF(TONG_GIO_KHOAN>0,QUY_CHEN/TONG_GIO_KHOAN*G9,0),0) -> 0 | O9: =IF(D9="Khoán",IF(TONG_GIO_KHOAN>0,-TONG_CONGNHAT/TONG_GIO_KHOAN*G9,0),0) -> 0 | P9: =IF(D9="Công nhật",H9*IFERROR(IF(INDEX(NV_DGCN,MATCH(B9,NV_MA,0))="",DG_CONGNHAT,INDEX(NV_DGCN,MATCH(B9,NV_MA,0))),DG_CONGNHAT),0) -> 0 | Q9: =IF(B9="","",IF(D9="Khoán",ROUNDDOWN(J9+K9+L9+M9+N9+O9,-3),P9+M9)) -> 0 | R9: =IF(B9="","",ROUNDDOWN(TIENAN_CONG*H9,-3)) -> 0 | S9: =IF(B9="","",Q9+R9) -> 0
A10: =IF(B10="","",5) -> 5 | B10: =IF(BCC_KHOAN!B10="","",BCC_KHOAN!B10) -> 046175005132 | C10: =IF(B10="","",IFERROR(INDEX(NV_TEN,MATCH(B10,NV_MA,0)),"MÃ KHÔNG CÓ")) -> Lê Thị Nga | D10: =IF(B10="","",IFERROR(INDEX(NV_HINHTHUC,MATCH(B10,NV_MA,0)),"")) -> Khoán | E10: =IF(D10="Khoán",IFERROR(INDEX(NV_HESO,MATCH(B10,NV_MA,0)),0),"") -> 1.15 | F10: =IF(D10="Khoán",IFERROR(INDEX(HS_SX!$B$5:$B$30,MATCH(E10,HS_SX!$A$5:$A$30,0)),0),"") -> 7400 | G10: =IF(B10="","",IFERROR(INDEX(BCC_GIO,MATCH(B10,BCC_MA,0)),0)) -> 0 | H10: =IF(B10="","",G10/GIO_CONG) -> 0 | I10: =IF(D10="Khoán",IF(GIO_TB>0,G10/GIO_TB*KL_CHEBIEN,0),0) -> 0 | J10: =IF(D10="Khoán",F10*I10,0) -> 0 | K10: =IF(D10="Khoán",IF(TONG_GIO_KHOAN>0,QUY_HANGING/TONG_GIO_KHOAN*G10,0),0) -> 0 | L10: =IF(D10="Khoán",IF(TONG_GIO_KHOAN>0,QUY_KHAC/TONG_GIO_KHOAN*G10,0),0) -> 0 | M10: =IF(B10="",0,SUMIFS(KHOAN_KHAC!$F$5:$F$39,KHOAN_KHAC!$G$5:$G$39,B10)) -> 0 | N10: =IF(D10="Khoán",IF(TONG_GIO_KHOAN>0,QUY_CHEN/TONG_GIO_KHOAN*G10,0),0) -> 0 | O10: =IF(D10="Khoán",IF(TONG_GIO_KHOAN>0,-TONG_CONGNHAT/TONG_GIO_KHOAN*G10,0),0) -> 0 | P10: =IF(D10="Công nhật",H10*IFERROR(IF(INDEX(NV_DGCN,MATCH(B10,NV_MA,0))="",DG_CONGNHAT,INDEX(NV_DGCN,MATCH(B10,NV_MA,0))),DG_CONGNHAT),0) -> 0 | Q10: =IF(B10="","",IF(D10="Khoán",ROUNDDOWN(J10+K10+L10+M10+N10+O10,-3),P10+M10)) -> 0 | R10: =IF(B10="","",ROUNDDOWN(TIENAN_CONG*H10,-3)) -> 0 | S10: =IF(B10="","",Q10+R10) -> 0
A11: =IF(B11="","",6) -> 6 | B11: =IF(BCC_KHOAN!B11="","",BCC_KHOAN!B11) -> 046090006706 | C11: =IF(B11="","",IFERROR(INDEX(NV_TEN,MATCH(B11,NV_MA,0)),"MÃ KHÔNG CÓ")) -> Phạm Bá Lượng | D11: =IF(B11="","",IFERROR(INDEX(NV_HINHTHUC,MATCH(B11,NV_MA,0)),"")) -> Khoán | E11: =IF(D11="Khoán",IFERROR(INDEX(NV_HESO,MATCH(B11,NV_MA,0)),0),"") -> 1.3 | F11: =IF(D11="Khoán",IFERROR(INDEX(HS_SX!$B$5:$B$30,MATCH(E11,HS_SX!$A$5:$A$30,0)),0),"") -> 8300 | G11: =IF(B11="","",IFERROR(INDEX(BCC_GIO,MATCH(B11,BCC_MA,0)),0)) -> 0 | H11: =IF(B11="","",G11/GIO_CONG) -> 0 | I11: =IF(D11="Khoán",IF(GIO_TB>0,G11/GIO_TB*KL_CHEBIEN,0),0) -> 0 | J11: =IF(D11="Khoán",F11*I11,0) -> 0 | K11: =IF(D11="Khoán",IF(TONG_GIO_KHOAN>0,QUY_HANGING/TONG_GIO_KHOAN*G11,0),0) -> 0 | L11: =IF(D11="Khoán",IF(TONG_GIO_KHOAN>0,QUY_KHAC/TONG_GIO_KHOAN*G11,0),0) -> 0 | M11: =IF(B11="",0,SUMIFS(KHOAN_KHAC!$F$5:$F$39,KHOAN_KHAC!$G$5:$G$39,B11)) -> 100000 | N11: =IF(D11="Khoán",IF(TONG_GIO_KHOAN>0,QUY_CHEN/TONG_GIO_KHOAN*G11,0),0) -> 0 | O11: =IF(D11="Khoán",IF(TONG_GIO_KHOAN>0,-TONG_CONGNHAT/TONG_GIO_KHOAN*G11,0),0) -> 0 | P11: =IF(D11="Công nhật",H11*IFERROR(IF(INDEX(NV_DGCN,MATCH(B11,NV_MA,0))="",DG_CONGNHAT,INDEX(NV_DGCN,MATCH(B11,NV_MA,0))),DG_CONGNHAT),0) -> 0 | Q11: =IF(B11="","",IF(D11="Khoán",ROUNDDOWN(J11+K11+L11+M11+N11+O11,-3),P11+M11)) -> 100000 | R11: =IF(B11="","",ROUNDDOWN(TIENAN_CONG*H11,-3)) -> 0 | S11: =IF(B11="","",Q11+R11) -> 100000
A12: =IF(B12="","",7) -> 7 | B12: =IF(BCC_KHOAN!B12="","",BCC_KHOAN!B12) -> 046178011746 | C12: =IF(B12="","",IFERROR(INDEX(NV_TEN,MATCH(B12,NV_MA,0)),"MÃ KHÔNG CÓ")) -> Văn Thị Vinh | D12: =IF(B12="","",IFERROR(INDEX(NV_HINHTHUC,MATCH(B12,NV_MA,0)),"")) -> Khoán | E12: =IF(D12="Khoán",IFERROR(INDEX(NV_HESO,MATCH(B12,NV_MA,0)),0),"") -> 1.1 | F12: =IF(D12="Khoán",IFERROR(INDEX(HS_SX!$B$5:$B$30,MATCH(E12,HS_SX!$A$5:$A$30,0)),0),"") -> 7100 | G12: =IF(B12="","",IFERROR(INDEX(BCC_GIO,MATCH(B12,BCC_MA,0)),0)) -> 0 | H12: =IF(B12="","",G12/GIO_CONG) -> 0 | I12: =IF(D12="Khoán",IF(GIO_TB>0,G12/GIO_TB*KL_CHEBIEN,0),0) -> 0 | J12: =IF(D12="Khoán",F12*I12,0) -> 0 | K12: =IF(D12="Khoán",IF(TONG_GIO_KHOAN>0,QUY_HANGING/TONG_GIO_KHOAN*G12,0),0) -> 0 | L12: =IF(D12="Khoán",IF(TONG_GIO_KHOAN>0,QUY_KHAC/TONG_GIO_KHOAN*G12,0),0) -> 0 | M12: =IF(B12="",0,SUMIFS(KHOAN_KHAC!$F$5:$F$39,KHOAN_KHAC!$G$5:$G$39,B12)) -> 0 | N12: =IF(D12="Khoán",IF(TONG_GIO_KHOAN>0,QUY_CHEN/TONG_GIO_KHOAN*G12,0),0) -> 0 | O12: =IF(D12="Khoán",IF(TONG_GIO_KHOAN>0,-TONG_CONGNHAT/TONG_GIO_KHOAN*G12,0),0) -> 0 | P12: =IF(D12="Công nhật",H12*IFERROR(IF(INDEX(NV_DGCN,MATCH(B12,NV_MA,0))="",DG_CONGNHAT,INDEX(NV_DGCN,MATCH(B12,NV_MA,0))),DG_CONGNHAT),0) -> 0 | Q12: =IF(B12="","",IF(D12="Khoán",ROUNDDOWN(J12+K12+L12+M12+N12+O12,-3),P12+M12)) -> 0 | R12: =IF(B12="","",ROUNDDOWN(TIENAN_CONG*H12,-3)) -> 0 | S12: =IF(B12="","",Q12+R12) -> 0
A13: =IF(B13="","",8) -> 8 | B13: =IF(BCC_KHOAN!B13="","",BCC_KHOAN!B13) -> 046172008975 | C13: =IF(B13="","",IFERROR(INDEX(NV_TEN,MATCH(B13,NV_MA,0)),"MÃ KHÔNG CÓ")) -> Nguyễn Thị Điệp | D13: =IF(B13="","",IFERROR(INDEX(NV_HINHTHUC,MATCH(B13,NV_MA,0)),"")) -> Khoán | E13: =IF(D13="Khoán",IFERROR(INDEX(NV_HESO,MATCH(B13,NV_MA,0)),0),"") -> 1.1 | F13: =IF(D13="Khoán",IFERROR(INDEX(HS_SX!$B$5:$B$30,MATCH(E13,HS_SX!$A$5:$A$30,0)),0),"") -> 7100 | G13: =IF(B13="","",IFERROR(INDEX(BCC_GIO,MATCH(B13,BCC_MA,0)),0)) -> 0 | H13: =IF(B13="","",G13/GIO_CONG) -> 0 | I13: =IF(D13="Khoán",IF(GIO_TB>0,G13/GIO_TB*KL_CHEBIEN,0),0) -> 0 | J13: =IF(D13="Khoán",F13*I13,0) -> 0 | K13: =IF(D13="Khoán",IF(TONG_GIO_KHOAN>0,QUY_HANGING/TONG_GIO_KHOAN*G13,0),0) -> 0 | L13: =IF(D13="Khoán",IF(TONG_GIO_KHOAN>0,QUY_KHAC/TONG_GIO_KHOAN*G13,0),0) -> 0 | M13: =IF(B13="",0,SUMIFS(KHOAN_KHAC!$F$5:$F$39,KHOAN_KHAC!$G$5:$G$39,B13)) -> 0 | N13: =IF(D13="Khoán",IF(TONG_GIO_KHOAN>0,QUY_CHEN/TONG_GIO_KHOAN*G13,0),0) -> 0 | O13: =IF(D13="Khoán",IF(TONG_GIO_KHOAN>0,-TONG_CONGNHAT/TONG_GIO_KHOAN*G13,0),0) -> 0 | P13: =IF(D13="Công nhật",H13*IFERROR(IF(INDEX(NV_DGCN,MATCH(B13,NV_MA,0))="",DG_CONGNHAT,INDEX(NV_DGCN,MATCH(B13,NV_MA,0))),DG_CONGNHAT),0) -> 0 | Q13: =IF(B13="","",IF(D13="Khoán",ROUNDDOWN(J13+K13+L13+M13+N13+O13,-3),P13+M13)) -> 0 | R13: =IF(B13="","",ROUNDDOWN(TIENAN_CONG*H13,-3)) -> 0 | S13: =IF(B13="","",Q13+R13) -> 0
A14: =IF(B14="","",9) -> 9 | B14: =IF(BCC_KHOAN!B14="","",BCC_KHOAN!B14) -> NV_KIMANH | C14: =IF(B14="","",IFERROR(INDEX(NV_TEN,MATCH(B14,NV_MA,0)),"MÃ KHÔNG CÓ")) -> Lê Thị Kim Anh | D14: =IF(B14="","",IFERROR(INDEX(NV_HINHTHUC,MATCH(B14,NV_MA,0)),"")) -> Khoán | E14: =IF(D14="Khoán",IFERROR(INDEX(NV_HESO,MATCH(B14,NV_MA,0)),0),"") -> 1 | F14: =IF(D14="Khoán",IFERROR(INDEX(HS_SX!$B$5:$B$30,MATCH(E14,HS_SX!$A$5:$A$30,0)),0),"") -> 6400 | G14: =IF(B14="","",IFERROR(INDEX(BCC_GIO,MATCH(B14,BCC_MA,0)),0)) -> 0 | H14: =IF(B14="","",G14/GIO_CONG) -> 0 | I14: =IF(D14="Khoán",IF(GIO_TB>0,G14/GIO_TB*KL_CHEBIEN,0),0) -> 0 | J14: =IF(D14="Khoán",F14*I14,0) -> 0 | K14: =IF(D14="Khoán",IF(TONG_GIO_KHOAN>0,QUY_HANGING/TONG_GIO_KHOAN*G14,0),0) -> 0 | L14: =IF(D14="Khoán",IF(TONG_GIO_KHOAN>0,QUY_KHAC/TONG_GIO_KHOAN*G14,0),0) -> 0 | M14: =IF(B14="",0,SUMIFS(KHOAN_KHAC!$F$5:$F$39,KHOAN_KHAC!$G$5:$G$39,B14)) -> 0 | N14: =IF(D14="Khoán",IF(TONG_GIO_KHOAN>0,QUY_CHEN/TONG_GIO_KHOAN*G14,0),0) -> 0 | O14: =IF(D14="Khoán",IF(TONG_GIO_KHOAN>0,-TONG_CONGNHAT/TONG_GIO_KHOAN*G14,0),0) -> 0 | P14: =IF(D14="Công nhật",H14*IFERROR(IF(INDEX(NV_DGCN,MATCH(B14,NV_MA,0))="",DG_CONGNHAT,INDEX(NV_DGCN,MATCH(B14,NV_MA,0))),DG_CONGNHAT),0) -> 0 | Q14: =IF(B14="","",IF(D14="Khoán",ROUNDDOWN(J14+K14+L14+M14+N14+O14,-3),P14+M14)) -> 0 | R14: =IF(B14="","",ROUNDDOWN(TIENAN_CONG*H14,-3)) -> 0 | S14: =IF(B14="","",Q14+R14) -> 0
A15: =IF(B15="","",10) -> 10 | B15: =IF(BCC_KHOAN!B15="","",BCC_KHOAN!B15) -> 046074011254 | C15: =IF(B15="","",IFERROR(INDEX(NV_TEN,MATCH(B15,NV_MA,0)),"MÃ KHÔNG CÓ")) -> Trần Đức Phúc | D15: =IF(B15="","",IFERROR(INDEX(NV_HINHTHUC,MATCH(B15,NV_MA,0)),"")) -> Khoán | E15: =IF(D15="Khoán",IFERROR(INDEX(NV_HESO,MATCH(B15,NV_MA,0)),0),"") -> 1.1 | F15: =IF(D15="Khoán",IFERROR(INDEX(HS_SX!$B$5:$B$30,MATCH(E15,HS_SX!$A$5:$A$30,0)),0),"") -> 7100 | G15: =IF(B15="","",IFERROR(INDEX(BCC_GIO,MATCH(B15,BCC_MA,0)),0)) -> 0 | H15: =IF(B15="","",G15/GIO_CONG) -> 0 | I15: =IF(D15="Khoán",IF(GIO_TB>0,G15/GIO_TB*KL_CHEBIEN,0),0) -> 0 | J15: =IF(D15="Khoán",F15*I15,0) -> 0 | K15: =IF(D15="Khoán",IF(TONG_GIO_KHOAN>0,QUY_HANGING/TONG_GIO_KHOAN*G15,0),0) -> 0 | L15: =IF(D15="Khoán",IF(TONG_GIO_KHOAN>0,QUY_KHAC/TONG_GIO_KHOAN*G15,0),0) -> 0 | M15: =IF(B15="",0,SUMIFS(KHOAN_KHAC!$F$5:$F$39,KHOAN_KHAC!$G$5:$G$39,B15)) -> 0 | N15: =IF(D15="Khoán",IF(TONG_GIO_KHOAN>0,QUY_CHEN/TONG_GIO_KHOAN*G15,0),0) -> 0 | O15: =IF(D15="Khoán",IF(TONG_GIO_KHOAN>0,-TONG_CONGNHAT/TONG_GIO_KHOAN*G15,0),0) -> 0 | P15: =IF(D15="Công nhật",H15*IFERROR(IF(INDEX(NV_DGCN,MATCH(B15,NV_MA,0))="",DG_CONGNHAT,INDEX(NV_DGCN,MATCH(B15,NV_MA,0))),DG_CONGNHAT),0) -> 0 | Q15: =IF(B15="","",IF(D15="Khoán",ROUNDDOWN(J15+K15+L15+M15+N15+O15,-3),P15+M15)) -> 0 | R15: =IF(B15="","",ROUNDDOWN(TIENAN_CONG*H15,-3)) -> 0 | S15: =IF(B15="","",Q15+R15) -> 0
A16: =IF(B16="","",11) -> 11 | B16: =IF(BCC_KHOAN!B16="","",BCC_KHOAN!B16) -> 046172013837 | C16: =IF(B16="","",IFERROR(INDEX(NV_TEN,MATCH(B16,NV_MA,0)),"MÃ KHÔNG CÓ")) -> Nguyễn Thị Nhung | D16: =IF(B16="","",IFERROR(INDEX(NV_HINHTHUC,MATCH(B16,NV_MA,0)),"")) -> Khoán | E16: =IF(D16="Khoán",IFERROR(INDEX(NV_HESO,MATCH(B16,NV_MA,0)),0),"") -> 0.9 | F16: =IF(D16="Khoán",IFERROR(INDEX(HS_SX!$B$5:$B$30,MATCH(E16,HS_SX!$A$5:$A$30,0)),0),"") -> 5800 | G16: =IF(B16="","",IFERROR(INDEX(BCC_GIO,MATCH(B16,BCC_MA,0)),0)) -> 0 | H16: =IF(B16="","",G16/GIO_CONG) -> 0 | I16: =IF(D16="Khoán",IF(GIO_TB>0,G16/GIO_TB*KL_CHEBIEN,0),0) -> 0 | J16: =IF(D16="Khoán",F16*I16,0) -> 0 | K16: =IF(D16="Khoán",IF(TONG_GIO_KHOAN>0,QUY_HANGING/TONG_GIO_KHOAN*G16,0),0) -> 0 | L16: =IF(D16="Khoán",IF(TONG_GIO_KHOAN>0,QUY_KHAC/TONG_GIO_KHOAN*G16,0),0) -> 0 | M16: =IF(B16="",0,SUMIFS(KHOAN_KHAC!$F$5:$F$39,KHOAN_KHAC!$G$5:$G$39,B16)) -> 0 | N16: =IF(D16="Khoán",IF(TONG_GIO_KHOAN>0,QUY_CHEN/TONG_GIO_KHOAN*G16,0),0) -> 0 | O16: =IF(D16="Khoán",IF(TONG_GIO_KHOAN>0,-TONG_CONGNHAT/TONG_GIO_KHOAN*G16,0),0) -> 0 | P16: =IF(D16="Công nhật",H16*IFERROR(IF(INDEX(NV_DGCN,MATCH(B16,NV_MA,0))="",DG_CONGNHAT,INDEX(NV_DGCN,MATCH(B16,NV_MA,0))),DG_CONGNHAT),0) -> 0 | Q16: =IF(B16="","",IF(D16="Khoán",ROUNDDOWN(J16+K16+L16+M16+N16+O16,-3),P16+M16)) -> 0 | R16: =IF(B16="","",ROUNDDOWN(TIENAN_CONG*H16,-3)) -> 0 | S16: =IF(B16="","",Q16+R16) -> 0
A17: =IF(B17="","",12) -> 12 | B17: =IF(BCC_KHOAN!B17="","",BCC_KHOAN!B17) -> 046175008129 | C17: =IF(B17="","",IFERROR(INDEX(NV_TEN,MATCH(B17,NV_MA,0)),"MÃ KHÔNG CÓ")) -> Lê Thị Thu Hữu | D17: =IF(B17="","",IFERROR(INDEX(NV_HINHTHUC,MATCH(B17,NV_MA,0)),"")) -> Khoán | E17: =IF(D17="Khoán",IFERROR(INDEX(NV_HESO,MATCH(B17,NV_MA,0)),0),"") -> 1.1 | F17: =IF(D17="Khoán",IFERROR(INDEX(HS_SX!$B$5:$B$30,MATCH(E17,HS_SX!$A$5:$A$30,0)),0),"") -> 7100 | G17: =IF(B17="","",IFERROR(INDEX(BCC_GIO,MATCH(B17,BCC_MA,0)),0)) -> 0 | H17: =IF(B17="","",G17/GIO_CONG) -> 0 | I17: =IF(D17="Khoán",IF(GIO_TB>0,G17/GIO_TB*KL_CHEBIEN,0),0) -> 0 | J17: =IF(D17="Khoán",F17*I17,0) -> 0 | K17: =IF(D17="Khoán",IF(TONG_GIO_KHOAN>0,QUY_HANGING/TONG_GIO_KHOAN*G17,0),0) -> 0 | L17: =IF(D17="Khoán",IF(TONG_GIO_KHOAN>0,QUY_KHAC/TONG_GIO_KHOAN*G17,0),0) -> 0 | M17: =IF(B17="",0,SUMIFS(KHOAN_KHAC!$F$5:$F$39,KHOAN_KHAC!$G$5:$G$39,B17)) -> 0 | N17: =IF(D17="Khoán",IF(TONG_GIO_KHOAN>0,QUY_CHEN/TONG_GIO_KHOAN*G17,0),0) -> 0 | O17: =IF(D17="Khoán",IF(TONG_GIO_KHOAN>0,-TONG_CONGNHAT/TONG_GIO_KHOAN*G17,0),0) -> 0 | P17: =IF(D17="Công nhật",H17*IFERROR(IF(INDEX(NV_DGCN,MATCH(B17,NV_MA,0))="",DG_CONGNHAT,INDEX(NV_DGCN,MATCH(B17,NV_MA,0))),DG_CONGNHAT),0) -> 0 | Q17: =IF(B17="","",IF(D17="Khoán",ROUNDDOWN(J17+K17+L17+M17+N17+O17,-3),P17+M17)) -> 0 | R17: =IF(B17="","",ROUNDDOWN(TIENAN_CONG*H17,-3)) -> 0 | S17: =IF(B17="","",Q17+R17) -> 0
A18: =IF(B18="","",13) -> 13 | B18: =IF(BCC_KHOAN!B18="","",BCC_KHOAN!B18) -> 046206004482 | C18: =IF(B18="","",IFERROR(INDEX(NV_TEN,MATCH(B18,NV_MA,0)),"MÃ KHÔNG CÓ")) -> Trần Đình Lĩnh | D18: =IF(B18="","",IFERROR(INDEX(NV_HINHTHUC,MATCH(B18,NV_MA,0)),"")) -> Khoán | E18: =IF(D18="Khoán",IFERROR(INDEX(NV_HESO,MATCH(B18,NV_MA,0)),0),"") -> 1.05 | F18: =IF(D18="Khoán",IFERROR(INDEX(HS_SX!$B$5:$B$30,MATCH(E18,HS_SX!$A$5:$A$30,0)),0),"") -> 6700 | G18: =IF(B18="","",IFERROR(INDEX(BCC_GIO,MATCH(B18,BCC_MA,0)),0)) -> 0 | H18: =IF(B18="","",G18/GIO_CONG) -> 0 | I18: =IF(D18="Khoán",IF(GIO_TB>0,G18/GIO_TB*KL_CHEBIEN,0),0) -> 0 | J18: =IF(D18="Khoán",F18*I18,0) -> 0 | K18: =IF(D18="Khoán",IF(TONG_GIO_KHOAN>0,QUY_HANGING/TONG_GIO_KHOAN*G18,0),0) -> 0 | L18: =IF(D18="Khoán",IF(TONG_GIO_KHOAN>0,QUY_KHAC/TONG_GIO_KHOAN*G18,0),0) -> 0 | M18: =IF(B18="",0,SUMIFS(KHOAN_KHAC!$F$5:$F$39,KHOAN_KHAC!$G$5:$G$39,B18)) -> 0 | N18: =IF(D18="Khoán",IF(TONG_GIO_KHOAN>0,QUY_CHEN/TONG_GIO_KHOAN*G18,0),0) -> 0 | O18: =IF(D18="Khoán",IF(TONG_GIO_KHOAN>0,-TONG_CONGNHAT/TONG_GIO_KHOAN*G18,0),0) -> 0 | P18: =IF(D18="Công nhật",H18*IFERROR(IF(INDEX(NV_DGCN,MATCH(B18,NV_MA,0))="",DG_CONGNHAT,INDEX(NV_DGCN,MATCH(B18,NV_MA,0))),DG_CONGNHAT),0) -> 0 | Q18: =IF(B18="","",IF(D18="Khoán",ROUNDDOWN(J18+K18+L18+M18+N18+O18,-3),P18+M18)) -> 0 | R18: =IF(B18="","",ROUNDDOWN(TIENAN_CONG*H18,-3)) -> 0 | S18: =IF(B18="","",Q18+R18) -> 0
A19: =IF(B19="","",14) -> 14 | B19: =IF(BCC_KHOAN!B19="","",BCC_KHOAN!B19) -> 046178006439 | C19: =IF(B19="","",IFERROR(INDEX(NV_TEN,MATCH(B19,NV_MA,0)),"MÃ KHÔNG CÓ")) -> Nguyễn Thị Thúy Vân | D19: =IF(B19="","",IFERROR(INDEX(NV_HINHTHUC,MATCH(B19,NV_MA,0)),"")) -> Khoán | E19: =IF(D19="Khoán",IFERROR(INDEX(NV_HESO,MATCH(B19,NV_MA,0)),0),"") -> 1.15 | F19: =IF(D19="Khoán",IFERROR(INDEX(HS_SX!$B$5:$B$30,MATCH(E19,HS_SX!$A$5:$A$30,0)),0),"") -> 7400 | G19: =IF(B19="","",IFERROR(INDEX(BCC_GIO,MATCH(B19,BCC_MA,0)),0)) -> 0 | H19: =IF(B19="","",G19/GIO_CONG) -> 0 | I19: =IF(D19="Khoán",IF(GIO_TB>0,G19/GIO_TB*KL_CHEBIEN,0),0) -> 0 | J19: =IF(D19="Khoán",F19*I19,0) -> 0 | K19: =IF(D19="Khoán",IF(TONG_GIO_KHOAN>0,QUY_HANGING/TONG_GIO_KHOAN*G19,0),0) -> 0 | L19: =IF(D19="Khoán",IF(TONG_GIO_KHOAN>0,QUY_KHAC/TONG_GIO_KHOAN*G19,0),0) -> 0 | M19: =IF(B19="",0,SUMIFS(KHOAN_KHAC!$F$5:$F$39,KHOAN_KHAC!$G$5:$G$39,B19)) -> 0 | N19: =IF(D19="Khoán",IF(TONG_GIO_KHOAN>0,QUY_CHEN/TONG_GIO_KHOAN*G19,0),0) -> 0 | O19: =IF(D19="Khoán",IF(TONG_GIO_KHOAN>0,-TONG_CONGNHAT/TONG_GIO_KHOAN*G19,0),0) -> 0 | P19: =IF(D19="Công nhật",H19*IFERROR(IF(INDEX(NV_DGCN,MATCH(B19,NV_MA,0))="",DG_CONGNHAT,INDEX(NV_DGCN,MATCH(B19,NV_MA,0))),DG_CONGNHAT),0) -> 0 | Q19: =IF(B19="","",IF(D19="Khoán",ROUNDDOWN(J19+K19+L19+M19+N19+O19,-3),P19+M19)) -> 0 | R19: =IF(B19="","",ROUNDDOWN(TIENAN_CONG*H19,-3)) -> 0 | S19: =IF(B19="","",Q19+R19) -> 0
A20: =IF(B20="","",15) -> 15 | B20: =IF(BCC_KHOAN!B20="","",BCC_KHOAN!B20) -> 046172008914 | C20: =IF(B20="","",IFERROR(INDEX(NV_TEN,MATCH(B20,NV_MA,0)),"MÃ KHÔNG CÓ")) -> Trần Thị Thùy | D20: =IF(B20="","",IFERROR(INDEX(NV_HINHTHUC,MATCH(B20,NV_MA,0)),"")) -> Khoán | E20: =IF(D20="Khoán",IFERROR(INDEX(NV_HESO,MATCH(B20,NV_MA,0)),0),"") -> 1.1 | F20: =IF(D20="Khoán",IFERROR(INDEX(HS_SX!$B$5:$B$30,MATCH(E20,HS_SX!$A$5:$A$30,0)),0),"") -> 7100 | G20: =IF(B20="","",IFERROR(INDEX(BCC_GIO,MATCH(B20,BCC_MA,0)),0)) -> 0 | H20: =IF(B20="","",G20/GIO_CONG) -> 0 | I20: =IF(D20="Khoán",IF(GIO_TB>0,G20/GIO_TB*KL_CHEBIEN,0),0) -> 0 | J20: =IF(D20="Khoán",F20*I20,0) -> 0 | K20: =IF(D20="Khoán",IF(TONG_GIO_KHOAN>0,QUY_HANGING/TONG_GIO_KHOAN*G20,0),0) -> 0 | L20: =IF(D20="Khoán",IF(TONG_GIO_KHOAN>0,QUY_KHAC/TONG_GIO_KHOAN*G20,0),0) -> 0 | M20: =IF(B20="",0,SUMIFS(KHOAN_KHAC!$F$5:$F$39,KHOAN_KHAC!$G$5:$G$39,B20)) -> 0 | N20: =IF(D20="Khoán",IF(TONG_GIO_KHOAN>0,QUY_CHEN/TONG_GIO_KHOAN*G20,0),0) -> 0 | O20: =IF(D20="Khoán",IF(TONG_GIO_KHOAN>0,-TONG_CONGNHAT/TONG_GIO_KHOAN*G20,0),0) -> 0 | P20: =IF(D20="Công nhật",H20*IFERROR(IF(INDEX(NV_DGCN,MATCH(B20,NV_MA,0))="",DG_CONGNHAT,INDEX(NV_DGCN,MATCH(B20,NV_MA,0))),DG_CONGNHAT),0) -> 0 | Q20: =IF(B20="","",IF(D20="Khoán",ROUNDDOWN(J20+K20+L20+M20+N20+O20,-3),P20+M20)) -> 0 | R20: =IF(B20="","",ROUNDDOWN(TIENAN_CONG*H20,-3)) -> 0 | S20: =IF(B20="","",Q20+R20) -> 0
A21: =IF(B21="","",16) -> 16 | B21: =IF(BCC_KHOAN!B21="","",BCC_KHOAN!B21) -> 046177011413 | C21: =IF(B21="","",IFERROR(INDEX(NV_TEN,MATCH(B21,NV_MA,0)),"MÃ KHÔNG CÓ")) -> Lê Thị Thơ | D21: =IF(B21="","",IFERROR(INDEX(NV_HINHTHUC,MATCH(B21,NV_MA,0)),"")) -> Khoán | E21: =IF(D21="Khoán",IFERROR(INDEX(NV_HESO,MATCH(B21,NV_MA,0)),0),"") -> 1.1 | F21: =IF(D21="Khoán",IFERROR(INDEX(HS_SX!$B$5:$B$30,MATCH(E21,HS_SX!$A$5:$A$30,0)),0),"") -> 7100 | G21: =IF(B21="","",IFERROR(INDEX(BCC_GIO,MATCH(B21,BCC_MA,0)),0)) -> 0 | H21: =IF(B21="","",G21/GIO_CONG) -> 0 | I21: =IF(D21="Khoán",IF(GIO_TB>0,G21/GIO_TB*KL_CHEBIEN,0),0) -> 0 | J21: =IF(D21="Khoán",F21*I21,0) -> 0 | K21: =IF(D21="Khoán",IF(TONG_GIO_KHOAN>0,QUY_HANGING/TONG_GIO_KHOAN*G21,0),0) -> 0 | L21: =IF(D21="Khoán",IF(TONG_GIO_KHOAN>0,QUY_KHAC/TONG_GIO_KHOAN*G21,0),0) -> 0 | M21: =IF(B21="",0,SUMIFS(KHOAN_KHAC!$F$5:$F$39,KHOAN_KHAC!$G$5:$G$39,B21)) -> 0 | N21: =IF(D21="Khoán",IF(TONG_GIO_KHOAN>0,QUY_CHEN/TONG_GIO_KHOAN*G21,0),0) -> 0 | O21: =IF(D21="Khoán",IF(TONG_GIO_KHOAN>0,-TONG_CONGNHAT/TONG_GIO_KHOAN*G21,0),0) -> 0 | P21: =IF(D21="Công nhật",H21*IFERROR(IF(INDEX(NV_DGCN,MATCH(B21,NV_MA,0))="",DG_CONGNHAT,INDEX(NV_DGCN,MATCH(B21,NV_MA,0))),DG_CONGNHAT),0) -> 0 | Q21: =IF(B21="","",IF(D21="Khoán",ROUNDDOWN(J21+K21+L21+M21+N21+O21,-3),P21+M21)) -> 0 | R21: =IF(B21="","",ROUNDDOWN(TIENAN_CONG*H21,-3)) -> 0 | S21: =IF(B21="","",Q21+R21) -> 0
A22: =IF(B22="","",17) -> 17 | B22: =IF(BCC_KHOAN!B22="","",BCC_KHOAN!B22) -> 046176012012 | C22: =IF(B22="","",IFERROR(INDEX(NV_TEN,MATCH(B22,NV_MA,0)),"MÃ KHÔNG CÓ")) -> Lê Thị Hồng Lan | D22: =IF(B22="","",IFERROR(INDEX(NV_HINHTHUC,MATCH(B22,NV_MA,0)),"")) -> Khoán | E22: =IF(D22="Khoán",IFERROR(INDEX(NV_HESO,MATCH(B22,NV_MA,0)),0),"") -> 1 | F22: =IF(D22="Khoán",IFERROR(INDEX(HS_SX!$B$5:$B$30,MATCH(E22,HS_SX!$A$5:$A$30,0)),0),"") -> 6400 | G22: =IF(B22="","",IFERROR(INDEX(BCC_GIO,MATCH(B22,BCC_MA,0)),0)) -> 0 | H22: =IF(B22="","",G22/GIO_CONG) -> 0 | I22: =IF(D22="Khoán",IF(GIO_TB>0,G22/GIO_TB*KL_CHEBIEN,0),0) -> 0 | J22: =IF(D22="Khoán",F22*I22,0) -> 0 | K22: =IF(D22="Khoán",IF(TONG_GIO_KHOAN>0,QUY_HANGING/TONG_GIO_KHOAN*G22,0),0) -> 0 | L22: =IF(D22="Khoán",IF(TONG_GIO_KHOAN>0,QUY_KHAC/TONG_GIO_KHOAN*G22,0),0) -> 0 | M22: =IF(B22="",0,SUMIFS(KHOAN_KHAC!$F$5:$F$39,KHOAN_KHAC!$G$5:$G$39,B22)) -> 0 | N22: =IF(D22="Khoán",IF(TONG_GIO_KHOAN>0,QUY_CHEN/TONG_GIO_KHOAN*G22,0),0) -> 0 | O22: =IF(D22="Khoán",IF(TONG_GIO_KHOAN>0,-TONG_CONGNHAT/TONG_GIO_KHOAN*G22,0),0) -> 0 | P22: =IF(D22="Công nhật",H22*IFERROR(IF(INDEX(NV_DGCN,MATCH(B22,NV_MA,0))="",DG_CONGNHAT,INDEX(NV_DGCN,MATCH(B22,NV_MA,0))),DG_CONGNHAT),0) -> 0 | Q22: =IF(B22="","",IF(D22="Khoán",ROUNDDOWN(J22+K22+L22+M22+N22+O22,-3),P22+M22)) -> 0 | R22: =IF(B22="","",ROUNDDOWN(TIENAN_CONG*H22,-3)) -> 0 | S22: =IF(B22="","",Q22+R22) -> 0
A23: =IF(B23="","",18) -> 18 | B23: =IF(BCC_KHOAN!B23="","",BCC_KHOAN!B23) -> 046091004633 | C23: =IF(B23="","",IFERROR(INDEX(NV_TEN,MATCH(B23,NV_MA,0)),"MÃ KHÔNG CÓ")) -> Nguyễn Quang Thọ | D23: =IF(B23="","",IFERROR(INDEX(NV_HINHTHUC,MATCH(B23,NV_MA,0)),"")) -> Khoán | E23: =IF(D23="Khoán",IFERROR(INDEX(NV_HESO,MATCH(B23,NV_MA,0)),0),"") -> 0.9 | F23: =IF(D23="Khoán",IFERROR(INDEX(HS_SX!$B$5:$B$30,MATCH(E23,HS_SX!$A$5:$A$30,0)),0),"") -> 5800 | G23: =IF(B23="","",IFERROR(INDEX(BCC_GIO,MATCH(B23,BCC_MA,0)),0)) -> 0 | H23: =IF(B23="","",G23/GIO_CONG) -> 0 | I23: =IF(D23="Khoán",IF(GIO_TB>0,G23/GIO_TB*KL_CHEBIEN,0),0) -> 0 | J23: =IF(D23="Khoán",F23*I23,0) -> 0 | K23: =IF(D23="Khoán",IF(TONG_GIO_KHOAN>0,QUY_HANGING/TONG_GIO_KHOAN*G23,0),0) -> 0 | L23: =IF(D23="Khoán",IF(TONG_GIO_KHOAN>0,QUY_KHAC/TONG_GIO_KHOAN*G23,0),0) -> 0 | M23: =IF(B23="",0,SUMIFS(KHOAN_KHAC!$F$5:$F$39,KHOAN_KHAC!$G$5:$G$39,B23)) -> 0 | N23: =IF(D23="Khoán",IF(TONG_GIO_KHOAN>0,QUY_CHEN/TONG_GIO_KHOAN*G23,0),0) -> 0 | O23: =IF(D23="Khoán",IF(TONG_GIO_KHOAN>0,-TONG_CONGNHAT/TONG_GIO_KHOAN*G23,0),0) -> 0 | P23: =IF(D23="Công nhật",H23*IFERROR(IF(INDEX(NV_DGCN,MATCH(B23,NV_MA,0))="",DG_CONGNHAT,INDEX(NV_DGCN,MATCH(B23,NV_MA,0))),DG_CONGNHAT),0) -> 0 | Q23: =IF(B23="","",IF(D23="Khoán",ROUNDDOWN(J23+K23+L23+M23+N23+O23,-3),P23+M23)) -> 0 | R23: =IF(B23="","",ROUNDDOWN(TIENAN_CONG*H23,-3)) -> 0 | S23: =IF(B23="","",Q23+R23) -> 0
A24: =IF(B24="","",19) -> 19 | B24: =IF(BCC_KHOAN!B24="","",BCC_KHOAN!B24) -> 046074013724 | C24: =IF(B24="","",IFERROR(INDEX(NV_TEN,MATCH(B24,NV_MA,0)),"MÃ KHÔNG CÓ")) -> Nguyễn Ngọc Phương | D24: =IF(B24="","",IFERROR(INDEX(NV_HINHTHUC,MATCH(B24,NV_MA,0)),"")) -> Khoán | E24: =IF(D24="Khoán",IFERROR(INDEX(NV_HESO,MATCH(B24,NV_MA,0)),0),"") -> 1.3 | F24: =IF(D24="Khoán",IFERROR(INDEX(HS_SX!$B$5:$B$30,MATCH(E24,HS_SX!$A$5:$A$30,0)),0),"") -> 8300 | G24: =IF(B24="","",IFERROR(INDEX(BCC_GIO,MATCH(B24,BCC_MA,0)),0)) -> 132 | H24: =IF(B24="","",G24/GIO_CONG) -> 16.5 | I24: =IF(D24="Khoán",IF(GIO_TB>0,G24/GIO_TB*KL_CHEBIEN,0),0) -> 13128.801 | J24: =IF(D24="Khoán",F24*I24,0) -> 1.0896905e+08 | K24: =IF(D24="Khoán",IF(TONG_GIO_KHOAN>0,QUY_HANGING/TONG_GIO_KHOAN*G24,0),0) -> 0 | L24: =IF(D24="Khoán",IF(TONG_GIO_KHOAN>0,QUY_KHAC/TONG_GIO_KHOAN*G24,0),0) -> -6512967 | M24: =IF(B24="",0,SUMIFS(KHOAN_KHAC!$F$5:$F$39,KHOAN_KHAC!$G$5:$G$39,B24)) -> 0 | N24: =IF(D24="Khoán",IF(TONG_GIO_KHOAN>0,QUY_CHEN/TONG_GIO_KHOAN*G24,0),0) -> 4279643.1 | O24: =IF(D24="Khoán",IF(TONG_GIO_KHOAN>0,-TONG_CONGNHAT/TONG_GIO_KHOAN*G24,0),0) -> 0 | P24: =IF(D24="Công nhật",H24*IFERROR(IF(INDEX(NV_DGCN,MATCH(B24,NV_MA,0))="",DG_CONGNHAT,INDEX(NV_DGCN,MATCH(B24,NV_MA,0))),DG_CONGNHAT),0) -> 0 | Q24: =IF(B24="","",IF(D24="Khoán",ROUNDDOWN(J24+K24+L24+M24+N24+O24,-3),P24+M24)) -> 106735000 | R24: =IF(B24="","",ROUNDDOWN(TIENAN_CONG*H24,-3)) -> 6408000 | S24: =IF(B24="","",Q24+R24) -> 113143000
A25: =IF(B25="","",20) -> 20 | B25: =IF(BCC_KHOAN!B25="","",BCC_KHOAN!B25) -> 046099007864 | C25: =IF(B25="","",IFERROR(INDEX(NV_TEN,MATCH(B25,NV_MA,0)),"MÃ KHÔNG CÓ")) -> Lê Lộc | D25: =IF(B25="","",IFERROR(INDEX(NV_HINHTHUC,MATCH(B25,NV_MA,0)),"")) -> Khoán | E25: =IF(D25="Khoán",IFERROR(INDEX(NV_HESO,MATCH(B25,NV_MA,0)),0),"") -> 1.15 | F25: =IF(D25="Khoán",IFERROR(INDEX(HS_SX!$B$5:$B$30,MATCH(E25,HS_SX!$A$5:$A$30,0)),0),"") -> 7400 | G25: =IF(B25="","",IFERROR(INDEX(BCC_GIO,MATCH(B25,BCC_MA,0)),0)) -> 0 | H25: =IF(B25="","",G25/GIO_CONG) -> 0 | I25: =IF(D25="Khoán",IF(GIO_TB>0,G25/GIO_TB*KL_CHEBIEN,0),0) -> 0 | J25: =IF(D25="Khoán",F25*I25,0) -> 0 | K25: =IF(D25="Khoán",IF(TONG_GIO_KHOAN>0,QUY_HANGING/TONG_GIO_KHOAN*G25,0),0) -> 0 | L25: =IF(D25="Khoán",IF(TONG_GIO_KHOAN>0,QUY_KHAC/TONG_GIO_KHOAN*G25,0),0) -> 0 | M25: =IF(B25="",0,SUMIFS(KHOAN_KHAC!$F$5:$F$39,KHOAN_KHAC!$G$5:$G$39,B25)) -> 0 | N25: =IF(D25="Khoán",IF(TONG_GIO_KHOAN>0,QUY_CHEN/TONG_GIO_KHOAN*G25,0),0) -> 0 | O25: =IF(D25="Khoán",IF(TONG_GIO_KHOAN>0,-TONG_CONGNHAT/TONG_GIO_KHOAN*G25,0),0) -> 0 | P25: =IF(D25="Công nhật",H25*IFERROR(IF(INDEX(NV_DGCN,MATCH(B25,NV_MA,0))="",DG_CONGNHAT,INDEX(NV_DGCN,MATCH(B25,NV_MA,0))),DG_CONGNHAT),0) -> 0 | Q25: =IF(B25="","",IF(D25="Khoán",ROUNDDOWN(J25+K25+L25+M25+N25+O25,-3),P25+M25)) -> 0 | R25: =IF(B25="","",ROUNDDOWN(TIENAN_CONG*H25,-3)) -> 0 | S25: =IF(B25="","",Q25+R25) -> 0
A26: =IF(B26="","",21) -> 21 | B26: =IF(BCC_KHOAN!B26="","",BCC_KHOAN!B26) -> 002191001272 | C26: =IF(B26="","",IFERROR(INDEX(NV_TEN,MATCH(B26,NV_MA,0)),"MÃ KHÔNG CÓ")) -> Thèn Thị Giang | D26: =IF(B26="","",IFERROR(INDEX(NV_HINHTHUC,MATCH(B26,NV_MA,0)),"")) -> Khoán | E26: =IF(D26="Khoán",IFERROR(INDEX(NV_HESO,MATCH(B26,NV_MA,0)),0),"") -> 1.15 | F26: =IF(D26="Khoán",IFERROR(INDEX(HS_SX!$B$5:$B$30,MATCH(E26,HS_SX!$A$5:$A$30,0)),0),"") -> 7400 | G26: =IF(B26="","",IFERROR(INDEX(BCC_GIO,MATCH(B26,BCC_MA,0)),0)) -> 0 | H26: =IF(B26="","",G26/GIO_CONG) -> 0 | I26: =IF(D26="Khoán",IF(GIO_TB>0,G26/GIO_TB*KL_CHEBIEN,0),0) -> 0 | J26: =IF(D26="Khoán",F26*I26,0) -> 0 | K26: =IF(D26="Khoán",IF(TONG_GIO_KHOAN>0,QUY_HANGING/TONG_GIO_KHOAN*G26,0),0) -> 0 | L26: =IF(D26="Khoán",IF(TONG_GIO_KHOAN>0,QUY_KHAC/TONG_GIO_KHOAN*G26,0),0) -> 0 | M26: =IF(B26="",0,SUMIFS(KHOAN_KHAC!$F$5:$F$39,KHOAN_KHAC!$G$5:$G$39,B26)) -> 0 | N26: =IF(D26="Khoán",IF(TONG_GIO_KHOAN>0,QUY_CHEN/TONG_GIO_KHOAN*G26,0),0) -> 0 | O26: =IF(D26="Khoán",IF(TONG_GIO_KHOAN>0,-TONG_CONGNHAT/TONG_GIO_KHOAN*G26,0),0) -> 0 | P26: =IF(D26="Công nhật",H26*IFERROR(IF(INDEX(NV_DGCN,MATCH(B26,NV_MA,0))="",DG_CONGNHAT,INDEX(NV_DGCN,MATCH(B26,NV_MA,0))),DG_CONGNHAT),0) -> 0 | Q26: =IF(B26="","",IF(D26="Khoán",ROUNDDOWN(J26+K26+L26+M26+N26+O26,-3),P26+M26)) -> 0 | R26: =IF(B26="","",ROUNDDOWN(TIENAN_CONG*H26,-3)) -> 0 | S26: =IF(B26="","",Q26+R26) -> 0
